Workbook
Name Counter: Data!$B$101:$B$102
Name Depallet1: Data!$B$24:$S$28
Name Depallet1_S: Data!$B$32:$S$32
Name Depallet2: Data!$B$39:$S$39
Name Depallet2_S: Data!$B$47:$S$47
Name Depallet3: Data!$B$52:$S$52
Name Depallet3_S: Data!$B$57:$S$57
Name dfegr: [1]Data!#REF!
Name dfegr: [1]Data!#REF!
Name dfegr: [1]Data!#REF!
Name dfegr: [1]Data!#REF!
Name dfegr: [1]Data!#REF!
Name dfegr: [1]Data!#REF!
Name dfegr: [1]Data!#REF!
Name dfegr: [1]Data!#REF!
Name dfegr: [1]Data!#REF!
Name dfegr: [1]Data!#REF!
Name dfegr: [1]Data!#REF!
Name dfegr: [1]Data!#REF!
Name dfegr: [1]Data!#REF!
Name dfegr: [1]Data!#REF!
Name dfegr: [1]Data!#REF!
Name dfegr: [1]Data!#REF!
Name dfegr: [1]Data!#REF!
Name dfegr: [1]Data!#REF!
Name dfegr: [1]Data!#REF!
Name dfegr: [1]Data!#REF!
Name dfegr: [1]Data!#REF!
Name dfegr: [1]Data!#REF!
Name dfegr: [1]Data!#REF!
Name dfegr: [1]Data!#REF!
Name dfegr: [1]Data!#REF!
Name dfegr: [1]Data!#REF!
Name dfegr: [1]Data!#REF!
Name dfegr: [1]Data!#REF!
Name dfegr: [1]Data!#REF!
Name dfegr: [1]Data!#REF!
Name dfegr: [1]Data!#REF!
Name dfegr: [1]Data!#REF!
Name dfegr: Data!#REF!
Name jyi: Data!#REF!
Name jyi: Data!#REF!
Name jyi: Data!#REF!
Name jyi: Data!#REF!
Name jyi: Data!#REF!
Name jyi: Data!#REF!
Name jyi: Data!#REF!
Name jyi: Data!#REF!
Name jyi: Data!#REF!
Name jyi: Data!#REF!
Name jyi: Data!#REF!
Name jyi: Data!#REF!
Name jyi: Data!#REF!
Name jyi: Data!#REF!
Name jyi: Data!#REF!
Name Performance1: Data!$B$61:$AA$69
Name Performance2: Data!$B$70:$AA$70
Name Performance3: Data!$B$79:$AA$79
Name ProdShift1: Data!$B$3:$AM$5
Name ProdShift2: Data!$B$11:$AM$11

Sheet รายงานการผลิต
A1: รายงานการผลิตครอบประจำวัน | F1: =IF(Data!$B$105=0,"",Data!$B$105) -> โรงงานนครปฐม ครอบชนผนัง | K1: สัปดาห์ที่ | L1: =Data!D104 -> 17/38 | N1: วันที่ผลิต | O1: 242754 | Q1: MATERIAL DOCUMENT NO | U1: =O1 -> 242754 | W1: Water base | AG1: =TEXT(U1,"ddmmyy") -> 190864 | AH1: =NOW()-ROUNDDOWN(NOW(),0) -> 0.80654178
E2: จำนวนที่ผลิต | L2: เถ้าลอย | M2: ปูนซีเมนต์ | N2: ปูนซีเมนต์ | O2: ทราย | P2: ทราย | Q2: น้ำมัน | R2: สี | S2: Adva | T2: สีพื้น | U2: สีเหลือบ | V2: สีเหลือบ | W2: Slurry | X2: primer | Y2: Add 1 | Z2: Add 2 | AA2: เถ้าลอย | AB2: ปูนซีเมนต์ | AC2: ทราย | AD2: พ่นแบบ | AE2: Batch | AG2: =IF($AH$1>0.25,IF($AH$1<0.75,TODAY(),IF($AH$1>0.75,TODAY()-1))) -> 46277 | AH2: ปูนผสมตัว | AI2: S/C | AJ2: ทรายผสมตัว | AK2: ความชื้น Mortar | AL2: น้ำหนัก Batch | AM2: น้ำ | AN2: น้ำหนักมาตรฐาน/1000 แผ่น | AP2: น้ำมันพ่นแบบ/1000 แผ่น | AS2: รายงานการใช้วัตถุดิบ (สรุปรายงานประจำเดือน)
A3: กะที่ | B3: LOT NO. | C3: ลอน | D3: สี | E3: (แผ่น) | H3: ปริมาณการใช้วัตถุดิบ | M3: ผสมตัว | N3: ผสมสี | O3: ผสมตัว | P3: ผสมสี | Q3: พ่นแบบ | R3: X-Shield | U3: 1 | V3: 2 | AG3: Nonoptimize | AH3: 300 | AI3: 3.7 | AJ3: =AI3*AH3 -> 1110 | AK3: 0.08 | AL3: 1400 | AM3: =AL3*AK3 -> 112 | AN3: 4400 | AP3: 18 | AS3: Counter | AT3: ห้องบ่ม | AU3: แผ่นเสีย | AV3: ปูนผสมตัว | AX3: ทรายผสมตัว | AZ3: Fly ash | BB3: ปูนผสมสี | BD3: ทรายผสมสี | BF3: GC2 | BH3: น้ำมันพ่นแบบ | BJ3: GEP | BL3: การใช้สี | BO3: ยอดแกะ | BP3: แผ่นดี | BQ3: แผ่นเสีย
E4: Plan | F4: Counter | G4: ห้องบ่ม | L4: (ตัน) | M4: (ตัน) | N4: (ตัน) | O4: (ตัน) | P4: (ตัน) | Q4: (ลิตร) | R4: (ลิตร) | S4: (ลิตร) | T4: (แผ่น/ถัง) | U4: (แผ่น/ถัง) | V4: (แผ่น/ถัง) | W4: (แผ่น/ถัง) | X4: (แผ่น/KG.) | Y4: (แผ่น/KG.) | Z4: (แผ่น/KG.) | AA4: ตัน | AB4: ตัน | AC4: ตัน | AD4: ลิตร | AG4: Optimize | AH4: =AH3 -> 300 | AI4: =AI3 -> 3.7 | AJ4: =AJ3 -> 1110 | AK4: =AK3 -> 0.08 | AL4: =AL3 -> 1400 | AM4: =AL4*AK4 -> 112 | AN4: 4200 | AP4: 18 | AS4: (แผ่น) | AT4: (แผ่น) | AU4: (แผ่น) | AV4: ton | AW4: ton/1000 | AX4: ton | AY4: ton/1000 | AZ4: ton | BA4: ton/1000 | BB4: ton | BC4: ton/1000 | BD4: ton | BE4: ton/1000 | BF4: ลิตร | BG4: ลิตร/1000 | BH4: ลิตร | BI4: ลิตร/1000 | BJ4: ลิตร | BK4: ลิตร/1000 | BL4: ถัง (BC) | BM4: แผ่น/ถัง | BN4: ถัง (OS) | BO4: (แผ่น) | BP4: (แผ่น) | BQ4: (แผ่น) | BR4: %
B5: 56408503 | C5: AB(E) | D5: คลาสสิคบลูP | E5: 700 | F5: 775 | G5: 705 | H5: ปริมาณการใช้กะ 1 | AH5: ปูนผสมสี | AI5: ทรายผสมสี | AJ5: GC2 | AK5: น้ำ | AL5: สี | AM5: น้ำหนักมาตรฐาน/1000 แผ่น | AR5: กะ1 | AS5: =F5 -> 775 | AT5: =G5 -> 705 | AV5: =M5 -> 0 | AX5: =O5 -> 0 | AZ5: =L5 -> 0 | BB5: =N5 -> 0 | BD5: =P5 -> 0 | BF5: =S5 -> 0 | BH5: =Q5 -> 0 | BJ5: =R5 -> 0 | BL5: =T5 -> 0 | BN5: =U5 -> 0 | BO5: =E32 -> 710 | BP5: =F32 -> 708
A6: 1 | H6: คำนวณจาก Counter (ต่อพันแผ่น) | L6: =IF($F$10=0,0,L5*1000/Data!J2) -> 0 | M6: 0 | N6: =IF($F$10=0,0,N5*1000/$F$10) -> 0 | O6: =IF($F$10=0,0,O5*1000/$F$10) -> 0 | P6: =IF($F$10=0,0,P5*1000/$F$10) -> 0 | Q6: =IF($F$10=0,0,Q5*1000/$F$10) -> 0 | R6: =IF($F$10=0,0,R5*1000/$F$10) -> 0 | S6: =IF($F$10=0,0,S5*1000/$F$10) -> 0 | T6: =IF(T5=0,0,F10/T5) -> 0 | U6: =IF(U5=0,0,Data!U1/U5) -> 0 | V6: =IF(V5=0,0,Data!V1/V5) -> 0 | W6: =IF(W5=0,0,Y11/W5) -> 0 | X6: =IF(X5=0,0,Y11/X5) -> 0 | Y6: =IF(Y5=0,0,Y11/Y5) -> 0 | Z6: =IF(Z5=0,0,Y11/Z5) -> 0 | AA6: =AA5*1000/Y11 -> #DIV/0! | AB6: =AB5*1000/Y11 -> #DIV/0! | AC6: =AC5*1000/Y11 -> #DIV/0! | AD6: =AD5*1000/Y11 -> #DIV/0! | AG6: B/C | AH6: 50 | AI6: 12.5 | AJ6: 0.24 | AK6: 20 | AL6: 6 | AM6: 18 | AR6: กะ2 | AS6: =F11 -> 520 | AT6: =G11 -> 500 | AV6: =M11 -> 0 | AX6: =O11 -> 0 | AZ6: =L11 -> 0 | BB6: =N11 -> 0 | BD6: =P11 -> 0 | BF6: =S11 -> 0 | BH6: =Q11 -> 0 | BJ6: =R11 -> 0 | BL6: =T11 -> 0 | BN6: =U11 -> 0 | BO6: =E39 -> 500 | BP6: =F39 -> 488
B7: =IF(ISBLANK(Data!F6),"",Data!F6) | C7: =IF(B7=""," ",UPPER(LEFT(Data!G6,15))) | D7: =IF(ISBLANK(Data!H6),"",Data!H6) | E7: =IF(ISBLANK(Data!I6),"",Data!I6) | H7: คำนวณจาก ห้องบ่ม (ต่อพันแผ่น) | L7: =IF($G$10=0,0,L5*1000/Data!K2) -> 0 | M7: =IF($G$10=0,0,M5*1000/$G$10) -> 0 | N7: =IF($G$10=0,0,N5*1000/$G$10) -> 0 | O7: =IF($G$10=0,0,O5*1000/$G$10) -> 0 | P7: =IF($G$10=0,0,P5*1000/$G$10) -> 0 | Q7: =IF($G$10=0,0,Q5*1000/$G$10) -> 0 | R7: =IF($G$10=0,0,R5*1000/$G$10) -> 0 | S7: =IF($G$10=0,0,S5*1000/$G$10) -> 0 | T7: =IF(T5=0,0,G10/T5) -> 0 | U7: =IF(U5=0,0,Data!X1/U5) -> 0 | V7: =IF(V5=0,0,Data!Y1/V5) -> 0 | W7: =IF(W5=0,0,Z11/W5) -> 0 | X7: =IF(X5=0,0,Z11/X5) -> 0 | Y7: =IF(Y5=0,0,Z11/Y5) -> 0 | Z7: =IF(Z5=0,0,Z11/Z5) -> 0 | AA7: =AA5*1000/Z11 -> #DIV/0! | AB7: =AB5*1000/Z11 -> #DIV/0! | AC7: =AC5*1000/Z11 -> #DIV/0! | AD7: =AD5*1000/Z11 -> #DIV/0! | AH7: ปูนผสมสี | AI7: ทรายผสมสี | AJ7: GC2 | AK7: น้ำ | AL7: สี | AM7: น้ำหนักมาตรฐาน/1000 แผ่น
B8: =IF(ISBLANK(Data!F7),"",Data!F7) | C8: =IF(B8=""," ",UPPER(LEFT(Data!G7,15))) | D8: =IF(ISBLANK(Data!H7),"",Data!H7) | E8: =IF(ISBLANK(Data!I7),"",Data!I7) | F8: =IF(ISBLANK(Data!J7),"",Data!J7) | G8: =IF(ISBLANK(Data!K7),"",Data!K7)
B9: =IF(ISBLANK(Data!F8),"",Data!F8) | C9: =IF(B9=""," ",UPPER(LEFT(Data!G8,15))) | D9: =IF(ISBLANK(Data!H8),"",Data!H8) | E9: =IF(ISBLANK(Data!I8),"",Data!I8) | F9: =IF(ISBLANK(Data!J8),"",Data!J8) | G9: =IF(ISBLANK(Data!K8),"",Data!K8) | H9: หมายเหตุ | L9: ใช้ปูน | N9: Batch | O9: ทิ้งปูน | Q9: Batch | R9: ทิ้งสีพื้น | S9: 1 | T9: ถัง | U9: =IF(ISBLANK(Data!AH2),"",Data!AH2) -> 0 | V9: ถัง
A10: รวมกะที่ 1 | E10: =SUM(E5:E9) -> 700 | F10: =SUM(F5:F9) -> 775 | G10: =SUM(G5:G9) -> 705 | L10: ใช้ผ้า | N10: ผืน | O10: =F10/M10 -> #DIV/0! | P10: แผ่น/ผืน | Q10: ตะแกรง | R10: 2 | S10: ผืน | T10: =F10/R10 -> 387.5 | U10: แผ่น/ผืน | X10: Plan | Y10: Counter | Z10: ห้องบ่ม | AG10: O/C | AH10: =AH6/2 -> 25 | AI10: =AI6/2 -> 6.25 | AJ10: =AJ6/2 -> 0.12 | AK10: 20 | AL10: 6 | AM10: 18 | AS10: รายงานการใช้วัตถุดิบ (ส่งพี่จง)
B11: 56408415 | C11: AB(B) | D11: เทาปีกนางนวลP | E11: 500 | F11: 520 | G11: 500 | H11: ปริมาณการใช้กะ 2 | AG11: ทรายผสมตัวคำนวน | AS11: ปูน | AT11: fly ash | AU11: ทราย | AV11: จำนวน batch | AW11: ห้องบ่ม
A12: 2 | H12: คำนวณจาก Counter (ต่อพันแผ่น) | L12: =+L11*1000/F15 -> 0 | M12: =IF($F$15=0,0,M11*1000/$F$15) -> 0 | N12: =IF($F$15=0,0,N11*1000/$F$15) -> 0 | O12: =IF($F$15=0,0,O11*1000/$F$15) -> 0 | P12: =IF($F$15=0,0,P11*1000/$F$15) -> 0 | Q12: =IF($F$15=0,0,Q11*1000/$F$15) -> 0 | R12: =IF($F$15=0,0,R11*1000/$F$15) -> 0 | S12: =IF($F$15=0,0,S11*1000/$F$15) -> 0 | T12: =IF(T11=0,0,F15/T11) -> 0 | U12: =IF(U11=0,0,Data!U9/U11) -> 0 | V12: =IF(V11=0,0,Data!V9/V11) -> 0 | AG12: =L5*$AI$3 -> 0 | AR12: กะ1 | AS12: =M5 -> 0 | AT12: =L5 -> 0 | AU12: =O5 -> 0 | AV12: =M9 -> 0 | AW12: =G10 -> 705
B13: =IF(ISBLANK(Data!F14),"",Data!F14) | C13: =IF(B13=""," ",UPPER(LEFT(Data!G14,15))) | D13: =IF(ISBLANK(Data!H14),"",Data!H14) | E13: =IF(ISBLANK(Data!I14),"",Data!I14) | F13: =IF(ISBLANK(Data!J14),"",Data!J14) | G13: =IF(ISBLANK(Data!K14),"",Data!K14) | H13: คำนวณจาก ห้องบ่ม (ต่อพันแผ่น) | L13: =+L11*1000/G15 -> 0 | M13: =IF($G$15=0,0,M11*1000/$G$15) -> 0 | N13: =IF($G$15=0,0,N11*1000/$G$15) -> 0 | O13: =IF($G$15=0,0,O11*1000/$G$15) -> 0 | P13: =IF($G$15=0,0,P11*1000/$G$15) -> 0 | Q13: =IF($G$15=0,0,Q11*1000/$G$15) -> 0 | R13: =IF($G$15=0,0,R11*1000/$G$15) -> 0 | S13: =IF($G$15=0,0,S11*1000/$G$15) -> 0 | T13: =IF(T11=0,0,G15/T11) -> 0 | U13: =IF(U11=0,0,Data!X9/U11) -> 0 | V13: =IF(V11=0,0,Data!Y9/V11) -> 0 | X13: วันที่ | Z13: เดือน | AB13: ปี | AI13: ช่องสีนี้เป็นช่องที่ต้องทำการแก้ไข Update เสมอเมื่อมีการเปลี่ยนแปลง | AR13: กะ2 | AS13: =M11 -> 0 | AT13: =L11 -> 0 | AU13: =O11 -> 0 | AV13: =M14 -> 0 | AW13: =G15 -> 500
B14: =IF(ISBLANK(Data!F15),"",Data!F15) | C14: =IF(B14=""," ",UPPER(LEFT(Data!G15,15))) | D14: =IF(ISBLANK(Data!H15),"",Data!H15) | E14: =IF(ISBLANK(Data!I15),"",Data!I15) | F14: =IF(ISBLANK(Data!J15),"",Data!J15) | G14: =IF(ISBLANK(Data!K15),"",Data!K15) | H14: หมายเหตุ | L14: ใช้ปูน | N14: Batch | O14: ทิ้งปูน | P14: =IF(ISBLANK(Data!Y10),"",Data!Y10) -> 0 | Q14: Batch | R14: ทิ้งสีพื้น | S14: 1 | T14: ถัง | U14: =IF(ISBLANK(Data!AH10),"",Data!AH10) -> 0 | V14: ถัง | X14: 2 | Y14: 7 | Z14: 0 | AA14: 5 | AB14: 6 | AC14: 0
A15: รวมกะที่ 2 | E15: =SUM(E11:E14) -> 500 | F15: =SUM(F11:F14) -> 520 | G15: =SUM(G11:G14) -> 500 | L15: ใช้ผ้า | N15: ผืน | O15: =F15/M15 -> #DIV/0! | P15: แผ่น/ผืน | Q15: ตะแกรง | S15: แผ่น | T15: =IF(R15=0,0,F15/R15) -> 0 | U15: แผ่น/ผืน
H16: ปริมาณการใช้กะ 3 | X16: รายการเบิก | Y16: ton | Z16: kg
A17: 3 | B17: =IF(ISBLANK(Data!F20),"",Data!F20) | H17: คำนวณจาก Counter (ต่อพันแผ่น) | L17: =+L16*1000/F19 -> #DIV/0! | M17: =IF($F$19=0,0,M16*1000/$F$19) -> 0 | N17: =IF($F$19=0,0,N16*1000/$F$19) -> 0 | O17: =IF($F$19=0,0,O16*1000/$F$19) -> 0 | P17: =IF($F$19=0,0,P16*1000/$F$19) -> 0 | Q17: =IF($F$19=0,0,Q16*1000/$F$19) -> 0 | R17: =IF($F$19=0,0,R16*1000/$F$19) -> 0 | S17: =IF($F$19=0,0,S16*1000/$F$15) -> 0 | T17: =IF(T16=0,0,F19/T16) -> 0 | U17: =IF(U16=0,0,Data!U14/U16) -> 0 | V17: =IF(V16=0,0,Data!V14/V16) -> 0 | X17: ปูนผสมตัว | Y17: 3 | Z17: 257
B18: =IF(ISBLANK(Data!F21),"",Data!F21) | C18: =IF(B18=""," ",UPPER(LEFT(Data!G21,15))) | D18: =IF(ISBLANK(Data!H21),"",Data!H21) | E18: =IF(ISBLANK(Data!I21),"",Data!I21) | F18: =IF(ISBLANK(Data!J21),"",Data!J21) | G18: =IF(ISBLANK(Data!K21),"",Data!K21) | H18: คำนวณจาก ห้องบ่ม (ต่อพันแผ่น) | L18: =+L16*1000/G19 -> #DIV/0! | M18: =IF($G$19=0,0,M16*1000/$G$19) -> 0 | N18: =IF($G$19=0,0,N16*1000/$G$19) -> 0 | O18: =IF($G$19=0,0,O16*1000/$G$19) -> 0 | P18: =IF($G$19=0,0,P16*1000/$G$19) -> 0 | Q18: =IF($G$19=0,0,Q16*1000/$G$19) -> 0 | R18: =IF($G$19=0,0,R16*1000/$G$19) -> 0 | S18: =IF($G$19=0,0,S16*1000/$G$15) -> 0 | T18: =IF(T16=0,0,G19/T16) -> 0 | U18: =IF(U16=0,0,Data!X14/U16) -> 0 | V18: =IF(V16=0,0,Data!Y14/V16) -> 0 | X18: ปูนผสมสี | Y18: 0 | Z18: 425 | AH18: 0.95833333 | AI18: 0.75 | AJ18: 0.95833333 | AK18: 0.25 | AL18: 0.35416667 | AM18: =NOW()-ROUNDDOWN(NOW(),0) -> 0.80654178
A19: รวมกะที่ 3 | E19: =SUM(E16:E18) -> 0 | F19: =SUM(F16:F18) -> 0 | G19: =SUM(G16:G18) -> 0 | H19: หมายเหตุ | L19: ใช้ปูน | N19: Batch | O19: ทิ้งปูน | P19: =IF(ISBLANK(Data!Y17),"",Data!Y17) -> 0 | Q19: Batch | R19: ทิ้งสีพื้น | S19: =IF(ISBLANK(Data!W17),"",Data!W17) -> 0 | T19: ถัง | U19: =IF(ISBLANK(Data!AH17),"",Data!AH17) -> 0 | V19: ถัง | X19: ทรายผสมตัว | Y19: 12 | Z19: 002 | AH19: =AH18 -> 0.95833333 | AI19: =AI18 -> 0.75 | AJ19: =AJ18 -> 0.95833333 | AK19: =AK18 -> 0.25 | AL19: =AL18 -> 0.35416667 | AM19: =AM18 -> 0.80654178
H20: ปริมาณการใช้รวม | L20: =SUM(L5,L11,L16) -> 0 | M20: =SUM(M5,M11,M16) -> 0 | N20: =SUM(N5,N11,N16) -> 0 | O20: =SUM(O5,O11,O16) -> 0 | P20: =SUM(P5,P11,P16) -> 0 | Q20: =SUM(Q5,Q11,Q16) -> 0 | R20: =SUM(R5,R11,R16) -> 0 | S20: =SUM(S5,S11,S16) -> 0 | ... V20: =SUM(V5,V11,V16) -> 0 | X20: ทรายผสมสี | Y20: 0 | Z20: 213
A21: รวมทุกกะ | E21: =E10+E15+E19 -> 1200 | F21: =F10+F15+F19 -> 1295 | G21: =G10+G15+G19 -> 1205 | H21: คำนวณจาก Counter (ต่อพันแผ่น) | L21: =IF($F$21=0,0,L20*1000/(Data!J2+Data!J10+Data!J17)) -> 0 | M21: =IF($F$21=0,0,M20*1000/$F$21) -> 0 | N21: =IF($F$21=0,0,N20*1000/$F$21) -> 0 | O21: =IF($F$21=0,0,O20*1000/$F$21) -> 0 | P21: 6 | Q21: =IF($F$21=0,0,Q20*1000/$F$21) -> 0 | R21: =IF($F$21=0,0,R20*1000/$F$21) -> 0 | S21: =IF($F$21=0,0,S20*1000/$F$21) -> 0 | T21: =IF(T20=0,0,F21/T20) -> 0 | U21: =IF(U20=0,0,(Data!U1+Data!U9+Data!U16)/U20) -> 0 | V21: =IF(V20=0,0,(Data!V1+Data!V9+Data!V16)/V20) -> 0 | X21: fly ash | Y21: 4 | Z21: 675
H22: คำนวณจาก ห้องบ่ม (ต่อพันแผ่น) | L22: =IF($G$21=0,0,L20*1000/(Data!K2+Data!K10+Data!K17)) -> 0 | M22: =IF($G$21=0,0,M20*1000/$G$21) -> 0 | N22: =IF($G$21=0,0,N20*1000/$G$21) -> 0 | O22: =IF($G$21=0,0,O20*1000/$G$21) -> 0 | P22: =IF($G$21=0,0,P20*1000/$G$21) -> 0 | Q22: =IF($G$21=0,0,Q20*1000/$G$21) -> 0 | R22: =IF($G$21=0,0,R20*1000/$G$21) -> 0 | S22: =IF($G$21=0,0,S20*1000/$G$21) -> 0 | T22: =IF(T20=0,0,G21/T20) -> 0 | U22: =IF(U20=0,0,(Data!X1+Data!X9+Data!X16)/U20) -> 0 | V22: =IF(V20=0,0,(Data!Y1+Data!Y9+Data!Y16)/V20) -> 0 | X22: กบ.บด | Y22: 1 | Z22: 001 | AA22: =+O20*5% -> 0
A24: รายงานการแกะครอบ | I24: รายละเอียดครอบเสีย | R24: แผ่นดีนำไปกองเก็บ | T24: หมายเหตุ | X24: โฟมรอง Water base | AA24: =+O20*35% -> 0
A25: กะที่ | B25: LOT NO. | C25: ลอน | D25: สี | E25: จำนวนที่นำมาแกะ | F25: แผ่นดี | G25: Reject | I25: แผ่นเสีย | J25: ร้าว | K25: เนื้อครอบ แหว่งใต้ครอบ | L25: สี | M25: GEP | N25: บิ่น, แหว่ง | O25: ปูด | P25: ยกเข้า Rack | Q25: อื่น ๆ | R25: บริเวณ / แถวที่ | W25: ( แผ่นโฟม / แผ่นครอบ
B26: 56408303 | C26: AB(E) | D26: ลิกไนต์เกรย์P | E26: 710 | F26: 708 | G26: =IF(E26=0,"",(E26-F26)/E26) -> 0.0028169014 | I26: =SUM(J26:Q26) -> 0 | W26: ปริมาณโฟม | Y26: =X26 -> 0
G27: =IF(E27=0,"",(E27-F27)/E27) | I27: =SUM(J27:Q27) -> 0 | W27: นำมาแกะ | Y27: =+X26/X27 -> #DIV/0!
G28: =IF(E28=0,"",(E28-F28)/E28) | I28: =SUM(J28:Q28) -> 0 | W28: แผ่นดี | Y28: =+X26/X28 -> #DIV/0!
A29: 1 | G29: =IF(E29=0,"",(E29-F29)/E29) | I29: =SUM(J29:Q29) -> 0
G30: =IF(E30=0,"",(E30-F30)/E30) | I30: =SUM(J30:Q30) -> 0
G31: =IF(E31=0,"",(E31-F31)/E31) | I31: =SUM(J31:Q31) -> 0
A32: รวมกะที่ 1 | E32: =SUM(E26:E31) -> 710 | F32: =SUM(F26:F31) -> 708 | G32: =IF(E32=0,"",(E32-F32)/E32) -> 0.0028169014 | I32: =SUM(J32:Q32) -> 0 | J32: =SUM(J26:J31) -> 0 | K32: =SUM(K26:K31) -> 0 | L32: =SUM(L26:L31) -> 0 | M32: =SUM(M26:M31) -> 0 | N32: =SUM(N26:N31) -> 0 | O32: =SUM(O26:O31) -> 0 | P32: =SUM(P26:P31) -> 0 | Q32: =SUM(Q26:Q31) -> 0
B33: 56408414 | C33: AB(B) | D33: เทาแทนทาลั่มP | E33: 500 | F33: 488 | G33: =IF(E33=0,"",(E33-F33)/E33) -> 0.024 | I33: =SUM(J33:Q33) -> 0
G34: =IF(E34=0,"",(E34-F34)/E34) | I34: =SUM(J34:Q34) -> 0
A35: 2 | B35: =IF(ISBLANK(Data!E42),"",Data!E42) | C35: =IF(B35=""," ",UPPER(LEFT(Data!F42,15))) | D35: =IF(ISBLANK(Data!G42),"",Data!G42) | G35: =IF(E35=0,"",(E35-F35)/E35) | I35: =SUM(J35:Q35) -> 0 | J35: =IF(ISBLANK(Data!J42),"",Data!J42) | K35: =IF(ISBLANK(Data!K42),"",Data!K42) | L35: =IF(ISBLANK(Data!L42),"",Data!L42) | M35: =IF(ISBLANK(Data!M42),"",Data!M42) | N35: =IF(ISBLANK(Data!N42),"",Data!N42) | O35: =IF(ISBLANK(Data!O42),"",Data!O42) | P35: =IF(ISBLANK(Data!P42),"",Data!P42) | Q35: =IF(ISBLANK(Data!Q42),"",Data!Q42)
B36: =IF(ISBLANK(Data!E43),"",Data!E43) | C36: =IF(B36=""," ",UPPER(LEFT(Data!F43,15))) | D36: =IF(ISBLANK(Data!G43),"",Data!G43) | G36: =IF(E36=0,"",(E36-F36)/E36) | I36: =SUM(J36:Q36) -> 0 | J36: =IF(ISBLANK(Data!J43),"",Data!J43) | K36: =IF(ISBLANK(Data!K43),"",Data!K43) | L36: =IF(ISBLANK(Data!L43),"",Data!L43) | M36: =IF(ISBLANK(Data!M43),"",Data!M43) | N36: =IF(ISBLANK(Data!N43),"",Data!N43) | O36: =IF(ISBLANK(Data!O43),"",Data!O43) | P36: =IF(ISBLANK(Data!P43),"",Data!P43) | Q36: =IF(ISBLANK(Data!Q43),"",Data!Q43)
B37: =IF(ISBLANK(Data!E44),"",Data!E44) | C37: =IF(B37=""," ",UPPER(LEFT(Data!F44,15))) | D37: =IF(ISBLANK(Data!G44),"",Data!G44) | G37: =IF(E37=0,"",(E37-F37)/E37) | I37: =SUM(J37:Q37) -> 0 | J37: =IF(ISBLANK(Data!J44),"",Data!J44) | K37: =IF(ISBLANK(Data!K44),"",Data!K44) | L37: =IF(ISBLANK(Data!L44),"",Data!L44) | M37: =IF(ISBLANK(Data!M44),"",Data!M44) | N37: =IF(ISBLANK(Data!N44),"",Data!N44) | O37: =IF(ISBLANK(Data!O44),"",Data!O44) | P37: =IF(ISBLANK(Data!P44),"",Data!P44) | Q37: =IF(ISBLANK(Data!Q44),"",Data!Q44)
B38: =IF(ISBLANK(Data!E45),"",Data!E45) | C38: =IF(B38=""," ",UPPER(LEFT(Data!F45,15))) | D38: =IF(ISBLANK(Data!G45),"",Data!G45) | G38: =IF(E38=0,"",(E38-F38)/E38) | I38: =SUM(J38:Q38) -> 0 | J38: =IF(ISBLANK(Data!J45),"",Data!J45) | K38: =IF(ISBLANK(Data!K45),"",Data!K45) | L38: =IF(ISBLANK(Data!L45),"",Data!L45) | M38: =IF(ISBLANK(Data!M45),"",Data!M45) | N38: =IF(ISBLANK(Data!N45),"",Data!N45) | O38: =IF(ISBLANK(Data!O45),"",Data!O45) | P38: =IF(ISBLANK(Data!P45),"",Data!P45) | Q38: =IF(ISBLANK(Data!Q45),"",Data!Q45)
A39: รวมกะที่ 2 | E39: =SUM(E33:E38) -> 500 | F39: =SUM(F33:F38) -> 488 | G39: =IF(E39=0,"",(E39-F39)/E39) -> 0.024 | I39: =SUM(J39:Q39) -> 0 | J39: =SUM(J33:J38) -> 0 | K39: =SUM(K33:K38) -> 0 | L39: =SUM(L33:L38) -> 0 | M39: =SUM(M33:M38) -> 0 | N39: =SUM(N33:N38) -> 0 | O39: =SUM(O33:O38) -> 0 | P39: =SUM(P33:P38) -> 0 | Q39: =SUM(Q33:Q38) -> 0
A40: 3 | B40: =IF(ISBLANK(Data!E54),"",Data!E54) | C40: =IF(B40=""," ",UPPER(LEFT(Data!F54,5))) | D40: =IF(ISBLANK(Data!G54),"",Data!G54) | E40: =IF(ISBLANK(Data!H54),0,Data!H54) -> 0 | F40: =E40-I40 -> 0 | G40: =IF(E40=0,"",(E40-F40)/E40) | I40: =SUM(J40:Q40) -> 0 | J40: =IF(ISBLANK(Data!J54),"",Data!J54) | K40: =IF(ISBLANK(Data!K54),"",Data!K54) | L40: =IF(ISBLANK(Data!L54),"",Data!L54) | M40: =IF(ISBLANK(Data!M54),"",Data!M54) | N40: =IF(ISBLANK(Data!N54),"",Data!N54) | O40: =IF(ISBLANK(Data!O54),"",Data!O54) | P40: =IF(ISBLANK(Data!P54),"",Data!P54) | Q40: =IF(ISBLANK(Data!Q54),"",Data!Q54)
A41: รวมกะที่ 3 | E41: =SUM(E40:E40) -> 0 | F41: =SUM(F40:F40) -> 0 | G41: =IF(E41=0,"",(E41-F41)/E41) | I41: =SUM(J41:Q41) -> 0 | J41: =SUM(J40:J40) -> 0 | K41: =SUM(K40:K40) -> 0 | L41: =SUM(L40:L40) -> 0 | M41: =SUM(M40:M40) -> 0 | N41: =SUM(N40:N40) -> 0 | O41: =SUM(O40:O40) -> 0 | P41: =SUM(P40:P40) -> 0 | Q41: =SUM(Q40:Q40) -> 0
...

Sheet รายงานการผลิต (2)
A1: รายงานการผลิตกระเบื้องประจำวัน | H1: =IF(Data!$B$105=0,"",Data!$B$105) -> โรงงานนครปฐม ครอบชนผนัง | K1: สัปดาห์ที่ | L1: =Data!D104 -> 17/38 | N1: วันที่ผลิต | O1: =Data!B104 -> 43042 | Q1: MATERIAL DOCUMENT NO | X1: =TEXT(U1,"ddmmyy") -> 000100 | Y1: =NOW()-ROUNDDOWN(NOW(),0) -> 0.80654178
E2: จำนวนที่ผลิต | L2: เถ้าลอย | M2: ปูนซีเมนต์ | N2: ปูนซีเมนต์ | O2: ทราย | P2: ทราย | Q2: น้ำมัน | R2: น้ำยา | S2: จีซี 2 | T2: สีพื้น | U2: สีเหลือบ | V2: สีเหลือบ | X2: =IF($Y$1>0.25,IF($Y$1<0.75,TODAY(),IF($Y$1>0.75,TODAY()-1))) -> 46277 | Y2: ปูนผสมตัว | Z2: S/C | AA2: ทรายผสมตัว | AB2: ความชื้น Mortar | AC2: น้ำหนัก Batch | AD2: น้ำ | AE2: น้ำหนักมาตรฐาน/1000 แผ่น | AG2: น้ำมันพ่นแบบ/1000 แผ่น
A3: กะที่ | B3: LOT NO. | C3: ลอน | D3: สี | E3: (แผ่น) | H3: ปริมาณการใช้วัตถุดิบ | M3: ผสมตัว | N3: ผสมสี | O3: ผสมตัว | P3: ผสมสี | Q3: พ่นแบบ | R3: เคลือบผิว | U3: 1 | V3: 2 | X3: Nonoptimize | Y3: 300 | Z3: 3.7 | AA3: =Z3*Y3 -> 1110 | AB3: 0.08 | AC3: 1400 | AD3: =AC3*AB3 -> 112 | AE3: 4400 | AG3: 18
E4: Plan | F4: Counter | G4: ห้องบ่ม | L4: (ตัน) | M4: (ตัน) | N4: (ตัน) | O4: (ตัน) | P4: (ตัน) | Q4: (ลิตร) | R4: (ลิตร) | S4: (ลิตร) | T4: (แผ่น/ถัง) | U4: (แผ่น/ถัง) | V4: (แผ่น/ถัง) | X4: Optimize | Y4: =Y3 -> 300 | Z4: =Z3 -> 3.7 | AA4: =AA3 -> 1110 | AB4: =AB3 -> 0.08 | AC4: =AC3 -> 1400 | AD4: =AC4*AB4 -> 112 | AE4: 4200 | AG4: 18
H5: ปริมาณการใช้กะ 1 | Y5: ปูนผสมสี | Z5: ทรายผสมสี | AA5: GC2 | AB5: น้ำ | AC5: สี | AD5: น้ำหนักมาตรฐาน/1000 แผ่น
A6: 1 | H6: คำนวณจาก Counter (ต่อพันแผ่น) | L6: =IF($F$8=0,0,L5*1000/$F$8) -> 0 | M6: =IF($F$8=0,0,M5*1000/$F$8) -> 0 | N6: =IF($F$8=0,0,N5*1000/$F$8) -> 0 | O6: =IF($F$8=0,0,O5*1000/$F$8) -> 0 | P6: =IF($F$8=0,0,P5*1000/$F$8) -> 0 | Q6: =IF($F$8=0,0,Q5*1000/$F$8) -> 0 | R6: =IF($F$8=0,0,R5*1000/$F$8) -> 0 | S6: =IF($F$8=0,0,S5*1000/$F$8) -> 0 | T6: =IF(T5=0,0,F8/T5) -> 0 | U6: =IF(U5=0,0,Data!U1/U5) -> 0 | V6: =IF(V5=0,0,Data!V1/V5) -> 0 | X6: B/C | Y6: 50 | Z6: 25 | AA6: 0.24 | AB6: 20 | AC6: 6 | AD6: 18
H7: คำนวณจาก ห้องบ่ม (ต่อพันแผ่น) | L7: =IF($G$8=0,0,L5*1000/$G$8) -> 0 | M7: =IF($G$8=0,0,M5*1000/$G$8) -> 0 | N7: =IF($G$8=0,0,N5*1000/$G$8) -> 0 | O7: =IF($G$8=0,0,O5*1000/$G$8) -> 0 | P7: =IF($G$8=0,0,P5*1000/$G$8) -> 0 | Q7: =IF($G$8=0,0,Q5*1000/$G$8) -> 0 | R7: =IF($G$8=0,0,R5*1000/$G$8) -> 0 | S7: =IF($G$8=0,0,S5*1000/$G$8) -> 0 | T7: =IF(T5=0,0,G8/T5) -> 0 | U7: =IF(U5=0,0,Data!X1/U5) -> 0 | V7: =IF(V5=0,0,Data!Y1/V5) -> 0 | Y7: ปูนผสมสี | Z7: ทรายผสมสี | AA7: GC2 | AB7: น้ำ | AC7: สี | AD7: น้ำหนักมาตรฐาน/1000 แผ่น
A8: รวมกะที่ 1 | E8: =SUM(E5:E7) -> 0 | F8: =SUM(F5:F7) -> 0 | G8: =SUM(G5:G7) -> 0 | H8: หมายเหตุ | L8: ใช้ปูน | M8: =IF(ISBLANK(Data!X2),"",Data!X2) -> 80 | N8: Batch | O8: ทิ้งปูน | P8: =IF(ISBLANK(Data!Y2),"",Data!Y2) -> 0 | Q8: Batch | R8: ทิ้งสีพื้น | S8: =IF(ISBLANK(Data!W2),"",Data!W2) -> 0 | T8: ถัง | U8: =IF(ISBLANK(Data!AH2),"",Data!AH2) -> 0 | V8: ถัง | X8: O/C | Y8: =Y6/2 -> 25 | Z8: =Z6/2 -> 12.5 | AA8: =AA6/2 -> 0.12 | AB8: 20 | AC8: 6 | AD8: 18
H9: ปริมาณการใช้กะ 2 | X9: ทรายผสมตัวคำนวน
A10: 2 | H10: คำนวณจาก Counter (ต่อพันแผ่น) | L10: =IF($F$12=0,0,L9*1000/$F$12) -> 0 | M10: =IF($F$12=0,0,M9*1000/$F$12) -> 0 | N10: =IF($F$12=0,0,N9*1000/$F$12) -> 0 | O10: =IF($F$12=0,0,O9*1000/$F$12) -> 0 | P10: =IF($F$12=0,0,P9*1000/$F$12) -> 0 | Q10: =IF($F$12=0,0,Q9*1000/$F$12) -> 0 | R10: =IF($F$12=0,0,R9*1000/$F$12) -> 0 | S10: =IF($F$12=0,0,S9*1000/$F$12) -> 0 | T10: =IF(T9=0,0,F12/T9) -> 0 | U10: =IF(U9=0,0,Data!U9/U9) -> 0 | V10: =IF(V9=0,0,Data!V9/V9) -> 0 | X10: =L5*$Z$3 -> 0
H11: คำนวณจาก ห้องบ่ม (ต่อพันแผ่น) | L11: =IF($G$12=0,0,L9*1000/$G$12) -> 0 | M11: =IF($G$12=0,0,M9*1000/$G$12) -> 0 | N11: =IF($G$12=0,0,N9*1000/$G$12) -> 0 | O11: =IF($G$12=0,0,O9*1000/$G$12) -> 0 | P11: =IF($G$12=0,0,P9*1000/$G$12) -> 0 | Q11: =IF($G$12=0,0,Q9*1000/$G$12) -> 0 | R11: =IF($G$12=0,0,R9*1000/$G$12) -> 0 | S11: =IF($G$12=0,0,S9*1000/$G$12) -> 0 | T11: =IF(T9=0,0,G12/T9) -> 0 | U11: =IF(U9=0,0,Data!X9/U9) -> 0 | V11: =IF(V9=0,0,Data!Y9/V9) -> 0 | Z11: ช่องสีนี้เป็นช่องที่ต้องทำการแก้ไข Update เสมอเมื่อมีการเปลี่ยนแปลง
A12: รวมกะที่ 2 | E12: =SUM(E9:E11) -> 0 | F12: =SUM(F9:F11) -> 0 | G12: =SUM(G9:G11) -> 0 | H12: หมายเหตุ | L12: ใช้ปูน | M12: =IF(ISBLANK(Data!X10),"",Data!X10) -> 0 | N12: Batch | O12: ทิ้งปูน | P12: =IF(ISBLANK(Data!Y10),"",Data!Y10) -> 0 | Q12: Batch | R12: ทิ้งสีพื้น | S12: =IF(ISBLANK(Data!W10),"",Data!W10) -> 0 | T12: ถัง | U12: =IF(ISBLANK(Data!AH10),"",Data!AH10) -> 0 | V12: ถัง
H13: ปริมาณการใช้กะ 3
A14: 3 | H14: คำนวณจาก Counter (ต่อพันแผ่น) | L14: =IF($F$16=0,0,L13*1000/$F$16) -> 0 | M14: =IF($F$16=0,0,M13*1000/$F$16) -> 0 | N14: =IF($F$16=0,0,N13*1000/$F$16) -> 0 | O14: =IF($F$16=0,0,O13*1000/$F$16) -> 0 | P14: =IF($F$16=0,0,P13*1000/$F$16) -> 0 | Q14: =IF($F$16=0,0,Q13*1000/$F$16) -> 0 | R14: =IF($F$16=0,0,R13*1000/$F$16) -> 0 | S14: =IF($F$16=0,0,S13*1000/$F$16) -> 0 | T14: =IF(T13=0,0,F16/T13) -> 0 | U14: =IF(U13=0,0,Data!U16/U13) -> 0 | V14: =IF(V13=0,0,Data!V16/V13) -> 0
H15: คำนวณจาก ห้องบ่ม (ต่อพันแผ่น) | L15: =IF($G$16=0,0,L13*1000/$G$16) -> 0 | M15: =IF($G$16=0,0,M13*1000/$G$16) -> 0 | N15: =IF($G$16=0,0,N13*1000/$G$16) -> 0 | O15: =IF($G$16=0,0,O13*1000/$G$16) -> 0 | P15: =IF($G$16=0,0,P13*1000/$G$16) -> 0 | Q15: =IF($G$16=0,0,Q13*1000/$G$16) -> 0 | R15: =IF($G$16=0,0,R13*1000/$G$16) -> 0 | S15: =IF($G$16=0,0,S13*1000/$G$16) -> 0 | T15: =IF(T13=0,0,G16/T13) -> 0 | U15: =IF(U13=0,0,Data!X16/U13) -> 0 | V15: =IF(V13=0,0,Data!Y16/V13) -> 0 | Y15: 0.95833333 | Z15: 0.75 | AA15: 0.95833333 | AB15: 0.25 | AC15: 0.35416667 | AD15: =NOW()-ROUNDDOWN(NOW(),0) -> 0.80654178
A16: รวมกะที่ 3 | E16: =SUM(E13:E15) -> 0 | F16: =SUM(F13:F15) -> 0 | G16: =SUM(G13:G15) -> 0 | H16: หมายเหตุ | L16: ใช้ปูน | M16: =IF(ISBLANK(Data!X17),"",Data!X17) -> 0 | N16: Batch | O16: ทิ้งปูน | P16: =IF(ISBLANK(Data!Y17),"",Data!Y17) -> 0 | Q16: Batch | R16: ทิ้งสีพื้น | S16: =IF(ISBLANK(Data!W17),"",Data!W17) -> 0 | T16: ถัง | U16: =IF(ISBLANK(Data!AH17),"",Data!AH17) -> 0 | V16: ถัง | Y16: =Y15 -> 0.95833333 | Z16: =Z15 -> 0.75 | AA16: =AA15 -> 0.95833333 | AB16: =AB15 -> 0.25 | AC16: =AC15 -> 0.35416667 | AD16: =AD15 -> 0.80654178
H17: ปริมาณการใช้รวม | L17: =SUM(L5,L9,L13) -> 0 | M17: =SUM(M5,M9,M13) -> 0 | N17: =SUM(N5,N9,N13) -> 0 | O17: =SUM(O5,O9,O13) -> 0 | P17: =SUM(P5,P9,P13) -> 0 | Q17: =SUM(Q5,Q9,Q13) -> 0 | R17: =SUM(R5,R9,R13) -> 0 | S17: =SUM(S5,S9,S13) -> 0 | ... V17: =SUM(V5,V9,V13) -> 0
A18: รวมทุกกะ | E18: =E8+E12+E16 -> 0 | F18: =F8+F12+F16 -> 0 | G18: =G8+G12+G16 -> 0 | H18: คำนวณจาก Counter (ต่อพันแผ่น) | L18: =IF($F$18=0,0,L17*1000/$F$18) -> 0 | M18: =IF($F$18=0,0,M17*1000/$F$18) -> 0 | N18: =IF($F$18=0,0,N17*1000/$F$18) -> 0 | O18: =IF($F$18=0,0,O17*1000/$F$18) -> 0 | P18: =IF($F$18=0,0,P17*1000/$F$18) -> 0 | Q18: =IF($F$18=0,0,Q17*1000/$F$18) -> 0 | R18: =IF($F$18=0,0,R17*1000/$F$18) -> 0 | S18: =IF($F$18=0,0,S17*1000/$F$18) -> 0 | T18: =IF(T17=0,0,F18/T17) -> 0 | U18: =IF(U17=0,0,(Data!U1+Data!U9+Data!U16)/U17) -> 0 | V18: =IF(V17=0,0,(Data!V1+Data!V9+Data!V16)/V17) -> 0
H19: คำนวณจาก ห้องบ่ม (ต่อพันแผ่น) | L19: =IF($G$18=0,0,L17*1000/$G$18) -> 0 | M19: =IF($G$18=0,0,M17*1000/$G$18) -> 0 | N19: =IF($G$18=0,0,N17*1000/$G$18) -> 0 | O19: =IF($G$18=0,0,O17*1000/$G$18) -> 0 | P19: =IF($G$18=0,0,P17*1000/$G$18) -> 0 | Q19: =IF($G$18=0,0,Q17*1000/$G$18) -> 0 | R19: =IF($G$18=0,0,R17*1000/$G$18) -> 0 | S19: =IF($G$18=0,0,S17*1000/$G$18) -> 0 | T19: =IF(T17=0,0,G18/T17) -> 0 | U19: =IF(U17=0,0,(Data!X1+Data!X9+Data!X16)/U17) -> 0 | V19: =IF(V17=0,0,(Data!Y1+Data!Y9+Data!Y16)/V17) -> 0
A21: รายงานการแกะกระเบื้อง | I21: รายละเอียดกระเบื้องเสีย | R21: แผ่นดีนำไปกองเก็บ | T21: หมายเหตุ
A22: กะที่ | B22: LOT NO. | C22: ลอน | D22: สี | E22: จำนวนที่นำมาแกะ | F22: แผ่นดี | G22: Reject | I22: แผ่นเสีย | J22: รอยขูด | K22: หัว/ชาย ก/บ | L22: สี | M22: GEP | N22: สิ่งสกปรก ติดผิว | O22: บิ่น, แหว่ง | P22: Collator | Q22: อื่น ๆ | R22: บริเวณ / แถวที่
B23: =IF(ISBLANK(Data!E33),"",Data!E33) | C23: =IF(B23=""," ",UPPER(LEFT(Data!F33,3))) | D23: =IF(ISBLANK(Data!G33),"",Data!G33) | E23: =IF(ISBLANK(Data!H33),0,Data!H33) -> 0 | F23: =E23-I23 -> 0 | G23: =IF(E23=0,"",(E23-F23)/E23) | I23: =SUM(J23:Q23) -> 0 | J23: =IF(ISBLANK(Data!J33),"",Data!J33) | K23: =IF(ISBLANK(Data!K33),"",Data!K33) | L23: =IF(ISBLANK(Data!L33),"",Data!L33) | M23: =IF(ISBLANK(Data!M33),"",Data!M33) | N23: =IF(ISBLANK(Data!N33),"",Data!N33) | O23: =IF(ISBLANK(Data!O33),"",Data!O33) | P23: =IF(ISBLANK(Data!P33),"",Data!P33) | Q23: =IF(ISBLANK(Data!Q33),"",Data!Q33) | R23: =IF(ISBLANK(Data!S33),"",Data!S33)
A24: 1 | B24: =IF(ISBLANK(Data!E36),"",Data!E36) | C24: =IF(B24=""," ",UPPER(LEFT(Data!F36,3))) | D24: =IF(ISBLANK(Data!G36),"",Data!G36) | E24: =IF(ISBLANK(Data!H36),0,Data!H36) -> 0 | F24: =E24-I24 -> 0 | G24: =IF(E24=0,"",(E24-F24)/E24) | I24: =SUM(J24:Q24) -> 0 | J24: =IF(ISBLANK(Data!J36),"",Data!J36) | K24: =IF(ISBLANK(Data!K36),"",Data!K36) | L24: =IF(ISBLANK(Data!L36),"",Data!L36) | M24: =IF(ISBLANK(Data!M36),"",Data!M36) | N24: =IF(ISBLANK(Data!N36),"",Data!N36) | O24: =IF(ISBLANK(Data!O36),"",Data!O36) | P24: =IF(ISBLANK(Data!P36),"",Data!P36) | Q24: =IF(ISBLANK(Data!Q36),"",Data!Q36) | R24: =IF(ISBLANK(Data!S36),"",Data!S36)
B25: =IF(ISBLANK(Data!E37),"",Data!E37) | C25: =IF(B25=""," ",UPPER(LEFT(Data!F37,3))) | D25: =IF(ISBLANK(Data!G37),"",Data!G37) | E25: =IF(ISBLANK(Data!H37),0,Data!H37) -> 0 | F25: =E25-I25 -> 0 | G25: =IF(E25=0,"",(E25-F25)/E25) | I25: =SUM(J25:Q25) -> 0 | J25: =IF(ISBLANK(Data!J37),"",Data!J37) | K25: =IF(ISBLANK(Data!K37),"",Data!K37) | L25: =IF(ISBLANK(Data!L37),"",Data!L37) | M25: =IF(ISBLANK(Data!M37),"",Data!M37) | N25: =IF(ISBLANK(Data!N37),"",Data!N37) | O25: =IF(ISBLANK(Data!O37),"",Data!O37) | P25: =IF(ISBLANK(Data!P37),"",Data!P37) | Q25: =IF(ISBLANK(Data!Q37),"",Data!Q37) | R25: =IF(ISBLANK(Data!S37),"",Data!S37)
A26: รวมกะที่ 1 | E26: =SUM(E23:E25) -> 0 | F26: =SUM(F23:F25) -> 0 | G26: =IF(E26=0,"",(E26-F26)/E26) | I26: =SUM(J26:Q26) -> 0 | J26: =SUM(J23:J25) -> 0 | K26: =SUM(K23:K25) -> 0 | L26: =SUM(L23:L25) -> 0 | M26: =SUM(M23:M25) -> 0 | N26: =SUM(N23:N25) -> 0 | O26: =SUM(O23:O25) -> 0 | P26: =SUM(P23:P25) -> 0 | Q26: =SUM(Q23:Q25) -> 0
B27: =IF(ISBLANK(Data!E48),"",Data!E48) | C27: =IF(B27=""," ",UPPER(LEFT(Data!F48,3))) | D27: =IF(ISBLANK(Data!G48),"",Data!G48) | E27: =IF(ISBLANK(Data!H48),0,Data!H48) -> 0 | F27: =E27-I27 -> 0 | G27: =IF(E27=0,"",(E27-F27)/E27) | I27: =SUM(J27:Q27) -> 0 | J27: =IF(ISBLANK(Data!J48),"",Data!J48) | K27: =IF(ISBLANK(Data!K48),"",Data!K48) | L27: =IF(ISBLANK(Data!L48),"",Data!L48) | M27: =IF(ISBLANK(Data!M48),"",Data!M48) | N27: =IF(ISBLANK(Data!N48),"",Data!N48) | O27: =IF(ISBLANK(Data!O48),"",Data!O48) | P27: =IF(ISBLANK(Data!P48),"",Data!P48) | Q27: =IF(ISBLANK(Data!Q48),"",Data!Q48) | R27: =IF(ISBLANK(Data!S48),"",Data!S48)
A28: 2 | B28: =IF(ISBLANK(Data!E49),"",Data!E49) | C28: =IF(B28=""," ",UPPER(LEFT(Data!F49,3))) | D28: =IF(ISBLANK(Data!G49),"",Data!G49) | E28: =IF(ISBLANK(Data!H49),0,Data!H49) -> 0 | F28: =E28-I28 -> 0 | G28: =IF(E28=0,"",(E28-F28)/E28) | I28: =SUM(J28:Q28) -> 0 | J28: =IF(ISBLANK(Data!J49),"",Data!J49) | K28: =IF(ISBLANK(Data!K49),"",Data!K49) | L28: =IF(ISBLANK(Data!L49),"",Data!L49) | M28: =IF(ISBLANK(Data!M49),"",Data!M49) | N28: =IF(ISBLANK(Data!N49),"",Data!N49) | O28: =IF(ISBLANK(Data!O49),"",Data!O49) | P28: =IF(ISBLANK(Data!P49),"",Data!P49) | Q28: =IF(ISBLANK(Data!Q49),"",Data!Q49) | R28: =IF(ISBLANK(Data!S49),"",Data!S49)
B29: =IF(ISBLANK(Data!E50),"",Data!E50) | C29: =IF(B29=""," ",UPPER(LEFT(Data!F50,3))) | D29: =IF(ISBLANK(Data!G50),"",Data!G50) | E29: =IF(ISBLANK(Data!H50),0,Data!H50) -> 0 | F29: =E29-I29 -> 0 | G29: =IF(E29=0,"",(E29-F29)/E29) | I29: =SUM(J29:Q29) -> 0 | J29: =IF(ISBLANK(Data!J50),"",Data!J50) | K29: =IF(ISBLANK(Data!K50),"",Data!K50) | L29: =IF(ISBLANK(Data!L50),"",Data!L50) | M29: =IF(ISBLANK(Data!M50),"",Data!M50) | N29: =IF(ISBLANK(Data!N50),"",Data!N50) | O29: =IF(ISBLANK(Data!O50),"",Data!O50) | P29: =IF(ISBLANK(Data!P50),"",Data!P50) | Q29: =IF(ISBLANK(Data!Q50),"",Data!Q50) | R29: =IF(ISBLANK(Data!S50),"",Data!S50)
A30: รวมกะที่ 2 | E30: =SUM(E27:E29) -> 0 | F30: =SUM(F27:F29) -> 0 | G30: =IF(E30=0,"",(E30-F30)/E30) | I30: =SUM(J30:Q30) -> 0 | J30: =SUM(J27:J29) -> 0 | K30: =SUM(K27:K29) -> 0 | L30: =SUM(L27:L29) -> 0 | M30: =SUM(M27:M29) -> 0 | N30: =SUM(N27:N29) -> 0 | O30: =SUM(O27:O29) -> 0 | P30: =SUM(P27:P29) -> 0 | Q30: =SUM(Q27:Q29) -> 0
B31: =IF(ISBLANK(Data!E58),"",Data!E58) | C31: =IF(B31=""," ",UPPER(LEFT(Data!F58,3))) | D31: =IF(ISBLANK(Data!G58),"",Data!G58) | E31: =IF(ISBLANK(Data!H58),0,Data!H58) -> 0 | F31: =E31-I31 -> 0 | G31: =IF(E31=0,"",(E31-F31)/E31) | I31: =SUM(J31:Q31) -> 0 | J31: =IF(ISBLANK(Data!J58),"",Data!J58) | K31: =IF(ISBLANK(Data!K58),"",Data!K58) | L31: =IF(ISBLANK(Data!L58),"",Data!L58) | M31: =IF(ISBLANK(Data!M58),"",Data!M58) | N31: =IF(ISBLANK(Data!N58),"",Data!N58) | O31: =IF(ISBLANK(Data!O58),"",Data!O58) | P31: =IF(ISBLANK(Data!P58),"",Data!P58) | Q31: =IF(ISBLANK(Data!Q58),"",Data!Q58) | R31: =IF(ISBLANK(Data!S58),"",Data!S58)
A32: 3 | B32: =IF(ISBLANK(Data!E59),"",Data!E59) | C32: =IF(B32=""," ",UPPER(LEFT(Data!F59,3))) | D32: =IF(ISBLANK(Data!G59),"",Data!G59) | E32: =IF(ISBLANK(Data!H59),0,Data!H59) -> 0 | F32: =E32-I32 -> 0 | G32: =IF(E32=0,"",(E32-F32)/E32) | I32: =SUM(J32:Q32) -> 0 | J32: =IF(ISBLANK(Data!J59),"",Data!J59) | K32: =IF(ISBLANK(Data!K59),"",Data!K59) | L32: =IF(ISBLANK(Data!L59),"",Data!L59) | M32: =IF(ISBLANK(Data!M59),"",Data!M59) | N32: =IF(ISBLANK(Data!N59),"",Data!N59) | O32: =IF(ISBLANK(Data!O59),"",Data!O59) | P32: =IF(ISBLANK(Data!P59),"",Data!P59) | Q32: =IF(ISBLANK(Data!Q59),"",Data!Q59) | R32: =IF(ISBLANK(Data!S59),"",Data!S59)
B33: =IF(ISBLANK(Data!E60),"",Data!E60) | C33: =IF(B33=""," ",UPPER(LEFT(Data!F60,3))) | D33: =IF(ISBLANK(Data!G60),"",Data!G60) | E33: =IF(ISBLANK(Data!H60),0,Data!H60) -> 0 | F33: =E33-I33 -> 0 | G33: =IF(E33=0,"",(E33-F33)/E33) | I33: =SUM(J33:Q33) -> 0 | J33: =IF(ISBLANK(Data!J60),"",Data!J60) | K33: =IF(ISBLANK(Data!K60),"",Data!K60) | L33: =IF(ISBLANK(Data!L60),"",Data!L60) | M33: =IF(ISBLANK(Data!M60),"",Data!M60) | N33: =IF(ISBLANK(Data!N60),"",Data!N60) | O33: =IF(ISBLANK(Data!O60),"",Data!O60) | P33: =IF(ISBLANK(Data!P60),"",Data!P60) | Q33: =IF(ISBLANK(Data!Q60),"",Data!Q60) | R33: =IF(ISBLANK(Data!S60),"",Data!S60)
A34: รวมกะที่ 3 | E34: =SUM(E31:E33) -> 0 | F34: =SUM(F31:F33) -> 0 | G34: =IF(E34=0,"",(E34-F34)/E34) | I34: =SUM(J34:Q34) -> 0 | J34: =SUM(J31:J33) -> 0 | K34: =SUM(K31:K33) -> 0 | L34: =SUM(L31:L33) -> 0 | M34: =SUM(M31:M33) -> 0 | N34: =SUM(N31:N33) -> 0 | O34: =SUM(O31:O33) -> 0 | P34: =SUM(P31:P33) -> 0 | Q34: =SUM(Q31:Q33) -> 0
A35: รวมทุกกะ | E35: =E26+E30+E34 -> 0 | F35: =F26+F30+F34 -> 0 | G35: =IF(E35=0,"",(E35-F35)/E35) | I35: =SUM(J35:Q35) -> 0 | J35: =SUM(J34,J30,J26) -> 0 | K35: =SUM(K34,K30,K26) -> 0 | L35: =SUM(L34,L30,L26) -> 0 | M35: =SUM(M34,M30,M26) -> 0 | N35: =SUM(N34,N30,N26) -> 0 | O35: =SUM(O34,O30,O26) -> 0 | P35: =SUM(P34,P30,P26) -> 0 | Q35: =SUM(Q34,Q30,Q26) -> 0
A37: ผู้ทำรายงาน | E37: หม.ผลิต | I37: หง.ผ | L37: หม.จัดบรรทุก | P37: พ.จ่ายสินค้า | S37: ผร.
A39: สำเนาเรียน : หัวหน้างานวางแผนผลิต, พนักงานควบคุมคุณภาพ | T39: GN-F-PD-112 (1 กรกฎาคม 2547)
J45: เทียบมาตรฐานการใช้จาก Counter | L45: ปูนซีเมนต์ | M45: ปูนซีเมนต์ | N45: ทราย | O45: ทราย | P45: น้ำมัน | Q45: น้ำยา | R45: จีซี 2 | S45: สีพื้น | T45: สีเหลือบ | U45: สีเหลือบ
H46: ปริมาณการใช้วัตถุดิบ | L46: ผสมตัว | M46: ผสมสี | N46: ผสมตัว | O46: ผสมสี | P46: พ่นแบบ | Q46: เคลือบผิว
L47: (ตัน) | M47: (ตัน) | N47: (ตัน) | O47: (ตัน) | P47: (ลิตร) | Q47: (ลิตร) | R47: (ลิตร) | S47: (แผ่น/ถัง) | T47: (แผ่น/ถัง) | U47: (แผ่น/ถัง)
H48: มาตรฐานการใช้วัตถุดิบ | L48: =L16-$L$49 -> #VALUE! | M48: =N16-M49 -> #VALUE! | N48: =O16-N49 -> #VALUE! | O48: =P16-O49 -> -0.033 | P48: =Q16-P49 -> #VALUE! | Q48: =R16-Q49 -> #VALUE! | R48: =S16-R49 -> -0.4 | S48: =T16-S49 -> #VALUE! | T48: =U16-T49 -> -2500 | U48: =V16-U49 -> #VALUE!
...

Sheet สมรรถภาพการผลิต_
A1: รายงานสมรรถภาพการผลิตประจำวัน | E1: =รายงานการผลิต!F1 -> โรงงานนครปฐม ครอบชนผนัง | J1: ความเร็วเครื่องจักร | K1: 34 | L1: วันที่ | M1: =รายงานการผลิต!O1 -> 242754
B2: เวลา | D2: เวลา | F2: Tile Counter | K2: จำนวนกระเบื้อง
A3: กะ | B3: เริ่มทำงาน | C3: เลิกงาน | D3: ทำงานรวม | E3: ก่อนผลิต | H3: หลังผลิต | J3: ที่รีดได้ | K3: ในห้องบ่ม | L3: คัดเปียก
A4: 1 | B4: =IF(ISBLANK(Data!E65),"",Data!E65) -> 0.33333333 | C4: =IF(ISBLANK(Data!F65),"",Data!F65) -> 0.66666667 | D4: =IF(C4=0,0,IF(B4=0,0,IF(C4>B4,C4*60/0.041666666667-B4*60/0.04166666667,0))) -> 480 | E4: 1997909 | H4: =E4+J4 -> 1998684 | J4: =รายงานการผลิต!F10 -> 775 | K4: =รายงานการผลิต!G10 -> 705 | L4: =J4-K4 -> 70 | P4: =D4+D5+D6 -> 480
A5: 2 | B5: =IF(ISBLANK(Data!E77),"",Data!E77) | C5: =IF(ISBLANK(Data!F77),"",Data!F77) | D5: =IF(C5="",0,IF(B5="",0,IF(C5>B5,(C5-B5)*60/0.041666666667,(1-B5)*60/0.0416666666667+C5*60/0.041666666667))) -> 0 | E5: 0 | H5: =E5+J5 -> 520 | J5: =รายงานการผลิต!F15 -> 520 | K5: =รายงานการผลิต!G15 -> 500 | L5: =J5-K5 -> 20
A6: 3 | B6: =IF(ISBLANK(Data!E83),"",Data!E83) | C6: =IF(ISBLANK(Data!F83),"",Data!F83) | D6: =IF(C5="",0,IF(B5="",0,IF(C5>B5,(C5-B5)*60/0.041666666667,(1-B5)*60/0.0416666666667+C5*60/0.041666666667))) -> 0 | E6: 0 | H6: =E6+J6 -> 0 | J6: =รายงานการผลิต!F19 -> 0 | K6: =รายงานการผลิต!G19 -> 0 | L6: =J6-K6 -> 0
A7: (ก) เวลาหยุดจากแผนผลิต (นาที) | E7: กะ 1 | F7: กะ 2 | G7: กะ 3 | H7: รวม | I7: (ค) เวลาหยุดซ่อมเครื่อง (นาที) | L7: กะ 1 | M7: กะ 2 | N7: กะ 3 | O7: รวม | Q7: การ SAVE FILE
A8: ก.1 เตรียมการผลิต | E8: =IF(ISBLANK(Data!H65),0,Data!H65) -> 10 | F8: =IF(ISBLANK(Data!$H77),0,Data!$H77) -> 0 | G8: =IF(ISBLANK(Data!$H83),0,Data!$H83) -> 0 | H8: =SUM(E8:G8) -> 10 | I8: เครื่องจักรเสียตั้งแต่ 10 นาทีขึ้นไป | L8: =IF(ISBLANK(Data!T$65),0,Data!T$65) -> 0 | M8: =IF(ISBLANK(Data!T$77),0,Data!T$77) -> 0 | N8: =IF(ISBLANK(Data!T$83),0,Data!T$83) -> 0 | O8: =SUM(L8:N8) -> 0 | Q8: ให้ SAVE FILE เป็น Format ดังนี้ครับ
A9: ก.2 หยุดเปลี่ยนสี | E9: =IF(ISBLANK(Data!I65),0,Data!I65) -> 10 | F9: =IF(ISBLANK(Data!$I77),0,Data!$I77) -> 0 | G9: =IF(ISBLANK(Data!$I83),0,Data!$I83) -> 0 | H9: =SUM(E9:G9) -> 10 | I9: (ดังรายละเอียดข้างล่าง) | O9: =SUM(L9:N9) -> 0 | Q9: เช่น โรงงานสระบุรี 2 ข้อมูลวันที่ 1 กุมภาพันธ์ 2547
A10: ก.3 หยุดเปลี่ยนลอน | E10: =IF(ISBLANK(Data!J65),0,Data!J65) -> 20 | F10: =IF(ISBLANK(Data!$J77),0,Data!$J77) -> 0 | G10: =IF(ISBLANK(Data!$J83),0,Data!$J83) -> 0 | H10: =SUM(E10:G10) -> 20 | O10: =SUM(L10:N10) -> 0 | Q10: ให้ SAVE เป็น
A11: ก.4 ทำความสะอาดหลังผลิต | E11: =IF(ISBLANK(Data!K65),0,Data!K65) -> 30 | F11: =IF(ISBLANK(Data!$K77),0,Data!$K77) -> 0 | G11: =IF(ISBLANK(Data!$K83),0,Data!$K83) -> 0 | H11: =SUM(E11:G11) -> 30 | O11: =SUM(L11:N11) -> 0 | Q11: sb2_010247.xls
A12: รวมเวลาหยุด (ก) | E12: =SUM(E8:E11) -> 70 | F12: =SUM(F8:F11) -> 0 | G12: =SUM(G8:G11) -> 0 | H12: =SUM(E12:G12) -> 70 | I12: รวมเวลาหยุด (ค) | L12: =SUM(L8:L11) -> 0 | M12: =SUM(M8:M11) -> 0 | N12: =SUM(N8:N11) -> 0 | O12: =SUM(L12:N12) -> 0 | Q12: โรงงานอื่นๆ : lp , sb1 , np1 , np2 , cb , kk , ns
A13: (ข) เวลาหยุดระหว่างผลิต (นาที) | E13: กะ 1 | F13: กะ 2 | G13: กะ 3 | H13: รวม | I13: (ง) เวลาหยุดจากปัจจัยภายนอก (นาที) | L13: กะ 1 | M13: กะ 2 | N13: กะ 3 | O13: รวม | Q13: ** สำคัญมากครับ เพราะจะใช้ในการดึงข้อมูลลงโปรแกรม
A14: ข.1 ปรับตั้งเครื่องจักร | E14: =IF(ISBLANK(Data!L$65),0,Data!L$65) -> 0 | F14: =IF(ISBLANK(Data!L$77),0,Data!L$77) -> 0 | G14: =IF(ISBLANK(Data!L$83),0,Data!L$83) -> 0 | H14: =SUM(E14:G14) -> 0 | I14: ง.1 ไม่มีแผนผลิต | L14: =IF(ISBLANK(Data!U$65),0,Data!U$65) -> 0 | M14: =IF(ISBLANK(Data!U$77),0,Data!U$77) -> 0 | N14: =IF(ISBLANK(Data!U$83),0,Data!U$83) -> 0 | O14: =SUM(L14:N14) -> 0
A15: ข.2 ผู้รับเหมาไม่มา/ทำไม่ทัน | E15: =IF(ISBLANK(Data!M$65),0,Data!M$65) -> 0 | F15: =IF(ISBLANK(Data!M$77),0,Data!M$77) -> 0 | G15: =IF(ISBLANK(Data!M$83),0,Data!M$83) -> 0 | H15: =SUM(E15:G15) -> 0 | I15: ง.2 ทดลองผลิต | L15: =IF(ISBLANK(Data!V$65),0,Data!V$65) -> 0 | M15: =IF(ISBLANK(Data!V$77),0,Data!V$77) -> 0 | N15: =IF(ISBLANK(Data!V$83),0,Data!V$83) -> 0 | O15: =SUM(L15:N15) -> 0 | Q15: *** ก่อนการส่ง file ให้กับ คุณสามารถ ช่วยพิจารณาความถูกต้อง
A16: ข.3 fork Lift เสีย/วิ่งไม่ทัน | E16: =IF(ISBLANK(Data!N$65),0,Data!N$65) -> 0 | F16: =IF(ISBLANK(Data!N$77),0,Data!N$77) -> 0 | G16: =IF(ISBLANK(Data!N$83),0,Data!N$83) -> 0 | H16: =SUM(E16:G16) -> 0 | I16: ง.3 ที่กองเต็ม | L16: =IF(ISBLANK(Data!W$65),0,Data!W$65) -> 0 | M16: =IF(ISBLANK(Data!W$77),0,Data!W$77) -> 0 | N16: =IF(ISBLANK(Data!W$83),0,Data!W$83) -> 0 | O16: =SUM(L16:N16) -> 0 | Q16: ของข้อมูลก่อนนะครับ เพราะถ้าส่งมาให้แล้วจะถือว่าข้อมูลนั้นถูกต้อง
A17: ข.4 วัตถุดิบหมด | E17: =IF(ISBLANK(Data!O$65),0,Data!O$65) -> 0 | F17: =IF(ISBLANK(Data!O$77),0,Data!O$77) -> 0 | G17: =IF(ISBLANK(Data!O$83),0,Data!O$83) -> 0 | H17: =SUM(E17:G17) -> 0 | I17: ง.4 ไฟฟ้าดับ/น้ำประปาไม่ไหล | L17: =IF(ISBLANK(Data!X$65),0,Data!X$65) -> 0 | M17: =IF(ISBLANK(Data!X$77),0,Data!X$77) -> 0 | N17: =IF(ISBLANK(Data!X$83),0,Data!X$83) -> 0 | O17: =SUM(L17:N17) -> 0 | Q17: สามารถนำไปใช้ประมวลผลให้ ผฝ.ผ.ต่อไปครับ ***
A18: ข.5 เครื่องจักรหยุด <10 นาที | E18: =IF(ISBLANK(Data!P$65),0,Data!P$65) -> 0 | F18: =IF(ISBLANK(Data!P$77),0,Data!P$77) -> 0 | G18: =IF(ISBLANK(Data!P$83),0,Data!P$83) -> 0 | H18: =SUM(E18:G18) -> 0 | I18: ง.5 กระเบื้องไม่แห้งรอแกะ | L18: =IF(ISBLANK(Data!Y$65),0,Data!Y$65) -> 0 | M18: =IF(ISBLANK(Data!Y$77),0,Data!Y$77) -> 0 | N18: =IF(ISBLANK(Data!Y$83),0,Data!Y$83) -> 0 | O18: =SUM(L18:N18) -> 0
A19: ข.6 ทำความสะอาดหนามคุ้ยปูน | E19: =IF(ISBLANK(Data!Q$65),0,Data!Q$65) -> 0 | F19: =IF(ISBLANK(Data!Q$77),0,Data!Q$77) -> 0 | G19: =IF(ISBLANK(Data!R$83),0,Data!R$83) -> 0 | H19: =SUM(E19:G19) -> 0 | I19: ง.6 อื่นๆ | L19: =IF(ISBLANK(Data!Z$65),0,Data!Z$65) -> 0 | M19: =IF(ISBLANK(Data!Z77),0,Data!Z$77) -> 0 | N19: =IF(ISBLANK(Data!Z$83),0,Data!Z$83) -> 0 | O19: =SUM(L19:N19) -> 0
A20: ข.7 อื่นๆ | E20: =IF(ISBLANK(Data!R$65),0,Data!R$65) -> 0 | F20: =IF(ISBLANK(Data!R$77),0,Data!R$77) -> 0 | G20: =IF(ISBLANK(Data!S$83),0,Data!S$83) -> 0 | H20: =SUM(E20:G20) -> 0
E21: =IF(ISBLANK(Data!S$65),0,Data!S$65) -> 0 | F21: =IF(ISBLANK(Data!S$77),0,Data!S$77) -> 0 | G21: =IF(ISBLANK(Data!T$83),0,Data!T$83) -> 0 | H21: =SUM(E21:G21) -> 0
A22: รวมเวลาหยุด (ข) | E22: =SUM(E14:E21) -> 0 | F22: =SUM(F14:F21) -> 0 | G22: =SUM(G14:G21) -> 0 | H22: =SUM(E22:G22) -> 0 | I22: รวมเวลาหยุด (ง) | L22: =SUM(L14:L19) -> 0 | M22: =SUM(M14:M19) -> 0 | N22: =SUM(N14:N19) -> 0 | O22: =SUM(L22:N22) -> 0
A23: ช่วงเวลาหยุด | C23: นาทีที่หยุด | D23: สาเหตุการหยุดเครื่องจักรเกิน 10 นาที | I23: *ประเภท | J23: รหัสอุปกรณ์หลัก | K23: การแก้ไข
A24: =IF(ISBLANK(Data!E85),"",Data!E85) | B24: =IF(ISBLANK(Data!F85),"",Data!F85) | C24: =IF(B24="",0,IF(A24=0,0,IF(B24>A24,(B24-A24)*60/0.041666666667,(1-A24)*60/0.04166666667+B24*60/0.0416666666667))) -> 0 | D24: =IF(ISBLANK(Data!H85),"",Data!H85) | I24: =IF(ISBLANK(Data!I85),"",Data!I85) | J24: =IF(ISBLANK(Data!J85),"",Data!J85) | K24: =IF(ISBLANK(Data!K85),"",Data!K85)
A25: =IF(ISBLANK(Data!E86),"",Data!E86) | B25: =IF(ISBLANK(Data!F86),"",Data!F86) | C25: =IF(B25="",0,IF(A25=0,0,IF(B25>A25,(B25-A25)*60/0.041666666667,(1-A25)*60/0.04166666667+B25*60/0.0416666666667))) -> 0 | D25: =IF(ISBLANK(Data!H86),"",Data!H86) | I25: =IF(ISBLANK(Data!I86),"",Data!I86) | J25: =IF(ISBLANK(Data!J86),"",Data!J86) | K25: =IF(ISBLANK(Data!K86),"",Data!K86) | Q25: กะที่ 1
A26: =IF(ISBLANK(Data!E87),"",Data!E87) | B26: =IF(ISBLANK(Data!F87),"",Data!F87) | C26: =IF(B26="",0,IF(A26=0,0,IF(B26>A26,(B26-A26)*60/0.041666666667,(1-A26)*60/0.04166666667+B26*60/0.0416666666667))) -> 0 | D26: =IF(ISBLANK(Data!H87),"",Data!H87) | I26: =IF(ISBLANK(Data!I87),"",Data!I87) | J26: =IF(ISBLANK(Data!J87),"",Data!J87) | K26: =IF(ISBLANK(Data!K87),"",Data!K87)
A27: =IF(ISBLANK(Data!E91),"",Data!E91) | B27: =IF(ISBLANK(Data!F91),"",Data!F91) | C27: =IF(B27="",0,IF(A27=0,0,IF(B27>A27,(B27-A27)*60/0.041666666667,(1-A27)*60/0.04166666667+B27*60/0.0416666666667))) -> 0 | D27: =IF(ISBLANK(Data!H91),"",Data!H91) | I27: =IF(ISBLANK(Data!I91),"",Data!I91) | J27: =IF(ISBLANK(Data!J91),"",Data!J91) | K27: =IF(ISBLANK(Data!K91),"",Data!K91)
A28: =IF(ISBLANK(Data!E92),"",Data!E92) | B28: =IF(ISBLANK(Data!F92),"",Data!F92) | C28: =IF(B28="",0,IF(A28=0,0,IF(B28>A28,(B28-A28)*60/0.041666666667,(1-A28)*60/0.04166666667+B28*60/0.0416666666667))) -> 0 | D28: =IF(ISBLANK(Data!H92),"",Data!H92) | I28: =IF(ISBLANK(Data!I92),"",Data!I92) | J28: =IF(ISBLANK(Data!J92),"",Data!J92) | K28: =IF(ISBLANK(Data!K92),"",Data!K92) | Q28: กะที่ 2
A29: =IF(ISBLANK(Data!#REF!),"",Data!#REF!) -> #REF! | B29: =IF(ISBLANK(Data!#REF!),"",Data!#REF!) -> #REF! | C29: =IF(B29="",0,IF(A29=0,0,IF(B29>A29,(B29-A29)*60/0.041666666667,(1-A29)*60/0.04166666667+B29*60/0.0416666666667))) -> #REF! | D29: =IF(ISBLANK(Data!#REF!),"",Data!#REF!) -> #REF! | I29: =IF(ISBLANK(Data!#REF!),"",Data!#REF!) -> #REF! | J29: =IF(ISBLANK(Data!#REF!),"",Data!#REF!) -> #REF! | K29: =IF(ISBLANK(Data!#REF!),"",Data!#REF!) -> #REF!
A30: =IF(ISBLANK(Data!E96),"",Data!E96) | B30: =IF(ISBLANK(Data!F96),"",Data!F96) | C30: =IF(B30="",0,IF(A30=0,0,IF(B30>A30,(B30-A30)*60/0.041666666667,(1-A30)*60/0.04166666667+B30*60/0.0416666666667))) -> 0 | D30: =IF(ISBLANK(Data!H96),"",Data!H96) | I30: =IF(ISBLANK(Data!I96),"",Data!I96) | J30: =IF(ISBLANK(Data!J96),"",Data!J96) | K30: =IF(ISBLANK(Data!K96),"",Data!K96)
A31: =IF(ISBLANK(Data!E97),"",Data!E97) | B31: =IF(ISBLANK(Data!F97),"",Data!F97) | C31: =IF(B31="",0,IF(A31=0,0,IF(B31>A31,(B31-A31)*60/0.041666666667,(1-A31)*60/0.04166666667+B31*60/0.0416666666667))) -> 0 | D31: =IF(ISBLANK(Data!H97),"",Data!H97) | I31: =IF(ISBLANK(Data!I97),"",Data!I97) | J31: =IF(ISBLANK(Data!J97),"",Data!J97) | K31: =IF(ISBLANK(Data!K97),"",Data!K97) | Q31: กะที่ 3
A32: =IF(ISBLANK(Data!#REF!),"",Data!#REF!) -> #REF! | B32: =IF(ISBLANK(Data!#REF!),"",Data!#REF!) -> #REF! | C32: =IF(B32="",0,IF(A32=0,0,IF(B32>A32,(B32-A32)*60/0.041666666667,(1-A32)*60/0.04166666667+B32*60/0.0416666666667))) -> #REF! | D32: =IF(ISBLANK(Data!#REF!),"",Data!#REF!) -> #REF! | I32: =IF(ISBLANK(Data!#REF!),"",Data!#REF!) -> #REF! | J32: =IF(ISBLANK(Data!#REF!),"",Data!#REF!) -> #REF! | K32: =IF(ISBLANK(Data!#REF!),"",Data!#REF!) -> #REF!
A33: ลำดับ | C33: ผลสรุปการผลิต | I33: การคำนวณ | L33: กะ 1 | M33: กะ 2 | N33: กะ 3 | O33: รวม
A34: (1) | B34: เวลาที่ทำการผลิต | F34: เวลาทำงานรวม - (ก) - (ง) | L34: =D4-E12-L22 -> 410 | M34: =D5-F12-M22 -> 0 | N34: =D6-G12-N22 -> 0 | O34: =SUM(L34:N34) -> 410
A35: (2) | B35: เวลาที่เสียในการคัดกระเบื้องเปียก | F35: จำนวนคัดเปียก / ความเร็วเครื่อง | L35: =IF(L34=0,"0",L4/K1) -> 2.0588235 | M35: =IF(M34=0,"0",L5/K1) -> 0 | N35: =IF(N34=0,"0",L6/K1) -> 0 | O35: =SUM(L35:N35) -> 2.0588235
A36: (3) | B36: เวลาที่ใช้ผลิตและได้ผลผลิต | F36: จำนวนในห้องบ่ม / ความเร็วเครื่อง | L36: =IF(L34=0,"0",K4/K1) -> 20.735294 | M36: =IF(M34=0,"0",K5/K1) -> 0 | N36: =IF(N34=0,"0",K6/K1) -> 0 | O36: =SUM(L36:N36) -> 20.735294
A37: (4) | B37: % Plan Stop | F37: (ก) / เวลาทำงานรวม x 100 | L37: =+E12/D4*100 -> 14.583333 | M37: =IF(D5=0,0,+F12/D5*100) -> 0 | N37: =IF(D6=0,0,+G12/D6*100) -> 0 | O37: =H12/(D4+D5+D6)*100 -> 14.583333
A38: (5) | B38: % Plant Idle | F38: (ง) / เวลาทำงานรวม x 100 | L38: =+L22/D4*100 -> 0 | M38: =IF(D5=0,"0",+M22/D5*100) -> 0 | N38: =IF(D6=0,0,+N22/D6*100) -> 0 | O38: =O22/(D4+D5+D6)*100 -> 0 | Q38: รวมกันได้ 100% | R38: =SUM(O37:O39) -> 100
A39: (6) | B39: % Availability Rate (AR) | F39: (1) / เวลาทำงานรวม x 100 | L39: =+L34/D4*100 -> 85.416667 | M39: =IF(D5=0,0,+M34/D5*100) -> 0 | N39: =IF(D6=0,0,+N34/D6*100) -> 0 | O39: =O34/(D4+D5+D6)*100 -> 85.416667 | Q39: =SUM(L37:L39) -> 100
A40: (7) | B40: % In-process Loss | F40: (2) / (1) x 100 | L40: =+L35/L34*100 -> 0.50215208 | M40: =IF(M34=0,0,+M35/M34*100) -> 0 | N40: =IF(N34=0,0,+N35/N34*100) -> 0 | O40: =O35/O34*100 -> 0.50215208
...

Sheet กราฟ
B1: AR | C1: PR | D1: QR | E1: OEE
A2: 1 | B2: ='1'!V$60 -> 93.022415 | C2: ='1'!V$63 -> 46.884311 | D2: ='1'!V$64 -> 94.160087 | E2: ='1'!V$65 -> 41.065962
A3: 2 | B3: ='2'!V$60 -> 0 | C3: ='2'!V$63 -> 0 | D3: ='2'!V$64 -> 0 | E3: ='2'!V$65 -> 0
A4: 3 | B4: ='[3]3'!V$60 -> #REF! | C4: ='[3]3'!V$63 -> #REF! | D4: ='[3]3'!V$64 -> #REF! | E4: ='[3]3'!V$65 -> #REF!
A5: 4 | B5: ='4'!V$60 -> 97.022094 | C5: ='4'!V$63 -> 63.158887 | D5: ='4'!V$64 -> 87.45838 | E5: ='4'!V$65 -> 53.592812
A6: 5 | B6: ='5'!V$61 -> 90.304382 | C6: ='5'!V$64 -> 62.918301 | D6: ='5'!V$65 -> 90.181247 | E6: ='5'!V$66 -> 51.239166
A7: 6 | B7: ='6'!V$60 -> 88.447937 | C7: ='6'!V$63 -> 76.292018 | D7: ='6'!V$64 -> 89.273956 | E7: ='6'!V$65 -> 60.24092
A8: 7 | B8: ='7'!V$66 -> 89.927679 | C8: ='7'!V$69 -> 60.998197 | D8: ='7'!V$70 -> 86.024451 | E8: ='7'!V$71 -> 47.188078
A9: 8 | B9: ='8'!V$60 -> 91.838006 | C9: ='8'!V$63 -> 57.473994 | D9: ='8'!V$64 -> 87.97728 | E9: ='8'!V$65 -> 46.437021
A10: 9 | B10: ='9'!V$60 -> 0 | C10: ='9'!V$63 -> 0 | D10: ='9'!V$64 -> 0 | E10: ='9'!V$65 -> 0
A11: 10 | B11: ='[4]10'!V$60 -> #REF! | C11: ='[4]10'!V$63 -> #REF! | D11: ='[4]10'!V$64 -> #REF! | E11: ='[4]10'!V$65 -> #REF!
A12: 11 | B12: ='11'!V$60 -> 85.271219 | C12: ='11'!V$63 -> 49.303996 | D12: ='11'!V$64 -> 89.39526 | E12: ='11'!V$65 -> 37.583661
A13: 12 | B13: ='[5]12'!V$60 -> #REF! | C13: ='[5]12'!V$63 -> #REF! | D13: ='[5]12'!V$64 -> #REF! | E13: ='[5]12'!V$65 -> #REF!
A14: 13 | B14: ='13'!V$65 -> 97.121267 | C14: ='13'!V$68 -> 68.070479 | D14: ='13'!V$69 -> 93.649866 | E14: ='13'!V$70 -> 61.912779
A15: 14 | B15: ='14'!V$64 -> 93.230373 | C15: ='14'!V$67 -> 69.156083 | D15: ='14'!V$68 -> 90.408435 | E15: ='14'!V$69 -> 58.290364
A16: 15 | B16: ='15'!V$60 -> 95.584213 | C16: ='15'!V$63 -> 72.996729 | D16: ='15'!V$64 -> 90.725664 | E16: ='15'!V$65 -> 63.302334
A17: 16 | B17: ='16'!V$60 -> 0 | C17: ='16'!V$63 -> 0 | D17: ='16'!V$64 -> 0 | E17: ='16'!V$65 -> 0
A18: 17 | B18: ='[6]17'!V$60 -> #REF! | C18: ='[6]17'!V$63 -> #REF! | D18: ='[6]17'!V$64 -> #REF! | E18: ='[6]17'!V$65 -> #REF!
A19: 18 | B19: ='18'!V$60 -> 91.95763 | C19: ='18'!V$63 -> 68.003413 | D19: ='18'!V$64 -> 90.453972 | E19: ='18'!V$65 -> 56.564783
A20: 19 | B20: ='19'!V$60 -> 94.493017 | C20: ='19'!V$63 -> 64.587839 | D20: ='19'!V$64 -> 96.59159 | E20: ='19'!V$65 -> 58.950811
A21: 20 | B21: ='20'!V$65 -> 96.390977 | C21: ='20'!V$68 -> 66.666667 | D21: ='20'!V$69 -> 89.143758 | E21: ='20'!V$70 -> 57.28436
A22: 21 | B22: ='21'!V$62 -> 97.33711 | C22: ='21'!V$65 -> 68.810633 | D22: ='21'!V$66 -> 90.2073 | E22: ='21'!V$67 -> 60.419299
A23: 22 | B23: ='22'!V$61 -> 91.025004 | C23: ='22'!V$64 -> 72.736644 | D23: ='22'!V$65 -> 0 | E23: ='22'!V$66 -> 0
A24: 23 | B24: ='[7]23'!V$60 -> #REF! | C24: ='[7]23'!V$63 -> #REF! | D24: ='[7]23'!V$64 -> #REF! | E24: ='[7]23'!V$65 -> #REF!
A25: 24 | B25: ='[8]24'!V$60 -> #REF! | C25: ='[8]24'!V$63 -> #REF! | D25: ='[8]24'!V$64 -> #REF! | E25: ='[8]24'!V$65 -> #REF!
A26: 25 | B26: ='25'!V$68 -> 0 | C26: ='25'!V$71 -> 0 | D26: ='25'!V$72 -> 0 | E26: ='25'!V$73 -> 0
A27: 26 | B27: ='26'!V$60 -> 0 | C27: ='26'!V$63 -> 0 | D27: ='26'!V$64 -> 0 | E27: ='26'!V$65 -> 0
A28: 27 | B28: ='27'!V$65 -> 0 | C28: ='27'!V$68 -> 0 | D28: ='27'!V$69 -> 0 | E28: ='27'!V$70 -> 0
A29: 28 | B29: ='28'!V$60 -> 0 | C29: ='28'!V$63 -> 0 | D29: ='28'!V$64 -> 0 | E29: ='28'!V$65 -> 0
A30: 29 | B30: ='30'!V$60 -> 0 | C30: ='30'!V$63 -> 0 | D30: ='30'!V$64 -> 0 | E30: ='30'!V$65 -> 0
A31: 30 | B31: ='29'!V$60 -> 0 | C31: ='29'!V$63 -> 0 | D31: ='29'!V$64 -> 0 | E31: ='29'!V$65 -> 0
A32: 31 | B32: ='31'!V$60 -> 0 | C32: ='31'!V$63 -> 0 | D32: ='31'!V$64 -> 0 | E32: ='31'!V$65 -> 0
A33: total | B33: =สรุป!L60 -> 92.815476 | C33: =สรุป!L63 -> 64.128915 | D33: =สรุป!L64 -> 91.424307 | E33: =สรุป!L65 -> 54.417171

Sheet สรุป
A1: รายงานสมรรถภาพการผลิตประจำวัน | E1: โรงงานครอบพิเศษสระบุรี2 | I1: Specail Ridge | M1: สัปดาห์ที่. | O1: 0/68 | T1: วันที่
A3: ครอบสันโค้ง | C3: ความเร็วเครื่องจักร | D3: กะ1+2 | AA3: เวลารวม | AB3: เวลาผลิตรวม | AC3: คัดเปียก | AD3: ผลผลิต | AE3: ก | AF3: ข | AG3: ค | AH3: ง
A4: เครื่อง ผลิต | B4: No. โมล | D4: เวลาทำงาน | G4: Counter | I4: ห้องบ่ม | K4: คัดเปียก | Z4: กะ1 | AA4: =F14 -> 126856 | AB4: =L54 -> 117742 | AC4: =L55 -> 9057.6667 | AD4: =L56 -> 75506.667 | AE4: =L21 -> 4494 | AF4: =L26 -> 33177.667 | AG4: =L28 -> 3652 | AH4: =L43 -> 78
D5: เริ่ม | E5: เลิก | F5: รวม(นาที) | G5: (แผ่น) | I5: (แผ่น) | K5: (แผ่น) | Z5: กะ2 | AA5: =O14 -> 0 | AB5: =U54 -> 0 | AC5: =U55 -> 0 | AD5: =U56 -> 0 | AE5: =U21 -> 0 | AF5: =U26 -> 0 | AG5: =U28 -> 0 | AH5: =U43 -> 0
A6: F7 | C6: 3 | F6: =SUM('31:1'!F6,'31:1'!O6) -> 18041 | G6: =SUM('31:1'!G6:H6,'31:1'!P6:Q6) -> 33155 | I6: =SUM('31:1'!I6:J6,'31:1'!R6:S6) -> 29211 | K6: =G6-I6 -> 3944 | IV6: 0
A7: F8 | C7: 3 | F7: =SUM('31:1'!F7,'31:1'!O7) -> 19666 | G7: =SUM('31:1'!G7:H7,'31:1'!P7:Q7) -> 36910 | I7: =SUM('31:1'!I7:J7,'31:1'!R7:S7) -> 33030 | K7: =G7-I7 -> 3880
A8: F9 | C8: 3 | F8: =SUM('31:1'!F8,'31:1'!O8) -> 18553 | G8: =SUM('31:1'!G8:H8,'31:1'!P8:Q8) -> 32466 | I8: =SUM('31:1'!I8:J8,'31:1'!R8:S8) -> 28597 | K8: =G8-I8 -> 3869
A9: F10 | C9: 3 | F9: =SUM('31:1'!F9,'31:1'!O9) -> 15055 | G9: =SUM('31:1'!G9:H9,'31:1'!P9:Q9) -> 30482 | I9: =SUM('31:1'!I9:J9,'31:1'!R9:S9) -> 27157 | K9: =G9-I9 -> 3325
A10: F11 | C10: 3 | F10: =SUM('31:1'!F10,'31:1'!O10) -> 19680 | G10: =SUM('31:1'!G10:H10,'31:1'!P10:Q10) -> 43750 | I10: =SUM('31:1'!I10:J10,'31:1'!R10:S10) -> 38685 | K10: =G10-I10 -> 5065
A11: F12 | C11: 3 | F11: =SUM('31:1'!F11,'31:1'!O11) -> 17173 | G11: =SUM('31:1'!G11:H11,'31:1'!P11:Q11) -> 33010 | I11: =SUM('31:1'!I11:J11,'31:1'!R11:S11) -> 28705 | K11: =G11-I11 -> 4305
A12: F13 | C12: 3 | F12: =SUM('31:1'!F12,'31:1'!O12) -> 18688 | G12: =SUM('31:1'!G12:H12,'31:1'!P12:Q12) -> 43920 | I12: =SUM('31:1'!I12:J12,'31:1'!R12:S12) -> 41135 | K12: =G12-I12 -> 2785
A13: F14 | C13: 3 | F13: =SUM('31:1'!F13,'31:1'!O13) -> 0 | G13: =SUM('31:1'!G13:H13,'31:1'!P13:Q13) -> 0 | I13: =SUM('31:1'!I13:J13,'31:1'!R13:S13) -> 0 | K13: =G13-I13 -> 0
A14: รวม | C14: =SUM(C6:C13) -> 24 | D14: =AVERAGE(D6:D13) -> #DIV/0! | E14: =AVERAGE(E6:E13) -> #DIV/0! | F14: =SUM(F6:F13) -> 126856 | G14: =SUM(G6:H13) -> 253693 | I14: =SUM(I6:I13) -> 226520 | K14: =SUM(K6:K13) -> 27173
A15: (ก) เวลาหยุดจากแผนผลิต | D15: F#7 | E15: F#8 | F15: F#9 | G15: F#10 | H15: F#11 | I15: F#12 | J15: F#13 | K15: F#14 | L15: รวม | Z15: 2989 | AA15: 2954
A16: ก.1 เตรียมการผลิต | D16: =SUM('31:1'!D16,'31:1'!M16) -> 0 | E16: =SUM('31:1'!E16,'31:1'!N16) -> 0 | F16: =SUM('31:1'!F16,'31:1'!O16) -> 0 | G16: =SUM('31:1'!G16,'31:1'!P16) -> 0 | H16: =SUM('31:1'!H16,'31:1'!Q16) -> 0 | I16: =SUM('31:1'!I16,'31:1'!R16) -> 0 | J16: =SUM('31:1'!J16,'31:1'!S16) -> 0 | K16: =SUM('31:1'!K16,'31:1'!T16) -> 0 | L16: =SUM(D16:K16) -> 0
A17: ก.2 หยุดเปลี่ยนสี | D17: =SUM('31:1'!D17,'31:1'!M17) -> 250 | E17: =SUM('31:1'!E17,'31:1'!N17) -> 250 | F17: =SUM('31:1'!F17,'31:1'!O17) -> 220 | G17: =SUM('31:1'!G17,'31:1'!P17) -> 130 | H17: =SUM('31:1'!H17,'31:1'!Q17) -> 250 | I17: =SUM('31:1'!I17,'31:1'!R17) -> 250 | J17: =SUM('31:1'!J17,'31:1'!S17) -> 250 | K17: =SUM('31:1'!K17,'31:1'!T17) -> 0 | L17: =SUM(D17:K17) -> 1600 | Z17: =Z15-1000 -> 1989 | AA17: =AA15-1000 -> 1954
A18: ก.3 หยุดเปลี่ยนโมล | D18: =SUM('31:1'!D18,'31:1'!M18) -> 0 | E18: =SUM('31:1'!E18,'31:1'!N18) -> 0 | F18: =SUM('31:1'!F18,'31:1'!O18) -> 0 | G18: =SUM('31:1'!G18,'31:1'!P18) -> 60 | H18: =SUM('31:1'!H18,'31:1'!Q18) -> 0 | I18: =SUM('31:1'!I18,'31:1'!R18) -> 0 | J18: =SUM('31:1'!J18,'31:1'!S18) -> 0 | K18: =SUM('31:1'!K18,'31:1'!T18) -> 0 | L18: =SUM(D18:K18) -> 60
A19: ก.4 หยุดเปลี่ยนผ้าตะแกรง | D19: =SUM('31:1'!D19,'31:1'!M19) -> 472 | E19: =SUM('31:1'!E19,'31:1'!N19) -> 412 | F19: =SUM('31:1'!F19,'31:1'!O19) -> 400 | G19: =SUM('31:1'!G19,'31:1'!P19) -> 372 | H19: =SUM('31:1'!H19,'31:1'!Q19) -> 337 | I19: =SUM('31:1'!I19,'31:1'!R19) -> 352 | J19: =SUM('31:1'!J19,'31:1'!S19) -> 489 | K19: =SUM('31:1'!K19,'31:1'!T19) -> 0 | L19: =SUM(D19:K19) -> 2834
A20: ก.5 ทำความสะอาดหลังผลิต | D20: =SUM('31:1'!D20,'31:1'!M20) -> 0 | E20: =SUM('31:1'!E20,'31:1'!N20) -> 0 | F20: =SUM('31:1'!F20,'31:1'!O20) -> 0 | G20: =SUM('31:1'!G20,'31:1'!P20) -> 0 | H20: =SUM('31:1'!H20,'31:1'!Q20) -> 0 | I20: =SUM('31:1'!I20,'31:1'!R20) -> 0 | J20: =SUM('31:1'!J20,'31:1'!S20) -> 0 | K20: =SUM('31:1'!K20,'31:1'!T20) -> 0 | L20: =SUM(D20:K20) -> 0
A21: รวมเวลาหยุด (ก) | D21: =SUM(D16:D20) -> 722 | E21: =SUM(E16:E20) -> 662 | F21: =SUM(F16:F20) -> 620 | G21: =SUM(G16:G20) -> 562 | H21: =SUM(H16:H20) -> 587 | I21: =SUM(I16:I20) -> 602 | J21: =SUM(J16:J20) -> 739 | K21: =SUM(K16:K20) -> 0 | L21: =SUM(D21:K21) -> 4494
A22: (ข) เวลาหยุดระหว่างผลิต | D22: F#7 | E22: F#8 | F22: F#9 | G22: F#10 | H22: F#11 | I22: F#12 | J22: F#13 | K22: F#14 | L22: รวม
A23: ข.1 ปรับตั้งเครื่องจักร | D23: =SUM('31:1'!D23,'31:1'!M23) -> 378 | E23: =SUM('31:1'!E23,'31:1'!N23) -> 71 | F23: =SUM('31:1'!F23,'31:1'!O23) -> 266 | G23: =SUM('31:1'!G23,'31:1'!P23) -> 237 | H23: =SUM('31:1'!H23,'31:1'!Q23) -> 239 | I23: =SUM('31:1'!I23,'31:1'!R23) -> 81 | J23: =SUM('31:1'!J23,'31:1'!S23) -> 30 | K23: =SUM('31:1'!K23,'31:1'!T23) -> 0 | L23: =SUM(D23:K23) -> 1302
A24: ข.2 เครื่องจักรหยุด < 10 นาที | D24: =SUM('31:1'!D24,'31:1'!M24) -> 3657 | E24: =SUM('31:1'!E24,'31:1'!N24) -> 3434 | F24: =SUM('31:1'!F24,'31:1'!O24) -> 3431 | G24: =SUM('31:1'!G24,'31:1'!P24) -> 2490 | H24: =SUM('31:1'!H24,'31:1'!Q24) -> 3053 | I24: =SUM('31:1'!I24,'31:1'!R24) -> 2534 | J24: =SUM('31:1'!J24,'31:1'!S24) -> 3136 | K24: =SUM('31:1'!K24,'31:1'!T24) -> 0 | L24: =SUM(D24:K24) -> 21735
A25: Diff Time | D25: =$F6-D$55-D$56-D$21-D$23-D$24-D$34-D$43 -> 1575.3333 | E25: =$F7-E$55-E$56-E$21-E$23-E$24-E$34-E$43 -> 2418.6667 | F25: =$F8-F$55-F$56-F$21-F$23-F$24-F$34-F$43 -> 2750 | G25: =$F9-G$55-G$56-G$21-G$23-G$24-G$34-G$43 -> 1126.3333 | H25: =$F10-H$55-H$56-H$21-H$23-H$24-H$34-H$43 -> 750.66667 | I25: =$F11-I$55-I$56-I$21-I$23-I$24-I$34-I$43 -> 1720.6667 | J25: =$F12-J$55-J$56-J$21-J$23-J$24-J$34-J$43 -> -201 | K25: =$F13-K$55-K$56-K$21-K$23-K$24-K$34-K$43 -> 0 | L25: =SUM(D25:K25) -> 10140.667
A26: รวมเวลาหยุด (ข) | D26: =SUM(D23:D25) -> 5610.3333 | E26: =SUM(E23:E25) -> 5923.6667 | F26: =SUM(F23:F25) -> 6447 | G26: =SUM(G23:G25) -> 3853.3333 | H26: =SUM(H23:H25) -> 4042.6667 | I26: =SUM(I23:I25) -> 4335.6667 | J26: =SUM(J23:J25) -> 2965 | K26: =SUM(K23:K25) -> 0 | L26: =SUM(D26:K26) -> 33177.667
A27: (ค) เวลาหยุดซ่อมเครื่อง (นาที) | D27: F#7 | E27: F#8 | F27: F#9 | G27: F#10 | H27: F#11 | I27: F#12 | J27: F#13 | K27: F#14 | L27: รวม
A28: ค.1 เครื่องจักรเสียตั้งแต่ 10 นาที ขึ้นไป | D28: =SUM('31:1'!D28,'31:1'!M28) -> 513 | E28: =SUM('31:1'!E28,'31:1'!N28) -> 633 | F28: =SUM('31:1'!F28,'31:1'!O28) -> 533 | G28: =SUM('31:1'!G28,'31:1'!P28) -> 335 | H28: =SUM('31:1'!H28,'31:1'!Q28) -> 323 | I28: =SUM('31:1'!I28,'31:1'!R28) -> 1115 | J28: =SUM('31:1'!J28,'31:1'!S28) -> 200 | K28: =SUM('31:1'!K28,'31:1'!T28) -> 0 | L28: =SUM(D28:K28) -> 3652
A29: ค.2 ผู้รับเหมาทำไม่ทัน | D29: =SUM('31:1'!D29,'31:1'!M29) -> 0 | E29: =SUM('31:1'!E29,'31:1'!N29) -> 0 | F29: =SUM('31:1'!F29,'31:1'!O29) -> 0 | G29: =SUM('31:1'!G29,'31:1'!P29) -> 0 | H29: =SUM('31:1'!H29,'31:1'!Q29) -> 0 | I29: =SUM('31:1'!I29,'31:1'!R29) -> 0 | J29: =SUM('31:1'!J29,'31:1'!S29) -> 0 | K29: =SUM('31:1'!K29,'31:1'!T29) -> 0 | L29: =SUM(D29:K29) -> 0
A30: ค.3 รถ Fork lift เสีย / วิ่งไม่ทัน | D30: =SUM('31:1'!D30,'31:1'!M30) -> 131 | E30: =SUM('31:1'!E30,'31:1'!N30) -> 131 | F30: =SUM('31:1'!F30,'31:1'!O30) -> 131 | G30: =SUM('31:1'!G30,'31:1'!P30) -> 131 | H30: =SUM('31:1'!H30,'31:1'!Q30) -> 131 | I30: =SUM('31:1'!I30,'31:1'!R30) -> 104 | J30: =SUM('31:1'!J30,'31:1'!S30) -> 131 | K30: =SUM('31:1'!K30,'31:1'!T30) -> 0 | L30: =SUM(D30:K30) -> 890
A31: ค.4 วัตถุดิบหมด | D31: =SUM('31:1'!D31,'31:1'!M31) -> 0 | E31: =SUM('31:1'!E31,'31:1'!N31) -> 0 | F31: =SUM('31:1'!F31,'31:1'!O31) -> 0 | G31: =SUM('31:1'!G31,'31:1'!P31) -> 0 | H31: =SUM('31:1'!H31,'31:1'!Q31) -> 0 | I31: =SUM('31:1'!I31,'31:1'!R31) -> 0 | J31: =SUM('31:1'!J31,'31:1'!S31) -> 0 | K31: =SUM('31:1'!K31,'31:1'!T31) -> 0 | L31: =SUM(D31:K31) -> 0
A32: ค.5 รอแบบ | D32: =SUM('31:1'!D32,'31:1'!M32) -> 0 | E32: =SUM('31:1'!E32,'31:1'!N32) -> 0 | F32: =SUM('31:1'!F32,'31:1'!O32) -> 0 | G32: =SUM('31:1'!G32,'31:1'!P32) -> 0 | H32: =SUM('31:1'!H32,'31:1'!Q32) -> 0 | I32: =SUM('31:1'!I32,'31:1'!R32) -> 0 | J32: =SUM('31:1'!J32,'31:1'!S32) -> 0 | K32: =SUM('31:1'!K32,'31:1'!T32) -> 0 | L32: =SUM(D32:K32) -> 0
A33: ค.6 อื่น ๆ | D33: =SUM('31:1'!D33,'31:1'!M33) -> 0 | E33: =SUM('31:1'!E33,'31:1'!N33) -> 0 | F33: =SUM('31:1'!F33,'31:1'!O33) -> 0 | G33: =SUM('31:1'!G33,'31:1'!P33) -> 0 | H33: =SUM('31:1'!H33,'31:1'!Q33) -> 0 | I33: =SUM('31:1'!I33,'31:1'!R33) -> 0 | J33: =SUM('31:1'!J33,'31:1'!S33) -> 0 | K33: =SUM('31:1'!K33,'31:1'!T33) -> 0 | L33: =SUM(D33:K33) -> 0
A34: รวมเวลาหยุด (ค) | D34: =SUM(D28:D33) -> 644 | E34: =SUM(E28:E33) -> 764 | F34: =SUM(F28:F33) -> 664 | G34: =SUM(G28:G33) -> 466 | H34: =SUM(H28:H33) -> 454 | I34: =SUM(I28:I33) -> 1219 | J34: =SUM(J28:J33) -> 331 | K34: =SUM(K28:K33) -> 0 | L34: =SUM(D34:K34) -> 4542
A35: (ง) เวลาหยุดจากปัจจัยภายนอก (นาที) | D35: F#7 | E35: F#8 | F35: F#9 | G35: F#10 | H35: F#11 | I35: F#12 | J35: F#13 | K35: F#14 | L35: รวม
A36: ง.1 ไม่มีแผนผลิต | D36: =SUM('31:1'!D36,'31:1'!M36) -> 0 | E36: =SUM('31:1'!E36,'31:1'!N36) -> 0 | F36: =SUM('31:1'!F36,'31:1'!O36) -> 0 | G36: =SUM('31:1'!G36,'31:1'!P36) -> 0 | H36: =SUM('31:1'!H36,'31:1'!Q36) -> 0 | I36: =SUM('31:1'!I36,'31:1'!R36) -> 0 | J36: =SUM('31:1'!J36,'31:1'!S36) -> 0 | K36: =SUM('31:1'!K36,'31:1'!T36) -> 0 | L36: =SUM(D36:K36) -> 0
