Workbook

Sheet 1
A1: รายงานการผลิตครอบประจำวัน | F1: ครอบ Prestige โรงงานสระบุรี 2/3 | L1: สัปดาห์ที่ | M1: 00/69 | Q1: วันที่ผลิต | R1: 244562 | V1: MATERIAL DOCUMENT NO
E2: จำนวนที่ผลิต | I2: ปริมาณการใช้วัตถุดิบ | P2: เถ้าลอย | R2: ปูนซีเมนต์ | T2: ปูนซีเมนต์ | V2: ทราย | X2: ทราย | Z2: Water Base | AB2: MOULD | AD2: Adva | AF2: สีพื้น | AH2: สีเหลือบ | AJ2: สีเหลือบ
A3: กะที่ | B3: LOT NO. | C3: ลอน | D3: สี | E3: (แผ่น) | R3: ผสมตัว | T3: ผสมสี | V3: ผสมตัว | X3: ผสมสี | Z3: Spray | AB3: OIL | AH3: 1 | AJ3: 2
E4: Plan | F4: Counter | G4: ห้องบ่ม | H4: Wet Reject | P4: (ตัน) | R4: (ตัน) | T4: (ตัน) | V4: (ตัน) | X4: (ตัน) | Z4: (ลิตร) | AB4: (ลิตร) | AD4: (ลิตร) | AF4: (แผ่น/ถัง) | AH4: (แผ่น/ถัง) | AJ4: (แผ่น/ถัง)
B5: I11690801 | C5: ครอบสัน | D5: มิดไนท์เกรย์*N | E5: 2000 | F5: 3648 | G5: 3310 | H5: =IF(F5=0,"",(F5-G5)/F5) -> 0.092653509 | I5: ปริมาณการใช้กะ 1 | P5: 3.445 | R5: 10.399 | T5: 0.923 | V5: 25.395 | X5: 0.554 | Z5: =90+156+80 -> 326 | AB5: =29+16 -> 45 | AD5: =SUM(AF5:AK5)*0.025 -> 1.9 | AF5: =14+14+14+10+14+10 -> 76 | AH5: 0 | AJ5: 0
A6: 1 | C6: ครอบปิดจั่ว | H6: =IF(F6=0,"",(F6-G6)/F6) | I6: คำนวณจาก Counter (ต่อพันแผ่น) | P6: =IF($F$15=0,0,P5*1000/$F$15) -> 0.28855013 | R6: =IF($F$15=0,0,R5*1000/$F$15) -> 0.87101097 | T6: =IF($F$15=0,0,T5*1000/$F$15) -> 0.077309657 | V6: =IF($F$15=0,0,V5*1000/$F$15) -> 2.1270626 | X6: =IF($F$15=0,0,X5*1000/$F$15) -> 0.046402546 | Z6: =IF($F$15=0,0,Z5*1000/$F$15) -> 27.305469 | AB6: =IF($F$15=0,0,AB5*1000/$F$15) -> 3.7691599 | AD6: =IF($F$15=0,0,AD5*1000/$F$15) -> 0.15914231 | AF6: =IF(AF5=0,0,F15/AF5) -> 157.09211 | AH6: =IF(AH5=0,0,F15/AH5) -> 0 | AJ6: =IF(AJ5=0,0,F15/AJ5) -> 0
B7: I13690801 | C7: ครอบตะเข้ | D7: มิดไนท์เกรย์*N | E7: 4000 | F7: 3513 | G7: 3251 | H7: =IF(F7=0,"",(F7-G7)/F7) -> 0.074580131 | I7: คำนวณจาก ห้องบ่ม (ต่อพันแผ่น) | P7: =IF($G$15=0,0,P5*1000/$G$15) -> 0.31730681 | R7: =IF($G$15=0,0,R5*1000/$G$15) -> 0.95781523 | T7: =IF($G$15=0,0,T5*1000/$G$15) -> 0.085014277 | V7: =IF($G$15=0,0,V5*1000/$G$15) -> 2.3390439 | X7: =IF($G$15=0,0,X5*1000/$G$15) -> 0.051026987 | Z7: =IF($G$15=0,0,Z5*1000/$G$15) -> 30.026711 | AB7: =IF($G$15=0,0,AB5*1000/$G$15) -> 4.1447914 | AD7: =IF($G$15=0,0,AD5*1000/$G$15) -> 0.1750023 | AF7: =IF(AF5=0,0,G15/AF5) -> 142.85526 | AH7: =IF(AH5=0,0,G15/AH5) -> 0 | AJ7: =IF(AJ5=0,0,G15/AJ5) -> 0
B8: I14690801 | C8: ครอบปิดปลายตะเข้ | D8: มิดไนท์เกรย์*N | E8: 2000 | F8: 1405 | G8: 1180 | H8: =IF(F8=0,"",(F8-G8)/F8) -> 0.16014235 | I8: ใช้ปูน ( Batch) | P8: =92+4+1+3+1+6+4+8+20+11 -> 150
B9: I15690801 | C9: ครอบข้างซิมเลท | D9: มิดไนท์เกรย์*N | E9: 2000 | F9: 1943 | G9: 1879 | H9: =IF(F9=0,"",(F9-G9)/F9) -> 0.032938755 | I9: ทิ้งปูน (Batct)
B10: I16690801 | C10: ครอบข้างปิดปลายซิมเลท | D10: มิดไนท์เกรย์*N | E10: 2000 | F10: 1430 | G10: 1237 | H10: =IF(F10=0,"",(F10-G10)/F10) -> 0.13496503 | I10: ทิ้งสีพื้น (ถัง)
C11: ครอบหัวผนัง | H11: =IF(F11=0,"",(F11-G11)/F11) | I11: ทิ้งสีเหลือบ (ถัง)
C12: ครอบข้างผนัง | H12: =IF(F12=0,"",(F12-G12)/F12) | I12: ใช้ผ้า (ผืน) | P12: =3+5+3+3+4+3+5+1+4+2+3+3+4+4 -> 47
C13: ครอบปั้นลม | H13: =IF(F13=0,"",(F13-G13)/F13) | I13: ใช้ผ้า (แผ่น/ผืน) | P13: =F15/P12 -> 254.02128
C14: ครอบปิดปลายปั้นลม | H14: =IF(F14=0,"",(F14-G14)/F14) | I14: ใช้ตะแกรง (แผ่น) | P14: 7
A15: รวมกะที่ 1 | E15: =SUM(E5:E14) -> 12000 | F15: =SUM(F5:F14) -> 11939 | G15: =SUM(G5:G14) -> 10857 | H15: =IF(F15=0,"",(F15-G15)/F15) -> 0.090627356 | I15: ใช้ตะแกรง (แผ่น/ผืน) | P15: =F15/P14 -> 1705.5714
C16: ครอบสัน | H16: =IF(F16=0,"",(F16-G16)/F16) | I16: ปริมาณการใช้กะ 2 | P16: 0.239 | R16: 0.72 | T16: 0.073 | V16: 1.863 | X16: 0.042 | Z16: =18+18 -> 36 | AB16: 0 | AD16: =SUM(AF16:AK16)*0.025 -> 0.15 | AF16: =6 -> 6 | AH16: 0 | AJ16: 0
A17: 2 | C17: ครอบปิดจั่ว | H17: =IF(F17=0,"",(F17-G17)/F17) | I17: คำนวณจาก Counter (ต่อพันแผ่น) | P17: =IF($F$26=0,0,P16*1000/$F$26) -> 0.26148796 | R17: =IF($F$26=0,0,R16*1000/$F$26) -> 0.78774617 | T17: =IF($F$26=0,0,T16*1000/$F$26) -> 0.079868709 | V17: =IF($F$26=0,0,V16*1000/$F$26) -> 2.0382932 | X17: =IF($F$26=0,0,X16*1000/$F$26) -> 0.04595186 | Z17: =IF($F$26=0,0,Z16*1000/$F$26) -> 39.387309 | AB17: =IF($F$26=0,0,AB16*1000/$F$26) -> 0 | AD17: =IF($F$26=0,0,AD16*1000/$F$26) -> 0.16411379 | AF17: =IF(AF16=0,0,F26/AF16) -> 152.33333 | AH17: =IF($F$26=0,0,AH16*1000/$F$26) -> 0 | AJ17: =IF($F$26=0,0,AJ16*1000/$F$26) -> 0
B18: I13690802 | C18: ครอบตะเข้ | D18: ออเบิร์น บราวน์*N | E18: 600 | F18: 914 | G18: 824 | H18: =IF(F18=0,"",(F18-G18)/F18) -> 0.098468271 | I18: คำนวณจาก ห้องบ่ม (ต่อพันแผ่น) | P18: =IF($G$26=0,0,P16*1000/$G$26) -> 0.29004854 | R18: =IF($G$26=0,0,R16*1000/$G$26) -> 0.87378641 | T18: =IF($G$26=0,0,T16*1000/$G$26) -> 0.088592233 | V18: =IF($G$26=0,0,V16*1000/$G$26) -> 2.2609223 | X18: =IF($G$26=0,0,X16*1000/$G$26) -> 0.050970874 | Z18: =IF($G$26=0,0,Z16*1000/$G$26) -> 43.68932 | AB18: =IF($G$26=0,0,AB16*1000/$G$26) -> 0 | AD18: =IF($G$26=0,0,AD16*1000/$G$26) -> 0.18203883 | AF18: =IF(AF16=0,0,G26/AF16) -> 137.33333 | AH18: =IF($G$26=0,0,AH16*1000/$G$26) -> 0 | AJ18: =IF($G$26=0,0,AJ16*1000/$G$26) -> 0
C19: ครอบปิดปลายตะเข้ | H19: =IF(F19=0,"",(F19-G19)/F19) | I19: ใช้ปูน ( Batch) | P19: =11 -> 11
C20: ครอบข้างซิมเลท | H20: =IF(F20=0,"",(F20-G20)/F20) | I20: ทิ้งปูน (Batct)
C21: ครอบข้างปิดปลายซิมเลท | H21: =IF(F21=0,"",(F21-G21)/F21) | I21: ทิ้งสีพื้น (ถัง)
C22: ครอบหัวผนัง | H22: =IF(F22=0,"",(F22-G22)/F22) | I22: ทิ้งสีเหลือบ (ถัง)
C23: ครอบข้างผนัง | H23: =IF(F23=0,"",(F23-G23)/F23) | I23: ใช้ผ้า (ผืน) | P23: =2+2 -> 4
C24: ครอบปั้นลม | H24: =IF(F24=0,"",(F24-G24)/F24) | I24: ใช้ผ้า (แผ่น/ผืน) | P24: =F26/P23 -> 228.5
C25: ครอบปิดปลายปั้นลม | H25: =IF(F25=0,"",(F25-G25)/F25) | I25: ใช้ตะแกรง (แผ่น) | P25: 2
A26: รวมกะที่ 2 | E26: =SUM(E16:E25) -> 600 | F26: =SUM(F16:F25) -> 914 | G26: =SUM(G16:G25) -> 824 | H26: =IF(F26=0,"",(F26-G26)/F26) -> 0.098468271 | I26: ใช้ตะแกรง (แผ่น/ผืน) | P26: =F26/P25 -> 457
I27: ปริมาณการใช้รวม | P27: =SUM(P5,P16) -> 3.684 | R27: =SUM(R5,R16) -> 11.119 | T27: =SUM(T5,T16) -> 0.996 | V27: =SUM(V5,V16) -> 27.258 | X27: =SUM(X5,X16) -> 0.596 | Z27: =SUM(Z5,Z16) -> 362 | AB27: =SUM(AB5,AB16) -> 45 | AD27: =SUM(AD5,AD16) -> 2.05 | AF27: =SUM(AF5,AF16) -> 82 | AH27: =SUM(AH5,AH16) -> 0 | AJ27: =SUM(AJ5,AJ16) -> 0
A28: รวมทุกกะ | E28: =E15+E26 -> 12600 | F28: =F15+F26 -> 12853 | G28: =G15+G26 -> 11681 | H28: =IF(F28=0,"",(F28-G28)/F28) -> 0.091184937 | I28: คำนวณจาก Counter (ต่อพันแผ่น) | P28: =IF($F$28=0,0,P27*1000/$F$28) -> 0.28662569 | R28: =IF($F$28=0,0,R27*1000/$F$28) -> 0.86508986 | T28: =IF($F$28=0,0,T27*1000/$F$28) -> 0.077491636 | V28: =IF($F$28=0,0,V27*1000/$F$28) -> 2.12075 | X28: =IF($F$28=0,0,X27*1000/$F$28) -> 0.046370497 | Z28: =IF($F$28=0,0,Z27*1000/$F$28) -> 28.164631 | AB28: =IF($F$28=0,0,AB27*1000/$F$28) -> 3.5011281 | AD28: =IF($F$28=0,0,AD27*1000/$F$28) -> 0.15949584 | AF28: =IF($F$28=0,0,AF27*1000/$F$28) -> 6.3798335 | AH28: =IF($F$28=0,0,AH27*1000/$F$28) -> 0 | AJ28: =IF($F$28=0,0,AJ27*1000/$F$28) -> 0
I29: คำนวณจาก ห้องบ่ม (ต่อพันแผ่น) | P29: =IF($G$28=0,0,P27*1000/$G$28) -> 0.31538396 | R29: =IF($G$28=0,0,R27*1000/$G$28) -> 0.95188768 | T29: =IF($G$28=0,0,T27*1000/$G$28) -> 0.085266672 | V29: =IF($G$28=0,0,V27*1000/$G$28) -> 2.3335331 | X29: =IF($G$28=0,0,X27*1000/$G$28) -> 0.051023029 | Z29: =IF($G$28=0,0,Z27*1000/$G$28) -> 30.990497 | AB29: =IF($G$28=0,0,AB27*1000/$G$28) -> 3.8524099 | AD29: =IF($G$28=0,0,AD27*1000/$G$28) -> 0.17549867 | AF29: =IF($G$28=0,0,AF27*1000/$G$28) -> 7.0199469 | AH29: =IF($G$28=0,0,AH27*1000/$G$28) -> 0 | AJ29: =IF($G$28=0,0,AJ27*1000/$G$28) -> 0
A31: รายงานการแกะครอบ | I31: รายละเอียดครอบเสีย | AI31: แผ่นดีนำไปกองเก็บจำนวนไม้ / แผ่น | AK31: หมายเหตุ
A32: กะที่ | B32: LOT NO. | C32: ลอน | D32: สี | E32: จำนวนที่นำมาแกะ | F32: แผ่นดี | G32: Reject | I32: แผ่นเสีย | J32: ร้าวผิว ตัวกระเบื้อง | K32: ร้าว รางลิ้นหงาย | L32: ร้าว ล่างรางลิ้นคว่ำ | M32: ร้าว ล่างตัวครอบ | N32: ร้าว ชายกระเบื้อง | O32: ร้าว เขื่อนรางลิ้นหงาย | P32: ร้าว เขื่อนรางลิ้นคว่ำ | Q32: บิ่นแหว่ง | R32: ผิวครอบปูดบวม | S32: ผิวครอบไม่เรียบ | T32: ขอบไม่คม / ไม่เรียบ | U32: รูพรุน | V32: แตกรูตะปู | W32: เนื้อแหว่งใต้ครอบ | X32: ปูนติดโมล | Y32: สี Salary ไม่เต็ม | Z32: สีเป็นเม็ด | AA32: สีพอง | AB32: สีด้าน | AC32: สีหยด | AD32: สีปูด | AE32: ครอบบาง/น้ำหนักเบา | AF32: ยกชน Rack | AG32: รถยกชน | AH32: อื่นๆ
B33: =B5 -> I11690801 | C33: ครอบสัน | D33: =D5 -> มิดไนท์เกรย์*N | E33: =G5 -> 3310 | F33: =144*22+33+6 -> 3207 | G33: =IF(E33=0,"",(E33-F33)/E33) -> 0.031117825 | I33: =SUM(J33:AH33) -> 103 | J33: =5+10+30 -> 45 | K33: =12 -> 12 | L33: =20 -> 20 | V33: 26 | AI33: 144*22+ศ.33+QC6 | AK33: จบ Lot. ส่งวันที่ 4/8/69
B34: =B6 -> 0 | C34: ครอบปิดจั่ว | D34: =D6 -> 0 | E34: 0 | G34: =IF(E34=0,"",(E34-F34)/E34) | I34: =SUM(J34:AH34) -> 0
B35: =B7 -> I13690801 | C35: ครอบตะเข้ | D35: =D7 -> มิดไนท์เกรย์*N | E35: =G7 -> 3251 | F35: =210*15+70+6 -> 3226 | G35: =IF(E35=0,"",(E35-F35)/E35) -> 0.0076899416 | I35: =SUM(J35:AH35) -> 25 | J35: =3 -> 3 | L35: =7+7 -> 14 | Q35: 2 | AB35: 5 | AF35: 1 | AI35: 210*15+ศ.70+QC6 | AK35: จบ Lot. ส่งวันที่ 4/8/69
A36: 1 | B36: =B8 -> I14690801 | C36: ครอบปิดปลายตะเข้ | D36: =D8 -> มิดไนท์เกรย์*N | E36: =G8 -> 1180 | F36: =140*7+63+6 -> 1049 | G36: =IF(E36=0,"",(E36-F36)/E36) -> 0.11101695 | I36: =SUM(J36:AH36) -> 131 | K36: 15 | O36: 20 | P36: =7+10 -> 17 | W36: =30+15 -> 45 | AB36: 34 | AI36: 140*7+ศ.63+QC6 | AK36: จบ Lot. ส่งวันที่ 4/8/69
B37: =B9 -> I15690801 | C37: ครอบข้างซิมเลท | D37: =D9 -> มิดไนท์เกรย์*N | E37: =G9 -> 1879 | F37: =280*6+141+6 -> 1827 | G37: =IF(E37=0,"",(E37-F37)/E37) -> 0.027674295 | I37: =SUM(J37:AH37) -> 52 | K37: =20+5 -> 25 | L37: 10 | Q37: 3 | AB37: =5+4 -> 9 | AF37: 5 | AI37: 280*6+ศ.141+QC6 | AK37: จบ Lot. ส่งวันที่ 4/8/69
B38: =B10 -> I16690801 | C38: ครอบข้างปิดปลายซิมเลท | D38: =D10 -> มิดไนท์เกรย์*N | E38: =G10 -> 1237 | F38: =96*11+6 -> 1062 | G38: =IF(E38=0,"",(E38-F38)/E38) -> 0.1414713 | I38: =SUM(J38:AH38) -> 175 | K38: =9+4+20+2 -> 35 | W38: =23+20+20+20+25+25 -> 133 | AF38: 7 | AI38: 96*11+QC6 | AK38: จบ Lot. ส่งวันที่ 6/8/69
B39: =B11 -> 0 | C39: ครอบหัวผนัง | D39: =D11 -> 0 | E39: =G11 -> 0 | G39: =IF(E39=0,"",(E39-F39)/E39) | I39: =SUM(J39:AH39) -> 0
B40: =B12 -> 0 | C40: ครอบข้างผนัง | D40: =D12 -> 0 | E40: =G12 -> 0 | G40: =IF(E40=0,"",(E40-F40)/E40) | I40: =SUM(J40:AH40) -> 0
B41: =B13 -> 0 | C41: ครอบปั้นลม | D41: =D13 -> 0 | E41: =G13 -> 0 | G41: =IF(E41=0,"",(E41-F41)/E41) | I41: =SUM(J41:AH41) -> 0
...

Sheet 2
A1: รายงานการผลิตครอบประจำวัน | F1: ครอบ Prestige โรงงานสระบุรี 2/3 | L1: สัปดาห์ที่ | M1: 00/69 | Q1: วันที่ผลิต | R1: 00/08/2569 | V1: MATERIAL DOCUMENT NO
E2: จำนวนที่ผลิต | I2: ปริมาณการใช้วัตถุดิบ | P2: เถ้าลอย | R2: ปูนซีเมนต์ | T2: ปูนซีเมนต์ | V2: ทราย | X2: ทราย | Z2: Water Base | AB2: MOULD | AD2: Adva | AF2: สีพื้น | AH2: สีเหลือบ | AJ2: สีเหลือบ
A3: กะที่ | B3: LOT NO. | C3: ลอน | D3: สี | E3: (แผ่น) | R3: ผสมตัว | T3: ผสมสี | V3: ผสมตัว | X3: ผสมสี | Z3: Spray | AB3: OIL | AH3: 1 | AJ3: 2
E4: Plan | F4: Counter | G4: ห้องบ่ม | H4: Wet Reject | P4: (ตัน) | R4: (ตัน) | T4: (ตัน) | V4: (ตัน) | X4: (ตัน) | Z4: (ลิตร) | AB4: (ลิตร) | AD4: (ลิตร) | AF4: (แผ่น/ถัง) | AH4: (แผ่น/ถัง) | AJ4: (แผ่น/ถัง)
C5: ครอบสัน | H5: =IF(F5=0,"",(F5-G5)/F5) | I5: ปริมาณการใช้กะ 1 | P5: 0 | R5: 0 | T5: 0 | V5: 0 | X5: 0 | Z5: 0 | AB5: 0 | AD5: =SUM(AF5:AK5)*0.025 -> 0 | AF5: 0 | AH5: 0 | AJ5: 0
A6: 1 | C6: ครอบปิดจั่ว | H6: =IF(F6=0,"",(F6-G6)/F6) | I6: คำนวณจาก Counter (ต่อพันแผ่น) | P6: =IF($F$15=0,0,P5*1000/$F$15) -> 0 | R6: =IF($F$15=0,0,R5*1000/$F$15) -> 0 | T6: =IF($F$15=0,0,T5*1000/$F$15) -> 0 | V6: =IF($F$15=0,0,V5*1000/$F$15) -> 0 | X6: =IF($F$15=0,0,X5*1000/$F$15) -> 0 | Z6: =IF($F$15=0,0,Z5*1000/$F$15) -> 0 | AB6: =IF($F$15=0,0,AB5*1000/$F$15) -> 0 | AD6: =IF($F$15=0,0,AD5*1000/$F$15) -> 0 | AF6: =IF(AF5=0,0,F15/AF5) -> 0 | AH6: =IF(AH5=0,0,F15/AH5) -> 0 | AJ6: =IF(AJ5=0,0,F15/AJ5) -> 0
C7: ครอบตะเข้ | H7: =IF(F7=0,"",(F7-G7)/F7) | I7: คำนวณจาก ห้องบ่ม (ต่อพันแผ่น) | P7: =IF($G$15=0,0,P5*1000/$G$15) -> 0 | R7: =IF($G$15=0,0,R5*1000/$G$15) -> 0 | T7: =IF($G$15=0,0,T5*1000/$G$15) -> 0 | V7: =IF($G$15=0,0,V5*1000/$G$15) -> 0 | X7: =IF($G$15=0,0,X5*1000/$G$15) -> 0 | Z7: =IF($G$15=0,0,Z5*1000/$G$15) -> 0 | AB7: =IF($G$15=0,0,AB5*1000/$G$15) -> 0 | AD7: =IF($G$15=0,0,AD5*1000/$G$15) -> 0 | AF7: =IF(AF5=0,0,G15/AF5) -> 0 | AH7: =IF(AH5=0,0,G15/AH5) -> 0 | AJ7: =IF(AJ5=0,0,G15/AJ5) -> 0
C8: ครอบปิดปลายตะเข้ | H8: =IF(F8=0,"",(F8-G8)/F8) | I8: ใช้ปูน ( Batch)
C9: ครอบข้างซิมเลท | H9: =IF(F9=0,"",(F9-G9)/F9) | I9: ทิ้งปูน (Batct)
C10: ครอบข้างปิดปลายซิมเลท | H10: =IF(F10=0,"",(F10-G10)/F10) | I10: ทิ้งสีพื้น (ถัง)
C11: ครอบหัวผนัง | H11: =IF(F11=0,"",(F11-G11)/F11) | I11: ทิ้งสีเหลือบ (ถัง)
C12: ครอบข้างผนัง | H12: =IF(F12=0,"",(F12-G12)/F12) | I12: ใช้ผ้า (ผืน)
C13: ครอบปั้นลม | H13: =IF(F13=0,"",(F13-G13)/F13) | I13: ใช้ผ้า (แผ่น/ผืน) | P13: =F15/P12 -> #DIV/0!
C14: ครอบปิดปลายปั้นลม | H14: =IF(F14=0,"",(F14-G14)/F14) | I14: ใช้ตะแกรง (แผ่น)
A15: รวมกะที่ 1 | E15: =SUM(E5:E14) -> 0 | F15: =SUM(F5:F14) -> 0 | G15: =SUM(G5:G14) -> 0 | H15: =IF(F15=0,"",(F15-G15)/F15) | I15: ใช้ตะแกรง (แผ่น/ผืน) | P15: =F15/P14 -> #DIV/0!
C16: ครอบสัน | H16: =IF(F16=0,"",(F16-G16)/F16) | I16: ปริมาณการใช้กะ 2 | P16: 0 | R16: 0 | T16: 0 | V16: 0 | X16: 0 | Z16: 0 | AB16: 0 | AD16: =SUM(AF16:AK16)*0.025 -> 0 | AF16: 0 | AH16: 0 | AJ16: 0
A17: 2 | C17: ครอบปิดจั่ว | H17: =IF(F17=0,"",(F17-G17)/F17) | I17: คำนวณจาก Counter (ต่อพันแผ่น) | P17: =IF($F$26=0,0,P16*1000/$F$26) -> 0 | R17: =IF($F$26=0,0,R16*1000/$F$26) -> 0 | T17: =IF($F$26=0,0,T16*1000/$F$26) -> 0 | V17: =IF($F$26=0,0,V16*1000/$F$26) -> 0 | X17: =IF($F$26=0,0,X16*1000/$F$26) -> 0 | Z17: =IF($F$26=0,0,Z16*1000/$F$26) -> 0 | AB17: =IF($F$26=0,0,AB16*1000/$F$26) -> 0 | AD17: =IF($F$26=0,0,AD16*1000/$F$26) -> 0 | AF17: =IF($F$26=0,0,AF16*1000/$F$26) -> 0 | AH17: =IF($F$26=0,0,AH16*1000/$F$26) -> 0 | AJ17: =IF($F$26=0,0,AJ16*1000/$F$26) -> 0
C18: ครอบตะเข้ | H18: =IF(F18=0,"",(F18-G18)/F18) | I18: คำนวณจาก ห้องบ่ม (ต่อพันแผ่น) | P18: =IF($G$26=0,0,P16*1000/$G$26) -> 0 | R18: =IF($G$26=0,0,R16*1000/$G$26) -> 0 | T18: =IF($G$26=0,0,T16*1000/$G$26) -> 0 | V18: =IF($G$26=0,0,V16*1000/$G$26) -> 0 | X18: =IF($G$26=0,0,X16*1000/$G$26) -> 0 | Z18: =IF($G$26=0,0,Z16*1000/$G$26) -> 0 | AB18: =IF($G$26=0,0,AB16*1000/$G$26) -> 0 | AD18: =IF($G$26=0,0,AD16*1000/$G$26) -> 0 | AF18: =IF($G$26=0,0,AF16*1000/$G$26) -> 0 | AH18: =IF($G$26=0,0,AH16*1000/$G$26) -> 0 | AJ18: =IF($G$26=0,0,AJ16*1000/$G$26) -> 0
C19: ครอบปิดปลายตะเข้ | H19: =IF(F19=0,"",(F19-G19)/F19) | I19: ใช้ปูน ( Batch)
C20: ครอบข้างซิมเลท | H20: =IF(F20=0,"",(F20-G20)/F20) | I20: ทิ้งปูน (Batct)
C21: ครอบข้างปิดปลายซิมเลท | H21: =IF(F21=0,"",(F21-G21)/F21) | I21: ทิ้งสีพื้น (ถัง)
C22: ครอบหัวผนัง | H22: =IF(F22=0,"",(F22-G22)/F22) | I22: ทิ้งสีเหลือบ (ถัง)
C23: ครอบข้างผนัง | H23: =IF(F23=0,"",(F23-G23)/F23) | I23: ใช้ผ้า (ผืน)
C24: ครอบปั้นลม | H24: =IF(F24=0,"",(F24-G24)/F24) | I24: ใช้ผ้า (แผ่น/ผืน) | P24: =F26/P23 -> #DIV/0!
C25: ครอบปิดปลายปั้นลม | H25: =IF(F25=0,"",(F25-G25)/F25) | I25: ใช้ตะแกรง (แผ่น)
A26: รวมกะที่ 2 | E26: =SUM(E16:E25) -> 0 | F26: =SUM(F16:F25) -> 0 | G26: =SUM(G16:G25) -> 0 | H26: =IF(F26=0,"",(F26-G26)/F26) | I26: ใช้ตะแกรง (แผ่น/ผืน) | P26: =F26/P25 -> #DIV/0!
I27: ปริมาณการใช้รวม | P27: =SUM(P5,P16) -> 0 | R27: =SUM(R5,R16) -> 0 | T27: =SUM(T5,T16) -> 0 | V27: =SUM(V5,V16) -> 0 | X27: =SUM(X5,X16) -> 0 | Z27: =SUM(Z5,Z16) -> 0 | AB27: =SUM(AB5,AB16) -> 0 | AD27: =SUM(AD5,AD16) -> 0 | AF27: =SUM(AF5,AF16) -> 0 | AH27: =SUM(AH5,AH16) -> 0 | AJ27: =SUM(AJ5,AJ16) -> 0
A28: รวมทุกกะ | E28: =E15+E26 -> 0 | F28: =F15+F26 -> 0 | G28: =G15+G26 -> 0 | H28: =IF(F28=0,"",(F28-G28)/F28) | I28: คำนวณจาก Counter (ต่อพันแผ่น) | P28: =IF($F$28=0,0,P27*1000/$F$28) -> 0 | R28: =IF($F$28=0,0,R27*1000/$F$28) -> 0 | T28: =IF($F$28=0,0,T27*1000/$F$28) -> 0 | V28: =IF($F$28=0,0,V27*1000/$F$28) -> 0 | X28: =IF($F$28=0,0,X27*1000/$F$28) -> 0 | Z28: =IF($F$28=0,0,Z27*1000/$F$28) -> 0 | AB28: =IF($F$28=0,0,AB27*1000/$F$28) -> 0 | AD28: =IF($F$28=0,0,AD27*1000/$F$28) -> 0 | AF28: =IF($F$28=0,0,AF27*1000/$F$28) -> 0 | AH28: =IF($F$28=0,0,AH27*1000/$F$28) -> 0 | AJ28: =IF($F$28=0,0,AJ27*1000/$F$28) -> 0
I29: คำนวณจาก ห้องบ่ม (ต่อพันแผ่น) | P29: =IF($G$28=0,0,P27*1000/$G$28) -> 0 | R29: =IF($G$28=0,0,R27*1000/$G$28) -> 0 | T29: =IF($G$28=0,0,T27*1000/$G$28) -> 0 | V29: =IF($G$28=0,0,V27*1000/$G$28) -> 0 | X29: =IF($G$28=0,0,X27*1000/$G$28) -> 0 | Z29: =IF($G$28=0,0,Z27*1000/$G$28) -> 0 | AB29: =IF($G$28=0,0,AB27*1000/$G$28) -> 0 | AD29: =IF($G$28=0,0,AD27*1000/$G$28) -> 0 | AF29: =IF($G$28=0,0,AF27*1000/$G$28) -> 0 | AH29: =IF($G$28=0,0,AH27*1000/$G$28) -> 0 | AJ29: =IF($G$28=0,0,AJ27*1000/$G$28) -> 0
A31: รายงานการแกะครอบ | I31: รายละเอียดครอบเสีย | AI31: แผ่นดีนำไปกองเก็บจำนวนไม้ / แผ่น | AK31: หมายเหตุ
A32: กะที่ | B32: LOT NO. | C32: ลอน | D32: สี | E32: จำนวนที่นำมาแกะ | F32: แผ่นดี | G32: Reject | I32: แผ่นเสีย | J32: ร้าวผิว ตัวกระเบื้อง | K32: ร้าว รางลิ้นหงาย | L32: ร้าว ล่างรางลิ้นคว่ำ | M32: ร้าว ล่างตัวครอบ | N32: ร้าว ชายกระเบื้อง | O32: ร้าว เขื่อนรางลิ้นหงาย | P32: ร้าว เขื่อนรางลิ้นคว่ำ | Q32: บิ่นแหว่ง | R32: ผิวครอบปูดบวม | S32: ผิวครอบไม่เรียบ | T32: ขอบไม่คม / ไม่เรียบ | U32: รูพรุน | V32: แตกรูตะปู | W32: เนื้อแหว่งใต้ครอบ | X32: ปูนติดโมล | Y32: สี Salary ไม่เต็ม | Z32: สีเป็นเม็ด | AA32: สีพอง | AB32: สีด้าน | AC32: สีหยด | AD32: สีปูด | AE32: ครอบบาง/น้ำหนักเบา | AF32: ยกชน Rack | AG32: รถยกชน | AH32: อื่นๆ
B33: =B5 -> 0 | C33: ครอบสัน | D33: =D5 -> 0 | E33: =G5 -> 0 | G33: =IF(E33=0,"",(E33-F33)/E33) | I33: =SUM(J33:AH33) -> 0
B34: =B6 -> 0 | C34: ครอบปิดจั่ว | D34: =D6 -> 0 | E34: =G6 -> 0 | G34: =IF(E34=0,"",(E34-F34)/E34) | I34: =SUM(J34:AH34) -> 0
B35: =B7 -> 0 | C35: ครอบตะเข้ | D35: =D7 -> 0 | E35: 0 | G35: =IF(E35=0,"",(E35-F35)/E35) | I35: =SUM(J35:AH35) -> 0
A36: 1 | B36: =B8 -> 0 | C36: ครอบปิดปลายตะเข้ | D36: =D8 -> 0 | E36: =G8 -> 0 | G36: =IF(E36=0,"",(E36-F36)/E36) | I36: =SUM(J36:AH36) -> 0
B37: =B9 -> 0 | C37: ครอบข้างซิมเลท | D37: =D9 -> 0 | E37: =G9 -> 0 | G37: =IF(E37=0,"",(E37-F37)/E37) | I37: =SUM(J37:AH37) -> 0
B38: =B10 -> 0 | C38: ครอบข้างปิดปลายซิมเลท | D38: =D10 -> 0 | E38: =G10 -> 0 | G38: =IF(E38=0,"",(E38-F38)/E38) | I38: =SUM(J38:AH38) -> 0
B39: =B11 -> 0 | C39: ครอบหัวผนัง | D39: =D11 -> 0 | E39: =G11 -> 0 | G39: =IF(E39=0,"",(E39-F39)/E39) | I39: =SUM(J39:AH39) -> 0
B40: =B12 -> 0 | C40: ครอบข้างผนัง | D40: =D12 -> 0 | E40: =G12 -> 0 | G40: =IF(E40=0,"",(E40-F40)/E40) | I40: =SUM(J40:AH40) -> 0
B41: =B13 -> 0 | C41: ครอบปั้นลม | D41: =D13 -> 0 | E41: =G13 -> 0 | G41: =IF(E41=0,"",(E41-F41)/E41) | I41: =SUM(J41:AH41) -> 0
...

Sheet 3
A1: รายงานการผลิตครอบประจำวัน | F1: ครอบ Prestige โรงงานสระบุรี 2/3 | L1: สัปดาห์ที่ | M1: 00/69 | Q1: วันที่ผลิต | R1: 244564 | V1: MATERIAL DOCUMENT NO
E2: จำนวนที่ผลิต | I2: ปริมาณการใช้วัตถุดิบ | P2: เถ้าลอย | R2: ปูนซีเมนต์ | T2: ปูนซีเมนต์ | V2: ทราย | X2: ทราย | Z2: Water Base | AB2: MOULD | AD2: Adva | AF2: สีพื้น | AH2: สีเหลือบ | AJ2: สีเหลือบ
A3: กะที่ | B3: LOT NO. | C3: ลอน | D3: สี | E3: (แผ่น) | R3: ผสมตัว | T3: ผสมสี | V3: ผสมตัว | X3: ผสมสี | Z3: Spray | AB3: OIL | AH3: 1 | AJ3: 2
E4: Plan | F4: Counter | G4: ห้องบ่ม | H4: Wet Reject | P4: (ตัน) | R4: (ตัน) | T4: (ตัน) | V4: (ตัน) | X4: (ตัน) | Z4: (ลิตร) | AB4: (ลิตร) | AD4: (ลิตร) | AF4: (แผ่น/ถัง) | AH4: (แผ่น/ถัง) | AJ4: (แผ่น/ถัง)
B5: I11690803 | C5: ครอบสัน | D5: มิดไนท์เกรย์*N | E5: 2000 | F5: 5217 | G5: 4676 | H5: =IF(F5=0,"",(F5-G5)/F5) -> 0.10369944 | I5: ปริมาณการใช้กะ 1 | P5: 4.868 | R5: 14.641 | T5: 1.47 | V5: 37.565 | X5: 0.855 | Z5: =120+200+200+28 -> 548 | AB5: =30+34 -> 64 | AD5: =SUM(AF5:AK5)*0.025 -> 3 | AF5: =14+14+14+14+8+14+14+14+14 -> 120 | AH5: 0 | AJ5: 0
A6: 1 | B6: I12690803 | C6: ครอบปิดจั่ว | D6: มิดไนท์เกรย์*N | E6: 0 | F6: 99 | G6: 99 | H6: =IF(F6=0,"",(F6-G6)/F6) -> 0 | I6: คำนวณจาก Counter (ต่อพันแผ่น) | P6: =IF($F$15=0,0,P5*1000/$F$15) -> 0.25587385 | R6: =IF($F$15=0,0,R5*1000/$F$15) -> 0.76956636 | T6: =IF($F$15=0,0,T5*1000/$F$15) -> 0.077266754 | V6: =IF($F$15=0,0,V5*1000/$F$15) -> 1.9745072 | X6: =IF($F$15=0,0,X5*1000/$F$15) -> 0.044940867 | Z6: =IF($F$15=0,0,Z5*1000/$F$15) -> 28.804205 | AB6: =IF($F$15=0,0,AB5*1000/$F$15) -> 3.3639947 | AD6: =IF($F$15=0,0,AD5*1000/$F$15) -> 0.15768725 | AF6: =IF(AF5=0,0,F15/AF5) -> 158.54167 | AH6: =IF(AH5=0,0,F15/AH5) -> 0 | AJ6: =IF(AJ5=0,0,F15/AJ5) -> 0
B7: I13690803 | C7: ครอบตะเข้ | D7: มิดไนท์เกรย์*N | E7: 6000 | F7: 8222 | G7: 7613 | H7: =IF(F7=0,"",(F7-G7)/F7) -> 0.074069569 | I7: คำนวณจาก ห้องบ่ม (ต่อพันแผ่น) | P7: =IF($G$15=0,0,P5*1000/$G$15) -> 0.27813964 | R7: =IF($G$15=0,0,R5*1000/$G$15) -> 0.83653297 | T7: =IF($G$15=0,0,T5*1000/$G$15) -> 0.083990401 | V7: =IF($G$15=0,0,V5*1000/$G$15) -> 2.1463261 | X7: =IF($G$15=0,0,X5*1000/$G$15) -> 0.04885156 | Z7: =IF($G$15=0,0,Z5*1000/$G$15) -> 31.310707 | AB7: =IF($G$15=0,0,AB5*1000/$G$15) -> 3.6567249 | AD7: =IF($G$15=0,0,AD5*1000/$G$15) -> 0.17140898 | AF7: =IF(AF5=0,0,G15/AF5) -> 145.85 | AH7: =IF(AH5=0,0,G15/AH5) -> 0 | AJ7: =IF(AJ5=0,0,G15/AJ5) -> 0
B8: I14690803 | C8: ครอบปิดปลายตะเข้ | D8: มิดไนท์เกรย์*N | E8: 2000 | F8: 2586 | G8: 2360 | H8: =IF(F8=0,"",(F8-G8)/F8) -> 0.087393658 | I8: ใช้ปูน ( Batch) | P8: =92+46+45+16+9+5+5 -> 218
B9: I15690803 | C9: ครอบข้างซิมเลท | D9: มิดไนท์เกรย์*N | E9: 2000 | F9: 2901 | G9: 2754 | H9: =IF(F9=0,"",(F9-G9)/F9) -> 0.050672182 | I9: ทิ้งปูน (Batct)
C10: ครอบข้างปิดปลายซิมเลท | H10: =IF(F10=0,"",(F10-G10)/F10) | I10: ทิ้งสีพื้น (ถัง)
C11: ครอบหัวผนัง | H11: =IF(F11=0,"",(F11-G11)/F11) | I11: ทิ้งสีเหลือบ (ถัง)
C12: ครอบข้างผนัง | H12: =IF(F12=0,"",(F12-G12)/F12) | I12: ใช้ผ้า (ผืน) | P12: =5+5+3+5+4+5+7+6+3+6+4+5+7+6 -> 71
C13: ครอบปั้นลม | H13: =IF(F13=0,"",(F13-G13)/F13) | I13: ใช้ผ้า (แผ่น/ผืน) | P13: =F15/P12 -> 267.95775
C14: ครอบปิดปลายปั้นลม | H14: =IF(F14=0,"",(F14-G14)/F14) | I14: ใช้ตะแกรง (แผ่น) | P14: 7
A15: รวมกะที่ 1 | E15: =SUM(E5:E14) -> 12000 | F15: =SUM(F5:F14) -> 19025 | G15: =SUM(G5:G14) -> 17502 | H15: =IF(F15=0,"",(F15-G15)/F15) -> 0.080052562 | I15: ใช้ตะแกรง (แผ่น/ผืน) | P15: =F15/P14 -> 2717.8571
C16: ครอบสัน | H16: =IF(F16=0,"",(F16-G16)/F16) | I16: ปริมาณการใช้กะ 2 | P16: 0 | R16: 0 | T16: 0 | V16: 0 | X16: 0 | Z16: 0 | AB16: 0 | AD16: =SUM(AF16:AK16)*0.025 -> 0 | AF16: 0 | AH16: 0 | AJ16: 0
A17: 2 | C17: ครอบปิดจั่ว | H17: =IF(F17=0,"",(F17-G17)/F17) | I17: คำนวณจาก Counter (ต่อพันแผ่น) | P17: =IF($F$26=0,0,P16*1000/$F$26) -> 0 | R17: =IF($F$26=0,0,R16*1000/$F$26) -> 0 | T17: =IF($F$26=0,0,T16*1000/$F$26) -> 0 | V17: =IF($F$26=0,0,V16*1000/$F$26) -> 0 | X17: =IF($F$26=0,0,X16*1000/$F$26) -> 0 | Z17: =IF($F$26=0,0,Z16*1000/$F$26) -> 0 | AB17: =IF($F$26=0,0,AB16*1000/$F$26) -> 0 | AD17: =IF($F$26=0,0,AD16*1000/$F$26) -> 0 | AF17: =IF(AF16=0,0,F26/AF16) -> 0 | AH17: =IF($F$26=0,0,AH16*1000/$F$26) -> 0 | AJ17: =IF($F$26=0,0,AJ16*1000/$F$26) -> 0
C18: ครอบตะเข้ | H18: =IF(F18=0,"",(F18-G18)/F18) | I18: คำนวณจาก ห้องบ่ม (ต่อพันแผ่น) | P18: =IF($G$26=0,0,P16*1000/$G$26) -> 0 | R18: =IF($G$26=0,0,R16*1000/$G$26) -> 0 | T18: =IF($G$26=0,0,T16*1000/$G$26) -> 0 | V18: =IF($G$26=0,0,V16*1000/$G$26) -> 0 | X18: =IF($G$26=0,0,X16*1000/$G$26) -> 0 | Z18: =IF($G$26=0,0,Z16*1000/$G$26) -> 0 | AB18: =IF($G$26=0,0,AB16*1000/$G$26) -> 0 | AD18: =IF($G$26=0,0,AD16*1000/$G$26) -> 0 | AF18: =IF(AF16=0,0,G26/AF16) -> 0 | AH18: =IF($G$26=0,0,AH16*1000/$G$26) -> 0 | AJ18: =IF($G$26=0,0,AJ16*1000/$G$26) -> 0
C19: ครอบปิดปลายตะเข้ | H19: =IF(F19=0,"",(F19-G19)/F19) | I19: ใช้ปูน ( Batch)
C20: ครอบข้างซิมเลท | H20: =IF(F20=0,"",(F20-G20)/F20) | I20: ทิ้งปูน (Batct)
C21: ครอบข้างปิดปลายซิมเลท | H21: =IF(F21=0,"",(F21-G21)/F21) | I21: ทิ้งสีพื้น (ถัง)
C22: ครอบหัวผนัง | H22: =IF(F22=0,"",(F22-G22)/F22) | I22: ทิ้งสีเหลือบ (ถัง)
C23: ครอบข้างผนัง | H23: =IF(F23=0,"",(F23-G23)/F23) | I23: ใช้ผ้า (ผืน)
C24: ครอบปั้นลม | H24: =IF(F24=0,"",(F24-G24)/F24) | I24: ใช้ผ้า (แผ่น/ผืน) | P24: =F26/P23 -> #DIV/0!
C25: ครอบปิดปลายปั้นลม | H25: =IF(F25=0,"",(F25-G25)/F25) | I25: ใช้ตะแกรง (แผ่น)
A26: รวมกะที่ 2 | E26: =SUM(E16:E25) -> 0 | F26: =SUM(F16:F25) -> 0 | G26: =SUM(G16:G25) -> 0 | H26: =IF(F26=0,"",(F26-G26)/F26) | I26: ใช้ตะแกรง (แผ่น/ผืน) | P26: =F26/P25 -> #DIV/0!
I27: ปริมาณการใช้รวม | P27: =SUM(P5,P16) -> 4.868 | R27: =SUM(R5,R16) -> 14.641 | T27: =SUM(T5,T16) -> 1.47 | V27: =SUM(V5,V16) -> 37.565 | X27: =SUM(X5,X16) -> 0.855 | Z27: =SUM(Z5,Z16) -> 548 | AB27: =SUM(AB5,AB16) -> 64 | AD27: =SUM(AD5,AD16) -> 3 | AF27: =SUM(AF5,AF16) -> 120 | AH27: =SUM(AH5,AH16) -> 0 | AJ27: =SUM(AJ5,AJ16) -> 0
A28: รวมทุกกะ | E28: =E15+E26 -> 12000 | F28: =F15+F26 -> 19025 | G28: =G15+G26 -> 17502 | H28: =IF(F28=0,"",(F28-G28)/F28) -> 0.080052562 | I28: คำนวณจาก Counter (ต่อพันแผ่น) | P28: =IF($F$28=0,0,P27*1000/$F$28) -> 0.25587385 | R28: =IF($F$28=0,0,R27*1000/$F$28) -> 0.76956636 | T28: =IF($F$28=0,0,T27*1000/$F$28) -> 0.077266754 | V28: =IF($F$28=0,0,V27*1000/$F$28) -> 1.9745072 | X28: =IF($F$28=0,0,X27*1000/$F$28) -> 0.044940867 | Z28: =IF($F$28=0,0,Z27*1000/$F$28) -> 28.804205 | AB28: =IF($F$28=0,0,AB27*1000/$F$28) -> 3.3639947 | AD28: =IF($F$28=0,0,AD27*1000/$F$28) -> 0.15768725 | AF28: =IF($F$28=0,0,AF27*1000/$F$28) -> 6.3074901 | AH28: =IF($F$28=0,0,AH27*1000/$F$28) -> 0 | AJ28: =IF($F$28=0,0,AJ27*1000/$F$28) -> 0
I29: คำนวณจาก ห้องบ่ม (ต่อพันแผ่น) | P29: =IF($G$28=0,0,P27*1000/$G$28) -> 0.27813964 | R29: =IF($G$28=0,0,R27*1000/$G$28) -> 0.83653297 | T29: =IF($G$28=0,0,T27*1000/$G$28) -> 0.083990401 | V29: =IF($G$28=0,0,V27*1000/$G$28) -> 2.1463261 | X29: =IF($G$28=0,0,X27*1000/$G$28) -> 0.04885156 | Z29: =IF($G$28=0,0,Z27*1000/$G$28) -> 31.310707 | AB29: =IF($G$28=0,0,AB27*1000/$G$28) -> 3.6567249 | AD29: =IF($G$28=0,0,AD27*1000/$G$28) -> 0.17140898 | AF29: =IF($G$28=0,0,AF27*1000/$G$28) -> 6.8563593 | AH29: =IF($G$28=0,0,AH27*1000/$G$28) -> 0 | AJ29: =IF($G$28=0,0,AJ27*1000/$G$28) -> 0
A31: รายงานการแกะครอบ | I31: รายละเอียดครอบเสีย | AI31: แผ่นดีนำไปกองเก็บจำนวนไม้ / แผ่น | AK31: หมายเหตุ
A32: กะที่ | B32: LOT NO. | C32: ลอน | D32: สี | E32: จำนวนที่นำมาแกะ | F32: แผ่นดี | G32: Reject | I32: แผ่นเสีย | J32: ร้าวผิว ตัวกระเบื้อง | K32: ร้าว รางลิ้นหงาย | L32: ร้าว ล่างรางลิ้นคว่ำ | M32: ร้าว ล่างตัวครอบ | N32: ร้าว ชายกระเบื้อง | O32: ร้าว เขื่อนรางลิ้นหงาย | P32: ร้าว เขื่อนรางลิ้นคว่ำ | Q32: บิ่นแหว่ง | R32: ผิวครอบปูดบวม | S32: ผิวครอบไม่เรียบ | T32: ขอบไม่คม / ไม่เรียบ | U32: รูพรุน | V32: แตกรูตะปู | W32: เนื้อแหว่งใต้ครอบ | X32: ปูนติดโมล | Y32: สี Salary ไม่เต็ม | Z32: สีเป็นเม็ด | AA32: สีพอง | AB32: สีด้าน | AC32: สีหยด | AD32: สีปูด | AE32: ครอบบาง/น้ำหนักเบา | AF32: ยกชน Rack | AG32: รถยกชน | AH32: อื่นๆ
B33: =B5 -> I11690803 | C33: ครอบสัน | D33: =D5 -> มิดไนท์เกรย์*N | E33: =G5 -> 4676 | F33: =144*30+105+6 -> 4431 | G33: =IF(E33=0,"",(E33-F33)/E33) -> 0.05239521 | I33: =SUM(J33:AH33) -> 245 | J33: =1 -> 1 | K33: =5+26 -> 31 | L33: =40+75+8 -> 123 | R33: 1 | V33: =11 -> 11 | W33: =45 -> 45 | Y33: =5 -> 5 | AC33: =5+3 -> 8 | AD33: =8 -> 8 | AF33: =2+10 -> 12 | AI33: 144*30+ศ.105+QC6 | AK33: จบ Lot. ส่งวันที่ 5/8/69
B34: =B6 -> I12690803 | C34: ครอบปิดจั่ว | D34: =D6 -> มิดไนท์เกรย์*N | E34: =G6 -> 99 | F34: =40*2+19 -> 99 | G34: =IF(E34=0,"",(E34-F34)/E34) -> 0 | I34: =SUM(J34:AH34) -> 0 | AI34: 40*2+ศ.19 | AK34: จบ Lot. ส่งวันที่ 8/8/69
B35: =B7 -> I13690803 | C35: ครอบตะเข้ | D35: =D7 -> มิดไนท์เกรย์*N | E35: =G7 -> 7613 | F35: =210*35+14+6 -> 7370 | G35: =IF(E35=0,"",(E35-F35)/E35) -> 0.031919086 | I35: =SUM(J35:AH35) -> 243 | J35: 7 | K35: =2+2+5+2+15+3+3+10+11 -> 53 | L35: =2+3+20+5 -> 30 | V35: =20+10+15 -> 45 | W35: =5+10+2 -> 17 | AB35: =243-152 -> 91 | AI35: 210*35+ศ.14+QC6 | AK35: จบ Lot. ส่งวันที่ 6/8/69
A36: 1 | B36: =B8 -> I14690803 | C36: ครอบปิดปลายตะเข้ | D36: =D8 -> มิดไนท์เกรย์*N | E36: =G8 -> 2360 | F36: =140*14+120+6 -> 2086 | G36: =IF(E36=0,"",(E36-F36)/E36) -> 0.11610169 | I36: =SUM(J36:AH36) -> 274 | K36: =32+50+55 -> 137 | L36: =40 -> 40 | Q36: =15 -> 15 | V36: =17 -> 17 | W36: =5+40+15 -> 60 | AC36: =5 -> 5 | AI36: 140*14+ศ.120+QC6 | AK36: จบ Lot. ส่งวันที่ 5/8/69
B37: =B9 -> I15690803 | C37: ครอบข้างซิมเลท | D37: =D9 -> มิดไนท์เกรย์*N | E37: =G9 -> 2754 | F37: =280*9+180+6 -> 2706 | G37: =IF(E37=0,"",(E37-F37)/E37) -> 0.017429194 | I37: =SUM(J37:AH37) -> 48 | K37: 22 | L37: 9 | R37: 2 | W37: 1 | AC37: 4 | AF37: 10 | AI37: 280*9+ศ.180+QC6 | AK37: จบ Lot. ส่งวันที่ 5/8/69
B38: =B10 -> 0 | C38: ครอบข้างปิดปลายซิมเลท | D38: =D10 -> 0 | E38: =G10 -> 0 | G38: =IF(E38=0,"",(E38-F38)/E38) | I38: =SUM(J38:AH38) -> 0
B39: =B11 -> 0 | C39: ครอบหัวผนัง | D39: =D11 -> 0 | E39: =G11 -> 0 | G39: =IF(E39=0,"",(E39-F39)/E39) | I39: =SUM(J39:AH39) -> 0
B40: =B12 -> 0 | C40: ครอบข้างผนัง | D40: =D12 -> 0 | E40: =G12 -> 0 | G40: =IF(E40=0,"",(E40-F40)/E40) | I40: =SUM(J40:AH40) -> 0
B41: =B13 -> 0 | C41: ครอบปั้นลม | D41: =D13 -> 0 | E41: =G13 -> 0 | G41: =IF(E41=0,"",(E41-F41)/E41) | I41: =SUM(J41:AH41) -> 0
...

Sheet 4
A1: รายงานการผลิตครอบประจำวัน | F1: ครอบ Prestige โรงงานสระบุรี 2/3 | L1: สัปดาห์ที่ | M1: 00/69 | Q1: วันที่ผลิต | R1: 00/08/2569 | V1: MATERIAL DOCUMENT NO
E2: จำนวนที่ผลิต | I2: ปริมาณการใช้วัตถุดิบ | P2: เถ้าลอย | R2: ปูนซีเมนต์ | T2: ปูนซีเมนต์ | V2: ทราย | X2: ทราย | Z2: Water Base | AB2: MOULD | AD2: Adva | AF2: สีพื้น | AH2: สีเหลือบ | AJ2: สีเหลือบ
A3: กะที่ | B3: LOT NO. | C3: ลอน | D3: สี | E3: (แผ่น) | R3: ผสมตัว | T3: ผสมสี | V3: ผสมตัว | X3: ผสมสี | Z3: Spray | AB3: OIL | AH3: 1 | AJ3: 2
E4: Plan | F4: Counter | G4: ห้องบ่ม | H4: Wet Reject | P4: (ตัน) | R4: (ตัน) | T4: (ตัน) | V4: (ตัน) | X4: (ตัน) | Z4: (ลิตร) | AB4: (ลิตร) | AD4: (ลิตร) | AF4: (แผ่น/ถัง) | AH4: (แผ่น/ถัง) | AJ4: (แผ่น/ถัง)
B5: I11690804 | C5: ครอบสัน | D5: มิดไนท์เกรย์*N | E5: 2000 | F5: 3765 | G5: 3210 | H5: =IF(F5=0,"",(F5-G5)/F5) -> 0.14741036 | I5: ปริมาณการใช้กะ 1 | P5: 3.742 | R5: 11.24 | T5: 1.257 | V5: 35.245 | X5: 0.682 | Z5: =172+200+97 -> 469 | AB5: =36+29 -> 65 | AD5: =SUM(AF5:AK5)*0.025 -> 2.5 | AF5: =14+14+12+14+14+14+14+4 -> 100 | AH5: 0 | AJ5: 0
A6: 1 | B6: I12690804 | C6: ครอบปิดจั่ว | D6: มิดไนท์เกรย์*N | E6: 0 | F6: 104 | G6: 104 | H6: =IF(F6=0,"",(F6-G6)/F6) -> 0 | I6: คำนวณจาก Counter (ต่อพันแผ่น) | P6: =IF($F$15=0,0,P5*1000/$F$15) -> 0.24265612 | R6: =IF($F$15=0,0,R5*1000/$F$15) -> 0.72887621 | T6: =IF($F$15=0,0,T5*1000/$F$15) -> 0.081512224 | V6: =IF($F$15=0,0,V5*1000/$F$15) -> 2.2855197 | X6: =IF($F$15=0,0,X5*1000/$F$15) -> 0.044225407 | Z6: =IF($F$15=0,0,Z5*1000/$F$15) -> 30.413073 | AB6: =IF($F$15=0,0,AB5*1000/$F$15) -> 4.2150315 | AD6: =IF($F$15=0,0,AD5*1000/$F$15) -> 0.16211659 | AF6: =IF(AF5=0,0,F15/AF5) -> 154.21 | AH6: =IF(AH5=0,0,F15/AH5) -> 0 | AJ6: =IF(AJ5=0,0,F15/AJ5) -> 0
B7: I13690804 | C7: ครอบตะเข้ | D7: มิดไนท์เกรย์*N | E7: 5500 | F7: 6790 | G7: 6140 | H7: =IF(F7=0,"",(F7-G7)/F7) -> 0.095729013 | I7: คำนวณจาก ห้องบ่ม (ต่อพันแผ่น) | P7: =IF($G$15=0,0,P5*1000/$G$15) -> 0.27718519 | R7: =IF($G$15=0,0,R5*1000/$G$15) -> 0.83259259 | T7: =IF($G$15=0,0,T5*1000/$G$15) -> 0.093111111 | V7: =IF($G$15=0,0,V5*1000/$G$15) -> 2.6107407 | X7: =IF($G$15=0,0,X5*1000/$G$15) -> 0.050518519 | Z7: =IF($G$15=0,0,Z5*1000/$G$15) -> 34.740741 | AB7: =IF($G$15=0,0,AB5*1000/$G$15) -> 4.8148148 | AD7: =IF($G$15=0,0,AD5*1000/$G$15) -> 0.18518519 | AF7: =IF(AF5=0,0,G15/AF5) -> 135 | AH7: =IF(AH5=0,0,G15/AH5) -> 0 | AJ7: =IF(AJ5=0,0,G15/AJ5) -> 0
B8: I14690804 | C8: ครอบปิดปลายตะเข้ | D8: มิดไนท์เกรย์*N | E8: 1800 | F8: 2105 | G8: 1605 | H8: =IF(F8=0,"",(F8-G8)/F8) -> 0.23752969 | I8: ใช้ปูน ( Batch) | P8: 171
B9: I15690804 | C9: ครอบข้างซิมเลท | D9: มิดไนท์เกรย์*N | E9: 1800 | F9: 2657 | G9: 2441 | H9: =IF(F9=0,"",(F9-G9)/F9) -> 0.081294693 | I9: ทิ้งปูน (Batct)
C10: ครอบข้างปิดปลายซิมเลท | H10: =IF(F10=0,"",(F10-G10)/F10) | I10: ทิ้งสีพื้น (ถัง)
C11: ครอบหัวผนัง | H11: =IF(F11=0,"",(F11-G11)/F11) | I11: ทิ้งสีเหลือบ (ถัง)
C12: ครอบข้างผนัง | H12: =IF(F12=0,"",(F12-G12)/F12) | I12: ใช้ผ้า (ผืน) | P12: =5+3+4+3+5+3+7+3+6+3+2+5+8+4 -> 61
C13: ครอบปั้นลม | H13: =IF(F13=0,"",(F13-G13)/F13) | I13: ใช้ผ้า (แผ่น/ผืน) | P13: =F15/P12 -> 252.80328
C14: ครอบปิดปลายปั้นลม | H14: =IF(F14=0,"",(F14-G14)/F14) | I14: ใช้ตะแกรง (แผ่น) | P14: 7
A15: รวมกะที่ 1 | E15: =SUM(E5:E14) -> 11100 | F15: =SUM(F5:F14) -> 15421 | G15: =SUM(G5:G14) -> 13500 | H15: =IF(F15=0,"",(F15-G15)/F15) -> 0.12457039 | I15: ใช้ตะแกรง (แผ่น/ผืน) | P15: =F15/P14 -> 2203
C16: ครอบสัน | H16: =IF(F16=0,"",(F16-G16)/F16) | I16: ปริมาณการใช้กะ 2 | P16: 0 | R16: 0 | T16: 0 | V16: 0 | X16: 0 | Z16: 0 | AB16: 0 | AD16: =SUM(AF16:AK16)*0.025 -> 0 | AF16: 0 | AH16: 0 | AJ16: 0
A17: 2 | C17: ครอบปิดจั่ว | H17: =IF(F17=0,"",(F17-G17)/F17) | I17: คำนวณจาก Counter (ต่อพันแผ่น) | P17: =IF($F$26=0,0,P16*1000/$F$26) -> 0 | R17: =IF($F$26=0,0,R16*1000/$F$26) -> 0 | T17: =IF($F$26=0,0,T16*1000/$F$26) -> 0 | V17: =IF($F$26=0,0,V16*1000/$F$26) -> 0 | X17: =IF($F$26=0,0,X16*1000/$F$26) -> 0 | Z17: =IF($F$26=0,0,Z16*1000/$F$26) -> 0 | AB17: =IF($F$26=0,0,AB16*1000/$F$26) -> 0 | AD17: =IF($F$26=0,0,AD16*1000/$F$26) -> 0 | AF17: =IF(AF16=0,0,F26/AF16) -> 0 | AH17: =IF($F$26=0,0,AH16*1000/$F$26) -> 0 | AJ17: =IF($F$26=0,0,AJ16*1000/$F$26) -> 0
C18: ครอบตะเข้ | H18: =IF(F18=0,"",(F18-G18)/F18) | I18: คำนวณจาก ห้องบ่ม (ต่อพันแผ่น) | P18: =IF($G$26=0,0,P16*1000/$G$26) -> 0 | R18: =IF($G$26=0,0,R16*1000/$G$26) -> 0 | T18: =IF($G$26=0,0,T16*1000/$G$26) -> 0 | V18: =IF($G$26=0,0,V16*1000/$G$26) -> 0 | X18: =IF($G$26=0,0,X16*1000/$G$26) -> 0 | Z18: =IF($G$26=0,0,Z16*1000/$G$26) -> 0 | AB18: =IF($G$26=0,0,AB16*1000/$G$26) -> 0 | AD18: =IF($G$26=0,0,AD16*1000/$G$26) -> 0 | AF18: =IF(AF16=0,0,G26/AF16) -> 0 | AH18: =IF($G$26=0,0,AH16*1000/$G$26) -> 0 | AJ18: =IF($G$26=0,0,AJ16*1000/$G$26) -> 0
C19: ครอบปิดปลายตะเข้ | H19: =IF(F19=0,"",(F19-G19)/F19) | I19: ใช้ปูน ( Batch)
C20: ครอบข้างซิมเลท | H20: =IF(F20=0,"",(F20-G20)/F20) | I20: ทิ้งปูน (Batct)
C21: ครอบข้างปิดปลายซิมเลท | H21: =IF(F21=0,"",(F21-G21)/F21) | I21: ทิ้งสีพื้น (ถัง)
C22: ครอบหัวผนัง | H22: =IF(F22=0,"",(F22-G22)/F22) | I22: ทิ้งสีเหลือบ (ถัง)
C23: ครอบข้างผนัง | H23: =IF(F23=0,"",(F23-G23)/F23) | I23: ใช้ผ้า (ผืน)
C24: ครอบปั้นลม | H24: =IF(F24=0,"",(F24-G24)/F24) | I24: ใช้ผ้า (แผ่น/ผืน) | P24: =F26/P23 -> #DIV/0!
C25: ครอบปิดปลายปั้นลม | H25: =IF(F25=0,"",(F25-G25)/F25) | I25: ใช้ตะแกรง (แผ่น)
A26: รวมกะที่ 2 | E26: =SUM(E16:E25) -> 0 | F26: =SUM(F16:F25) -> 0 | G26: =SUM(G16:G25) -> 0 | H26: =IF(F26=0,"",(F26-G26)/F26) | I26: ใช้ตะแกรง (แผ่น/ผืน) | P26: =F26/P25 -> #DIV/0!
I27: ปริมาณการใช้รวม | P27: =SUM(P5,P16) -> 3.742 | R27: =SUM(R5,R16) -> 11.24 | T27: =SUM(T5,T16) -> 1.257 | V27: =SUM(V5,V16) -> 35.245 | X27: =SUM(X5,X16) -> 0.682 | Z27: =SUM(Z5,Z16) -> 469 | AB27: =SUM(AB5,AB16) -> 65 | AD27: =SUM(AD5,AD16) -> 2.5 | AF27: =SUM(AF5,AF16) -> 100 | AH27: =SUM(AH5,AH16) -> 0 | AJ27: =SUM(AJ5,AJ16) -> 0
A28: รวมทุกกะ | E28: =E15+E26 -> 11100 | F28: =F15+F26 -> 15421 | G28: =G15+G26 -> 13500 | H28: =IF(F28=0,"",(F28-G28)/F28) -> 0.12457039 | I28: คำนวณจาก Counter (ต่อพันแผ่น) | P28: =IF($F$28=0,0,P27*1000/$F$28) -> 0.24265612 | R28: =IF($F$28=0,0,R27*1000/$F$28) -> 0.72887621 | T28: =IF($F$28=0,0,T27*1000/$F$28) -> 0.081512224 | V28: =IF($F$28=0,0,V27*1000/$F$28) -> 2.2855197 | X28: =IF($F$28=0,0,X27*1000/$F$28) -> 0.044225407 | Z28: =IF($F$28=0,0,Z27*1000/$F$28) -> 30.413073 | AB28: =IF($F$28=0,0,AB27*1000/$F$28) -> 4.2150315 | AD28: =IF($F$28=0,0,AD27*1000/$F$28) -> 0.16211659 | AF28: =IF($F$28=0,0,AF27*1000/$F$28) -> 6.4846638 | AH28: =IF($F$28=0,0,AH27*1000/$F$28) -> 0 | AJ28: =IF($F$28=0,0,AJ27*1000/$F$28) -> 0
I29: คำนวณจาก ห้องบ่ม (ต่อพันแผ่น) | P29: =IF($G$28=0,0,P27*1000/$G$28) -> 0.27718519 | R29: =IF($G$28=0,0,R27*1000/$G$28) -> 0.83259259 | T29: =IF($G$28=0,0,T27*1000/$G$28) -> 0.093111111 | V29: =IF($G$28=0,0,V27*1000/$G$28) -> 2.6107407 | X29: =IF($G$28=0,0,X27*1000/$G$28) -> 0.050518519 | Z29: =IF($G$28=0,0,Z27*1000/$G$28) -> 34.740741 | AB29: =IF($G$28=0,0,AB27*1000/$G$28) -> 4.8148148 | AD29: =IF($G$28=0,0,AD27*1000/$G$28) -> 0.18518519 | AF29: =IF($G$28=0,0,AF27*1000/$G$28) -> 7.4074074 | AH29: =IF($G$28=0,0,AH27*1000/$G$28) -> 0 | AJ29: =IF($G$28=0,0,AJ27*1000/$G$28) -> 0
A31: รายงานการแกะครอบ | I31: รายละเอียดครอบเสีย | AI31: แผ่นดีนำไปกองเก็บจำนวนไม้ / แผ่น | AK31: หมายเหตุ
A32: กะที่ | B32: LOT NO. | C32: ลอน | D32: สี | E32: จำนวนที่นำมาแกะ | F32: แผ่นดี | G32: Reject | I32: แผ่นเสีย | J32: ร้าวผิว ตัวกระเบื้อง | K32: ร้าว รางลิ้นหงาย | L32: ร้าว ล่างรางลิ้นคว่ำ | M32: ร้าว ล่างตัวครอบ | N32: ร้าว ชายกระเบื้อง | O32: ร้าว เขื่อนรางลิ้นหงาย | P32: ร้าว เขื่อนรางลิ้นคว่ำ | Q32: บิ่นแหว่ง | R32: ผิวครอบปูดบวม | S32: ผิวครอบไม่เรียบ | T32: ขอบไม่คม / ไม่เรียบ | U32: รูพรุน | V32: แตกรูตะปู | W32: เนื้อแหว่งใต้ครอบ | X32: ปูนติดโมล | Y32: สี Salary ไม่เต็ม | Z32: สีเป็นเม็ด | AA32: สีพอง | AB32: สีด้าน | AC32: สีหยด | AD32: สีปูด | AE32: ครอบบาง/น้ำหนักเบา | AF32: ยกชน Rack | AG32: รถยกชน | AH32: อื่นๆ
B33: =B5 -> I11690804 | C33: ครอบสัน | D33: =D5 -> มิดไนท์เกรย์*N | E33: =F33+652 -> 3106 | F33: =144*17+6 -> 2454 | G33: =IF(E33=0,"",(E33-F33)/E33) -> 0.20991629 | I33: =SUM(J33:AH33) -> 652 | K33: 3 | L33: =651-181 -> 470 | V33: =17+20+16+2+25+30+30+30 -> 170 | AB33: =3+4 -> 7 | AC33: 2 | AI33: 144*17+QC6 | AK33: จบ Lot. ส่งวันที่ 6/8/69
B34: =B6 -> I12690804 | C34: ครอบปิดจั่ว | D34: =D6 -> มิดไนท์เกรย์*N | E34: =G6 -> 104 | F34: =40*2+24 -> 104 | G34: =IF(E34=0,"",(E34-F34)/E34) -> 0 | I34: =SUM(J34:AH34) -> 0 | AI34: 40*2+ศ.24 | AK34: จบ Lot. ส่งวันที่ 8/8/69
B35: =B7 -> I13690804 | C35: ครอบตะเข้ | D35: =D7 -> มิดไนท์เกรย์*N | E35: =G7 -> 6140 | F35: =210*27+39+6 -> 5715 | G35: =IF(E35=0,"",(E35-F35)/E35) -> 0.069218241 | I35: =SUM(J35:AH35) -> 425 | J35: =20+25+30 -> 75 | K35: =1+2+3 -> 6 | L35: =6+13+6+8+15+11+8+4 -> 71 | O35: 2 | R35: =6 -> 6 | V35: =8+10+12+15+25+25 -> 95 | W35: =20+30+30+10 -> 90 | AB35: =4+4+1+11+2+5 -> 27 | AC35: 4 | AD35: 10 | AE35: =17 -> 17 | AH35: 22 | AI35: 210*27+ศ.39+QC6 | AK35: จบ Lot. ส่งวันที่ 6/8/69
A36: 1 | B36: =B8 -> I14690804 | C36: ครอบปิดปลายตะเข้ | D36: =D8 -> มิดไนท์เกรย์*N | E36: =G8 -> 1605 | F36: =140*9+65+6 -> 1331 | G36: =IF(E36=0,"",(E36-F36)/E36) -> 0.17071651 | I36: =SUM(J36:AH36) -> 274 | K36: =25+25+25+25+15+20 -> 135 | L36: =25+25+25+30 -> 105 | R36: =5 -> 5 | W36: =20 -> 20 | AC36: 5 | AF36: 4 | AI36: 140*9+ศ.65+QC6 | AK36: จบ Lot. ส่งวันที่ 13/8/69
B37: =B9 -> I15690804 | C37: ครอบข้างซิมเลท | D37: =D9 -> มิดไนท์เกรย์*N | E37: =G9 -> 2441 | F37: =280*8+152+6 -> 2398 | G37: =IF(E37=0,"",(E37-F37)/E37) -> 0.017615731 | I37: =SUM(J37:AH37) -> 43 | K37: =4+20 -> 24 | L37: 15 | R37: 1 | AB37: 3 | AI37: 280*8+ศ.152+QC6 | AK37: จบ Lot. ส่งวันที่ 6/8/69
B38: =B10 -> 0 | C38: ครอบข้างปิดปลายซิมเลท | D38: =D10 -> 0 | E38: =G10 -> 0 | G38: =IF(E38=0,"",(E38-F38)/E38) | I38: =SUM(J38:AH38) -> 0
B39: =B11 -> 0 | C39: ครอบหัวผนัง | D39: =D11 -> 0 | E39: =G11 -> 0 | G39: =IF(E39=0,"",(E39-F39)/E39) | I39: =SUM(J39:AH39) -> 0
B40: =B12 -> 0 | C40: ครอบข้างผนัง | D40: =D12 -> 0 | E40: =G12 -> 0 | G40: =IF(E40=0,"",(E40-F40)/E40) | I40: =SUM(J40:AH40) -> 0
B41: =B13 -> 0 | C41: ครอบปั้นลม | D41: =D13 -> 0 | E41: =G13 -> 0 | G41: =IF(E41=0,"",(E41-F41)/E41) | I41: =SUM(J41:AH41) -> 0
...

Sheet 5
A1: รายงานการผลิตครอบประจำวัน | F1: ครอบ Prestige โรงงานสระบุรี 2/3 | L1: สัปดาห์ที่ | M1: 00/69 | Q1: วันที่ผลิต | R1: 244566 | V1: MATERIAL DOCUMENT NO
E2: จำนวนที่ผลิต | I2: ปริมาณการใช้วัตถุดิบ | P2: เถ้าลอย | R2: ปูนซีเมนต์ | T2: ปูนซีเมนต์ | V2: ทราย | X2: ทราย | Z2: Water Base | AB2: MOULD | AD2: Adva | AF2: สีพื้น | AH2: สีเหลือบ | AJ2: สีเหลือบ
A3: กะที่ | B3: LOT NO. | C3: ลอน | D3: สี | E3: (แผ่น) | R3: ผสมตัว | T3: ผสมสี | V3: ผสมตัว | X3: ผสมสี | Z3: Spray | AB3: OIL | AH3: 1 | AJ3: 2
E4: Plan | F4: Counter | G4: ห้องบ่ม | H4: Wet Reject | P4: (ตัน) | R4: (ตัน) | T4: (ตัน) | V4: (ตัน) | X4: (ตัน) | Z4: (ลิตร) | AB4: (ลิตร) | AD4: (ลิตร) | AF4: (แผ่น/ถัง) | AH4: (แผ่น/ถัง) | AJ4: (แผ่น/ถัง)
B5: I11690806 | C5: ครอบสัน | D5: ไอวอรี่เกรย์*N | E5: 1000 | F5: 1145 | G5: 882 | H5: =IF(F5=0,"",(F5-G5)/F5) -> 0.22969432 | I5: ปริมาณการใช้กะ 1 | P5: 2.135 | R5: 6.549 | T5: 0.403 | V5: 20.482 | X5: 0.212 | Z5: =200-22 -> 178 | AB5: 38 | AD5: =SUM(AF5:AK5)*0.025 -> 0.8 | AF5: =14+14+4 -> 32 | AH5: 0 | AJ5: 0
A6: 1 | B6: I12690806 | C6: ครอบปิดจั่ว | D6: ไอวอรี่เกรย์*N | E6: 40 | F6: 43 | G6: 43 | H6: =IF(F6=0,"",(F6-G6)/F6) -> 0 | I6: คำนวณจาก Counter (ต่อพันแผ่น) | P6: =IF($F$15=0,0,P5*1000/$F$15) -> 0.40435606 | R6: =IF($F$15=0,0,R5*1000/$F$15) -> 1.2403409 | T6: =IF($F$15=0,0,T5*1000/$F$15) -> 0.076325758 | V6: =IF($F$15=0,0,V5*1000/$F$15) -> 3.8791667 | X6: =IF($F$15=0,0,X5*1000/$F$15) -> 0.040151515 | Z6: =IF($F$15=0,0,Z5*1000/$F$15) -> 33.712121 | AB6: =IF($F$15=0,0,AB5*1000/$F$15) -> 7.1969697 | AD6: =IF($F$15=0,0,AD5*1000/$F$15) -> 0.15151515 | AF6: =IF(AF5=0,0,F15/AF5) -> 165 | AH6: =IF(AH5=0,0,F15/AH5) -> 0 | AJ6: =IF(AJ5=0,0,F15/AJ5) -> 0
B7: I13690806 | C7: ครอบตะเข้ | D7: ไอวอรี่เกรย์*N | E7: 2000 | F7: 2878 | G7: 2531 | H7: =IF(F7=0,"",(F7-G7)/F7) -> 0.12056984 | I7: คำนวณจาก ห้องบ่ม (ต่อพันแผ่น) | P7: =IF($G$15=0,0,P5*1000/$G$15) -> 0.47773551 | R7: =IF($G$15=0,0,R5*1000/$G$15) -> 1.4654285 | T7: =IF($G$15=0,0,T5*1000/$G$15) -> 0.090176773 | V7: =IF($G$15=0,0,V5*1000/$G$15) -> 4.5831282 | X7: =IF($G$15=0,0,X5*1000/$G$15) -> 0.047437906 | Z7: =IF($G$15=0,0,Z5*1000/$G$15) -> 39.82994 | AB7: =IF($G$15=0,0,AB5*1000/$G$15) -> 8.5030208 | AD7: =IF($G$15=0,0,AD5*1000/$G$15) -> 0.17901096 | AF7: =IF(AF5=0,0,G15/AF5) -> 139.65625 | AH7: =IF(AH5=0,0,G15/AH5) -> 0 | AJ7: =IF(AJ5=0,0,G15/AJ5) -> 0
C8: ครอบปิดปลายตะเข้ | H8: =IF(F8=0,"",(F8-G8)/F8) | I8: ใช้ปูน ( Batch) | P8: 97
B9: I15690806 | C9: ครอบข้างซิมเลท | D9: ไอวอรี่เกรย์*N | E9: 800 | F9: 969 | G9: 862 | H9: =IF(F9=0,"",(F9-G9)/F9) -> 0.11042312 | I9: ทิ้งปูน (Batct)
B10: I16690806 | C10: ครอบข้างปิดปลายซิมเลท | D10: ไอวอรี่เกรย์*N | E10: 500 | F10: 245 | G10: 151 | H10: =IF(F10=0,"",(F10-G10)/F10) -> 0.38367347 | I10: ทิ้งสีพื้น (ถัง)
C11: ครอบหัวผนัง | H11: =IF(F11=0,"",(F11-G11)/F11) | I11: ทิ้งสีเหลือบ (ถัง)
C12: ครอบข้างผนัง | H12: =IF(F12=0,"",(F12-G12)/F12) | I12: ใช้ผ้า (ผืน) | P12: =3+3+3+3+4+2+5 -> 23
C13: ครอบปั้นลม | H13: =IF(F13=0,"",(F13-G13)/F13) | I13: ใช้ผ้า (แผ่น/ผืน) | P13: =F15/P12 -> 229.56522
C14: ครอบปิดปลายปั้นลม | H14: =IF(F14=0,"",(F14-G14)/F14) | I14: ใช้ตะแกรง (แผ่น) | P14: 7
A15: รวมกะที่ 1 | E15: =SUM(E5:E14) -> 4340 | F15: =SUM(F5:F14) -> 5280 | G15: =SUM(G5:G14) -> 4469 | H15: =IF(F15=0,"",(F15-G15)/F15) -> 0.15359848 | I15: ใช้ตะแกรง (แผ่น/ผืน) | P15: =F15/P14 -> 754.28571
B16: I11690807 | C16: ครอบสัน | D16: ดาร์กเกรย์*N | E16: 3000 | F16: 2807 | G16: 2338 | H16: =IF(F16=0,"",(F16-G16)/F16) -> 0.16708229 | I16: ปริมาณการใช้กะ 2 | P16: 1.585 | R16: 4.927 | T16: 0.553 | V16: 15.499 | X16: 0.315 | Z16: =40+200+73 -> 313 | AB16: 27 | AD16: =SUM(AF16:AK16)*0.025 -> 1.125 | AF16: =3+14+14+14 -> 45 | AH16: 0 | AJ16: 0
A17: 2 | C17: ครอบปิดจั่ว | H17: =IF(F17=0,"",(F17-G17)/F17) | I17: คำนวณจาก Counter (ต่อพันแผ่น) | P17: =IF($F$26=0,0,P16*1000/$F$26) -> 0.16248078 | R17: =IF($F$26=0,0,R16*1000/$F$26) -> 0.50507432 | T17: =IF($F$26=0,0,T16*1000/$F$26) -> 0.056688877 | V17: =IF($F$26=0,0,V16*1000/$F$26) -> 1.5888262 | X17: =IF($F$26=0,0,X16*1000/$F$26) -> 0.032291133 | Z17: =IF($F$26=0,0,Z16*1000/$F$26) -> 32.08611 | AB17: =IF($F$26=0,0,AB16*1000/$F$26) -> 2.7678114 | AD17: =IF($F$26=0,0,AD16*1000/$F$26) -> 0.11532547 | AF17: =IF(AF16=0,0,F26/AF16) -> 216.77778 | AH17: =IF($F$26=0,0,AH16*1000/$F$26) -> 0 | AJ17: =IF($F$26=0,0,AJ16*1000/$F$26) -> 0
B18: I13690807 | C18: ครอบตะเข้ | D18: ดาร์กเกรย์*N | E18: 2000 | F18: 4178 | G18: 3679 | H18: =IF(F18=0,"",(F18-G18)/F18) -> 0.11943514 | I18: คำนวณจาก ห้องบ่ม (ต่อพันแผ่น) | P18: =IF($G$26=0,0,P16*1000/$G$26) -> 0.18503385 | R18: =IF($G$26=0,0,R16*1000/$G$26) -> 0.57518095 | T18: =IF($G$26=0,0,T16*1000/$G$26) -> 0.064557553 | V18: =IF($G$26=0,0,V16*1000/$G$26) -> 1.8093626 | X18: =IF($G$26=0,0,X16*1000/$G$26) -> 0.03677329 | Z18: =IF($G$26=0,0,Z16*1000/$G$26) -> 36.539809 | AB18: =IF($G$26=0,0,AB16*1000/$G$26) -> 3.1519963 | AD18: =IF($G$26=0,0,AD16*1000/$G$26) -> 0.13133318 | AF18: =IF(AF16=0,0,G26/AF16) -> 190.35556 | AH18: =IF($G$26=0,0,AH16*1000/$G$26) -> 0 | AJ18: =IF($G$26=0,0,AJ16*1000/$G$26) -> 0
C19: ครอบปิดปลายตะเข้ | H19: =IF(F19=0,"",(F19-G19)/F19) | I19: ใช้ปูน ( Batch) | P19: 72
B20: I15690807 | C20: ครอบข้างซิมเลท | D20: ดาร์กเกรย์*N | E20: 1200 | F20: 1866 | G20: 1795 | H20: =IF(F20=0,"",(F20-G20)/F20) -> 0.038049303 | I20: ทิ้งปูน (Batct)
B21: I16690807 | C21: ครอบข้างปิดปลายซิมเลท | D21: ดาร์กเกรย์*N | E21: 1500 | F21: 904 | G21: 754 | H21: =IF(F21=0,"",(F21-G21)/F21) -> 0.1659292 | I21: ทิ้งสีพื้น (ถัง)
C22: ครอบหัวผนัง | H22: =IF(F22=0,"",(F22-G22)/F22) | I22: ทิ้งสีเหลือบ (ถัง)
C23: ครอบข้างผนัง | H23: =IF(F23=0,"",(F23-G23)/F23) | I23: ใช้ผ้า (ผืน) | P23: =1+4+1+3+2+4+5+4+1+5+2+4+3+5 -> 44
C24: ครอบปั้นลม | H24: =IF(F24=0,"",(F24-G24)/F24) | I24: ใช้ผ้า (แผ่น/ผืน) | P24: =F26/P23 -> 221.70455
C25: ครอบปิดปลายปั้นลม | H25: =IF(F25=0,"",(F25-G25)/F25) | I25: ใช้ตะแกรง (แผ่น) | P25: 7
A26: รวมกะที่ 2 | E26: =SUM(E16:E25) -> 7700 | F26: =SUM(F16:F25) -> 9755 | G26: =SUM(G16:G25) -> 8566 | H26: =IF(F26=0,"",(F26-G26)/F26) -> 0.12188621 | I26: ใช้ตะแกรง (แผ่น/ผืน) | P26: =F26/P25 -> 1393.5714
I27: ปริมาณการใช้รวม | P27: =SUM(P5,P16) -> 3.72 | R27: =SUM(R5,R16) -> 11.476 | T27: =SUM(T5,T16) -> 0.956 | V27: =SUM(V5,V16) -> 35.981 | X27: =SUM(X5,X16) -> 0.527 | Z27: =SUM(Z5,Z16) -> 491 | AB27: =SUM(AB5,AB16) -> 65 | AD27: =SUM(AD5,AD16) -> 1.925 | AF27: =SUM(AF5,AF16) -> 77 | AH27: =SUM(AH5,AH16) -> 0 | AJ27: =SUM(AJ5,AJ16) -> 0
A28: รวมทุกกะ | E28: =E15+E26 -> 12040 | F28: =F15+F26 -> 15035 | G28: =G15+G26 -> 13035 | H28: =IF(F28=0,"",(F28-G28)/F28) -> 0.13302295 | I28: คำนวณจาก Counter (ต่อพันแผ่น) | P28: =IF($F$28=0,0,P27*1000/$F$28) -> 0.24742268 | R28: =IF($F$28=0,0,R27*1000/$F$28) -> 0.76328567 | T28: =IF($F$28=0,0,T27*1000/$F$28) -> 0.063584968 | V28: =IF($F$28=0,0,V27*1000/$F$28) -> 2.3931493 | X28: =IF($F$28=0,0,X27*1000/$F$28) -> 0.035051546 | Z28: =IF($F$28=0,0,Z27*1000/$F$28) -> 32.657133 | AB28: =IF($F$28=0,0,AB27*1000/$F$28) -> 4.3232458 | AD28: =IF($F$28=0,0,AD27*1000/$F$28) -> 0.12803459 | AF28: =IF($F$28=0,0,AF27*1000/$F$28) -> 5.1213834 | AH28: =IF($F$28=0,0,AH27*1000/$F$28) -> 0 | AJ28: =IF($F$28=0,0,AJ27*1000/$F$28) -> 0
I29: คำนวณจาก ห้องบ่ม (ต่อพันแผ่น) | P29: =IF($G$28=0,0,P27*1000/$G$28) -> 0.2853855 | R29: =IF($G$28=0,0,R27*1000/$G$28) -> 0.88039893 | T29: =IF($G$28=0,0,T27*1000/$G$28) -> 0.073341005 | V29: =IF($G$28=0,0,V27*1000/$G$28) -> 2.7603376 | X29: =IF($G$28=0,0,X27*1000/$G$28) -> 0.040429613 | Z29: =IF($G$28=0,0,Z27*1000/$G$28) -> 37.667817 | AB29: =IF($G$28=0,0,AB27*1000/$G$28) -> 4.9865746 | AD29: =IF($G$28=0,0,AD27*1000/$G$28) -> 0.14767932 | AF29: =IF($G$28=0,0,AF27*1000/$G$28) -> 5.907173 | AH29: =IF($G$28=0,0,AH27*1000/$G$28) -> 0 | AJ29: =IF($G$28=0,0,AJ27*1000/$G$28) -> 0
A31: รายงานการแกะครอบ | I31: รายละเอียดครอบเสีย | AI31: แผ่นดีนำไปกองเก็บจำนวนไม้ / แผ่น | AK31: หมายเหตุ
A32: กะที่ | B32: LOT NO. | C32: ลอน | D32: สี | E32: จำนวนที่นำมาแกะ | F32: แผ่นดี | G32: Reject | I32: แผ่นเสีย | J32: ร้าวผิว ตัวกระเบื้อง | K32: ร้าว รางลิ้นหงาย | L32: ร้าว ล่างรางลิ้นคว่ำ | M32: ร้าว ล่างตัวครอบ | N32: ร้าว ชายกระเบื้อง | O32: ร้าว เขื่อนรางลิ้นหงาย | P32: ร้าว เขื่อนรางลิ้นคว่ำ | Q32: บิ่นแหว่ง | R32: ผิวครอบปูดบวม | S32: ผิวครอบไม่เรียบ | T32: ขอบไม่คม / ไม่เรียบ | U32: รูพรุน | V32: แตกรูตะปู | W32: เนื้อแหว่งใต้ครอบ | X32: ปูนติดโมล | Y32: สี Salary ไม่เต็ม | Z32: สีเป็นเม็ด | AA32: สีพอง | AB32: สีด้าน | AC32: สีหยด | AD32: สีปูด | AE32: ครอบบาง/น้ำหนักเบา | AF32: ยกชน Rack | AG32: รถยกชน | AH32: อื่นๆ
B33: =B5 -> I11690806 | C33: ครอบสัน | D33: =D5 -> ไอวอรี่เกรย์*N | E33: =G5 -> 882 | F33: =144*5+76+6 -> 802 | G33: =IF(E33=0,"",(E33-F33)/E33) -> 0.090702948 | I33: =SUM(J33:AH33) -> 80 | K33: =5 -> 5 | L33: =20+20+20 -> 60 | AC33: =4 -> 4 | AE33: 1 | AF33: 10 | AI33: 144*5+ศ.76+QC6 | AK33: จบ Lot. ส่งวันที่ 6/8/69
B34: =B6 -> I12690806 | C34: ครอบปิดจั่ว | D34: =D6 -> ไอวอรี่เกรย์*N | E34: =G6 -> 43 | F34: =40*1+3 -> 43 | G34: =IF(E34=0,"",(E34-F34)/E34) -> 0 | I34: =SUM(J34:AH34) -> 0 | AI34: 40*1+ศ.3 | AK34: จบ Lot. ส่งวันที่ 8/8/69
B35: =B7 -> I13690806 | C35: ครอบตะเข้ | D35: =D7 -> ไอวอรี่เกรย์*N | E35: =G7 -> 2531 | F35: =210*12+6 -> 2526 | G35: =IF(E35=0,"",(E35-F35)/E35) -> 0.0019755038 | I35: =SUM(J35:AH35) -> 5 | K35: 5 | AI35: 210*12+QC6 | AK35: จบ Lot. ส่งวันที่ 6/8/69
A36: 1 | B36: =B8 -> 0 | C36: ครอบปิดปลายตะเข้ | D36: =D8 -> 0 | E36: =G8 -> 0 | G36: =IF(E36=0,"",(E36-F36)/E36) | I36: =SUM(J36:AH36) -> 0
B37: =B9 -> I15690806 | C37: ครอบข้างซิมเลท | D37: =D9 -> ไอวอรี่เกรย์*N | E37: =G9 -> 862 | F37: =280*3+6 -> 846 | G37: =IF(E37=0,"",(E37-F37)/E37) -> 0.018561485 | I37: =SUM(J37:AH37) -> 16 | K37: 12 | R37: 4 | AI37: 280*3+QC6 | AK37: จบ Lot. ส่งวันที่ 6/8/69
B38: =B10 -> I16690806 | C38: ครอบข้างปิดปลายซิมเลท | D38: =D10 -> ไอวอรี่เกรย์*N | E38: =G10 -> 151 | F38: =96*1+26+6 -> 128 | G38: =IF(E38=0,"",(E38-F38)/E38) -> 0.15231788 | I38: =SUM(J38:AH38) -> 23 | K38: 2 | W38: 21 | AI38: 96*1+ศ.26+QC6 | AK38: จบ Lot. ส่งวันที่ 6/8/69
B39: =B11 -> 0 | C39: ครอบหัวผนัง | D39: =D11 -> 0 | E39: =G11 -> 0 | G39: =IF(E39=0,"",(E39-F39)/E39) | I39: =SUM(J39:AH39) -> 0
B40: =B12 -> 0 | C40: ครอบข้างผนัง | D40: =D12 -> 0 | E40: =G12 -> 0 | G40: =IF(E40=0,"",(E40-F40)/E40) | I40: =SUM(J40:AH40) -> 0
B41: =B13 -> 0 | C41: ครอบปั้นลม | D41: =D13 -> 0 | E41: =G13 -> 0 | G41: =IF(E41=0,"",(E41-F41)/E41) | I41: =SUM(J41:AH41) -> 0
...

Sheet 6
A1: รายงานการผลิตครอบประจำวัน | F1: ครอบ Prestige โรงงานสระบุรี 2/3 | L1: สัปดาห์ที่ | M1: 00/69 | Q1: วันที่ผลิต | R1: 244567 | V1: MATERIAL DOCUMENT NO
E2: จำนวนที่ผลิต | I2: ปริมาณการใช้วัตถุดิบ | P2: เถ้าลอย | R2: ปูนซีเมนต์ | T2: ปูนซีเมนต์ | V2: ทราย | X2: ทราย | Z2: Water Base | AB2: MOULD | AD2: Adva | AF2: สีพื้น | AH2: สีเหลือบ | AJ2: สีเหลือบ
A3: กะที่ | B3: LOT NO. | C3: ลอน | D3: สี | E3: (แผ่น) | R3: ผสมตัว | T3: ผสมสี | V3: ผสมตัว | X3: ผสมสี | Z3: Spray | AB3: OIL | AH3: 1 | AJ3: 2
E4: Plan | F4: Counter | G4: ห้องบ่ม | H4: Wet Reject | P4: (ตัน) | R4: (ตัน) | T4: (ตัน) | V4: (ตัน) | X4: (ตัน) | Z4: (ลิตร) | AB4: (ลิตร) | AD4: (ลิตร) | AF4: (แผ่น/ถัง) | AH4: (แผ่น/ถัง) | AJ4: (แผ่น/ถัง)
C5: ครอบสัน | H5: =IF(F5=0,"",(F5-G5)/F5) | I5: ปริมาณการใช้กะ 1 | P5: 0 | R5: 0 | T5: 0 | V5: 0 | X5: 0 | Z5: 0 | AB5: 0 | AD5: =SUM(AF5:AK5)*0.025 -> 0 | AF5: 0 | AH5: 0 | AJ5: 0
A6: 1 | C6: ครอบปิดจั่ว | H6: =IF(F6=0,"",(F6-G6)/F6) | I6: คำนวณจาก Counter (ต่อพันแผ่น) | P6: =IF($F$15=0,0,P5*1000/$F$15) -> 0 | R6: =IF($F$15=0,0,R5*1000/$F$15) -> 0 | T6: =IF($F$15=0,0,T5*1000/$F$15) -> 0 | V6: =IF($F$15=0,0,V5*1000/$F$15) -> 0 | X6: =IF($F$15=0,0,X5*1000/$F$15) -> 0 | Z6: =IF($F$15=0,0,Z5*1000/$F$15) -> 0 | AB6: =IF($F$15=0,0,AB5*1000/$F$15) -> 0 | AD6: =IF($F$15=0,0,AD5*1000/$F$15) -> 0 | AF6: =IF(AF5=0,0,F15/AF5) -> 0 | AH6: =IF(AH5=0,0,F15/AH5) -> 0 | AJ6: =IF(AJ5=0,0,F15/AJ5) -> 0
C7: ครอบตะเข้ | H7: =IF(F7=0,"",(F7-G7)/F7) | I7: คำนวณจาก ห้องบ่ม (ต่อพันแผ่น) | P7: =IF($G$15=0,0,P5*1000/$G$15) -> 0 | R7: =IF($G$15=0,0,R5*1000/$G$15) -> 0 | T7: =IF($G$15=0,0,T5*1000/$G$15) -> 0 | V7: =IF($G$15=0,0,V5*1000/$G$15) -> 0 | X7: =IF($G$15=0,0,X5*1000/$G$15) -> 0 | Z7: =IF($G$15=0,0,Z5*1000/$G$15) -> 0 | AB7: =IF($G$15=0,0,AB5*1000/$G$15) -> 0 | AD7: =IF($G$15=0,0,AD5*1000/$G$15) -> 0 | AF7: =IF(AF5=0,0,G15/AF5) -> 0 | AH7: =IF(AH5=0,0,G15/AH5) -> 0 | AJ7: =IF(AJ5=0,0,G15/AJ5) -> 0
C8: ครอบปิดปลายตะเข้ | H8: =IF(F8=0,"",(F8-G8)/F8) | I8: ใช้ปูน ( Batch)
C9: ครอบข้างซิมเลท | H9: =IF(F9=0,"",(F9-G9)/F9) | I9: ทิ้งปูน (Batct)
C10: ครอบข้างปิดปลายซิมเลท | H10: =IF(F10=0,"",(F10-G10)/F10) | I10: ทิ้งสีพื้น (ถัง)
C11: ครอบหัวผนัง | H11: =IF(F11=0,"",(F11-G11)/F11) | I11: ทิ้งสีเหลือบ (ถัง)
C12: ครอบข้างผนัง | H12: =IF(F12=0,"",(F12-G12)/F12) | I12: ใช้ผ้า (ผืน)
C13: ครอบปั้นลม | H13: =IF(F13=0,"",(F13-G13)/F13) | I13: ใช้ผ้า (แผ่น/ผืน) | P13: =F15/P12 -> #DIV/0!
C14: ครอบปิดปลายปั้นลม | H14: =IF(F14=0,"",(F14-G14)/F14) | I14: ใช้ตะแกรง (แผ่น)
A15: รวมกะที่ 1 | E15: =SUM(E5:E14) -> 0 | F15: =SUM(F5:F14) -> 0 | G15: =SUM(G5:G14) -> 0 | H15: =IF(F15=0,"",(F15-G15)/F15) | I15: ใช้ตะแกรง (แผ่น/ผืน) | P15: =F15/P14 -> #DIV/0!
C16: ครอบสัน | H16: =IF(F16=0,"",(F16-G16)/F16) | I16: ปริมาณการใช้กะ 2 | P16: 1.34 | R16: 4.673 | T16: 0.479 | V16: 11.295 | X16: 0.272 | Z16: =98+42+77 -> 217 | AB16: 25 | AD16: =SUM(AF16:AK16)*0.025 -> 0.975 | AF16: =14+14+11 -> 39 | AH16: 0 | AJ16: 0
A17: 2 | C17: ครอบปิดจั่ว | H17: =IF(F17=0,"",(F17-G17)/F17) | I17: คำนวณจาก Counter (ต่อพันแผ่น) | P17: =IF($F$26=0,0,P16*1000/$F$26) -> 0.23219546 | R17: =IF($F$26=0,0,R16*1000/$F$26) -> 0.80973835 | T17: =IF($F$26=0,0,T16*1000/$F$26) -> 0.083001213 | V17: =IF($F$26=0,0,V16*1000/$F$26) -> 1.9571998 | X17: =IF($F$26=0,0,X16*1000/$F$26) -> 0.047132213 | Z17: =IF($F$26=0,0,Z16*1000/$F$26) -> 37.601802 | AB17: =IF($F$26=0,0,AB16*1000/$F$26) -> 4.3320049 | AD17: =IF($F$26=0,0,AD16*1000/$F$26) -> 0.16894819 | AF17: =IF(AF16=0,0,F26/AF16) -> 147.97436 | AH17: =IF($F$26=0,0,AH16*1000/$F$26) -> 0 | AJ17: =IF($F$26=0,0,AJ16*1000/$F$26) -> 0
B18: I13690809 | C18: ครอบตะเข้ | D18: มิสทีเกรย์*N | E18: 3000 | F18: 5771 | G18: 5152 | H18: =IF(F18=0,"",(F18-G18)/F18) -> 0.10726044 | I18: คำนวณจาก ห้องบ่ม (ต่อพันแผ่น) | P18: =IF($G$26=0,0,P16*1000/$G$26) -> 0.26009317 | R18: =IF($G$26=0,0,R16*1000/$G$26) -> 0.9070264 | T18: =IF($G$26=0,0,T16*1000/$G$26) -> 0.092973602 | V18: =IF($G$26=0,0,V16*1000/$G$26) -> 2.1923525 | X18: =IF($G$26=0,0,X16*1000/$G$26) -> 0.052795031 | Z18: =IF($G$26=0,0,Z16*1000/$G$26) -> 42.119565 | AB18: =IF($G$26=0,0,AB16*1000/$G$26) -> 4.8524845 | AD18: =IF($G$26=0,0,AD16*1000/$G$26) -> 0.18924689 | AF18: =IF(AF16=0,0,G26/AF16) -> 132.10256 | AH18: =IF($G$26=0,0,AH16*1000/$G$26) -> 0 | AJ18: =IF($G$26=0,0,AJ16*1000/$G$26) -> 0
C19: ครอบปิดปลายตะเข้ | H19: =IF(F19=0,"",(F19-G19)/F19) | I19: ใช้ปูน ( Batch) | P19: =63 -> 63
C20: ครอบข้างซิมเลท | H20: =IF(F20=0,"",(F20-G20)/F20) | I20: ทิ้งปูน (Batct)
C21: ครอบข้างปิดปลายซิมเลท | H21: =IF(F21=0,"",(F21-G21)/F21) | I21: ทิ้งสีพื้น (ถัง)
C22: ครอบหัวผนัง | H22: =IF(F22=0,"",(F22-G22)/F22) | I22: ทิ้งสีเหลือบ (ถัง)
C23: ครอบข้างผนัง | H23: =IF(F23=0,"",(F23-G23)/F23) | I23: ใช้ผ้า (ผืน) | P23: =4+4+4+4+4+4 -> 24
C24: ครอบปั้นลม | H24: =IF(F24=0,"",(F24-G24)/F24) | I24: ใช้ผ้า (แผ่น/ผืน) | P24: =F26/P23 -> 240.45833
C25: ครอบปิดปลายปั้นลม | H25: =IF(F25=0,"",(F25-G25)/F25) | I25: ใช้ตะแกรง (แผ่น) | P25: 6
A26: รวมกะที่ 2 | E26: =SUM(E16:E25) -> 3000 | F26: =SUM(F16:F25) -> 5771 | G26: =SUM(G16:G25) -> 5152 | H26: =IF(F26=0,"",(F26-G26)/F26) -> 0.10726044 | I26: ใช้ตะแกรง (แผ่น/ผืน) | P26: =F26/P25 -> 961.83333
I27: ปริมาณการใช้รวม | P27: =SUM(P5,P16) -> 1.34 | R27: =SUM(R5,R16) -> 4.673 | T27: =SUM(T5,T16) -> 0.479 | V27: =SUM(V5,V16) -> 11.295 | X27: =SUM(X5,X16) -> 0.272 | Z27: =SUM(Z5,Z16) -> 217 | AB27: =SUM(AB5,AB16) -> 25 | AD27: =SUM(AD5,AD16) -> 0.975 | AF27: =SUM(AF5,AF16) -> 39 | AH27: =SUM(AH5,AH16) -> 0 | AJ27: =SUM(AJ5,AJ16) -> 0
A28: รวมทุกกะ | E28: =E15+E26 -> 3000 | F28: =F15+F26 -> 5771 | G28: =G15+G26 -> 5152 | H28: =IF(F28=0,"",(F28-G28)/F28) -> 0.10726044 | I28: คำนวณจาก Counter (ต่อพันแผ่น) | P28: =IF($F$28=0,0,P27*1000/$F$28) -> 0.23219546 | R28: =IF($F$28=0,0,R27*1000/$F$28) -> 0.80973835 | T28: =IF($F$28=0,0,T27*1000/$F$28) -> 0.083001213 | V28: =IF($F$28=0,0,V27*1000/$F$28) -> 1.9571998 | X28: =IF($F$28=0,0,X27*1000/$F$28) -> 0.047132213 | Z28: =IF($F$28=0,0,Z27*1000/$F$28) -> 37.601802 | AB28: =IF($F$28=0,0,AB27*1000/$F$28) -> 4.3320049 | AD28: =IF($F$28=0,0,AD27*1000/$F$28) -> 0.16894819 | AF28: =IF(AF27=0,0,F28/AF27) -> 147.97436 | AH28: =IF($F$28=0,0,AH27*1000/$F$28) -> 0 | AJ28: =IF($F$28=0,0,AJ27*1000/$F$28) -> 0
I29: คำนวณจาก ห้องบ่ม (ต่อพันแผ่น) | P29: =IF($G$28=0,0,P27*1000/$G$28) -> 0.26009317 | R29: =IF($G$28=0,0,R27*1000/$G$28) -> 0.9070264 | T29: =IF($G$28=0,0,T27*1000/$G$28) -> 0.092973602 | V29: =IF($G$28=0,0,V27*1000/$G$28) -> 2.1923525 | X29: =IF($G$28=0,0,X27*1000/$G$28) -> 0.052795031 | Z29: =IF($G$28=0,0,Z27*1000/$G$28) -> 42.119565 | AB29: =IF($G$28=0,0,AB27*1000/$G$28) -> 4.8524845 | AD29: =IF($G$28=0,0,AD27*1000/$G$28) -> 0.18924689 | AF29: =IF(AF27=0,0,G28/AF27) -> 132.10256 | AH29: =IF($G$28=0,0,AH27*1000/$G$28) -> 0 | AJ29: =IF($G$28=0,0,AJ27*1000/$G$28) -> 0
A31: รายงานการแกะครอบ | I31: รายละเอียดครอบเสีย | AI31: แผ่นดีนำไปกองเก็บจำนวนไม้ / แผ่น | AK31: หมายเหตุ
A32: กะที่ | B32: LOT NO. | C32: ลอน | D32: สี | E32: จำนวนที่นำมาแกะ | F32: แผ่นดี | G32: Reject | I32: แผ่นเสีย | J32: ร้าวผิว ตัวกระเบื้อง | K32: ร้าว รางลิ้นหงาย | L32: ร้าว ล่างรางลิ้นคว่ำ | M32: ร้าว ล่างตัวครอบ | N32: ร้าว ชายกระเบื้อง | O32: ร้าว เขื่อนรางลิ้นหงาย | P32: ร้าว เขื่อนรางลิ้นคว่ำ | Q32: บิ่นแหว่ง | R32: ผิวครอบปูดบวม | S32: ผิวครอบไม่เรียบ | T32: ขอบไม่คม / ไม่เรียบ | U32: รูพรุน | V32: แตกรูตะปู | W32: เนื้อแหว่งใต้ครอบ | X32: ปูนติดโมล | Y32: สี Salary ไม่เต็ม | Z32: สีเป็นเม็ด | AA32: สีพอง | AB32: สีด้าน | AC32: สีหยด | AD32: สีปูด | AE32: ครอบบาง/น้ำหนักเบา | AF32: ยกชน Rack | AG32: รถยกชน | AH32: อื่นๆ
B33: =B5 -> 0 | C33: ครอบสัน | D33: =D5 -> 0 | E33: =G5 -> 0 | G33: =IF(E33=0,"",(E33-F33)/E33) | I33: =SUM(J33:AH33) -> 0
B34: =B6 -> 0 | C34: ครอบปิดจั่ว | D34: =D6 -> 0 | E34: =G6 -> 0 | G34: =IF(E34=0,"",(E34-F34)/E34) | I34: =SUM(J34:AH34) -> 0
B35: =B7 -> 0 | C35: ครอบตะเข้ | D35: =D7 -> 0 | E35: 0 | G35: =IF(E35=0,"",(E35-F35)/E35) | I35: =SUM(J35:AH35) -> 0
A36: 1 | B36: =B8 -> 0 | C36: ครอบปิดปลายตะเข้ | D36: =D8 -> 0 | E36: =G8 -> 0 | G36: =IF(E36=0,"",(E36-F36)/E36) | I36: =SUM(J36:AH36) -> 0
B37: =B9 -> 0 | C37: ครอบข้างซิมเลท | D37: =D9 -> 0 | E37: 0 | G37: =IF(E37=0,"",(E37-F37)/E37) | I37: =SUM(J37:AH37) -> 0
B38: =B10 -> 0 | C38: ครอบข้างปิดปลายซิมเลท | D38: =D10 -> 0 | E38: =G10 -> 0 | G38: =IF(E38=0,"",(E38-F38)/E38) | I38: =SUM(J38:AH38) -> 0
B39: =B11 -> 0 | C39: ครอบหัวผนัง | D39: =D11 -> 0 | E39: =G11 -> 0 | G39: =IF(E39=0,"",(E39-F39)/E39) | I39: =SUM(J39:AH39) -> 0
B40: =B12 -> 0 | C40: ครอบข้างผนัง | D40: =D12 -> 0 | E40: =G12 -> 0 | G40: =IF(E40=0,"",(E40-F40)/E40) | I40: =SUM(J40:AH40) -> 0
B41: =B13 -> 0 | C41: ครอบปั้นลม | D41: =D13 -> 0 | E41: =G13 -> 0 | G41: =IF(E41=0,"",(E41-F41)/E41) | I41: =SUM(J41:AH41) -> 0
...

Sheet 7
A1: รายงานการผลิตครอบประจำวัน | F1: ครอบ Prestige โรงงานสระบุรี 2/3 | L1: สัปดาห์ที่ | M1: 00/69 | Q1: วันที่ผลิต | R1: 244568 | V1: MATERIAL DOCUMENT NO
E2: จำนวนที่ผลิต | I2: ปริมาณการใช้วัตถุดิบ | P2: เถ้าลอย | R2: ปูนซีเมนต์ | T2: ปูนซีเมนต์ | V2: ทราย | X2: ทราย | Z2: Water Base | AB2: MOULD | AD2: Adva | AF2: สีพื้น | AH2: สีเหลือบ | AJ2: สีเหลือบ
A3: กะที่ | B3: LOT NO. | C3: ลอน | D3: สี | E3: (แผ่น) | R3: ผสมตัว | T3: ผสมสี | V3: ผสมตัว | X3: ผสมสี | Z3: Spray | AB3: OIL | AH3: 1 | AJ3: 2
E4: Plan | F4: Counter | G4: ห้องบ่ม | H4: Wet Reject | P4: (ตัน) | R4: (ตัน) | T4: (ตัน) | V4: (ตัน) | X4: (ตัน) | Z4: (ลิตร) | AB4: (ลิตร) | AD4: (ลิตร) | AF4: (แผ่น/ถัง) | AH4: (แผ่น/ถัง) | AJ4: (แผ่น/ถัง)
C5: ครอบสัน | H5: =IF(F5=0,"",(F5-G5)/F5) | I5: ปริมาณการใช้กะ 1 | P5: 0.89 | R5: 4.948 | T5: 0.486 | V5: 11.562 | X5: 0.249 | Z5: =215-20 -> 195 | AB5: 29 | AD5: =SUM(AF5:AK5)*0.025 -> 1 | AF5: =14+14+12 -> 40 | AH5: 0 | AJ5: 0
A6: 1 | C6: ครอบปิดจั่ว | H6: =IF(F6=0,"",(F6-G6)/F6) | I6: คำนวณจาก Counter (ต่อพันแผ่น) | P6: =IF($F$15=0,0,P5*1000/$F$15) -> 0.12973761 | R6: =IF($F$15=0,0,R5*1000/$F$15) -> 0.7212828 | T6: =IF($F$15=0,0,T5*1000/$F$15) -> 0.070845481 | V6: =IF($F$15=0,0,V5*1000/$F$15) -> 1.6854227 | X6: =IF($F$15=0,0,X5*1000/$F$15) -> 0.036297376 | Z6: =IF($F$15=0,0,Z5*1000/$F$15) -> 28.425656 | AB6: =IF($F$15=0,0,AB5*1000/$F$15) -> 4.2274052 | AD6: =IF($F$15=0,0,AD5*1000/$F$15) -> 0.14577259 | AF6: =IF(AF5=0,0,F15/AF5) -> 171.5 | AH6: =IF(AH5=0,0,F15/AH5) -> 0 | AJ6: =IF(AJ5=0,0,F15/AJ5) -> 0
B7: I13690811 | C7: ครอบตะเข้ | D7: เทาปีกนางนวล (ไม่มีรูตะปู)*N | E7: 5040 | F7: 6860 | G7: 5623 | H7: =IF(F7=0,"",(F7-G7)/F7) -> 0.1803207 | I7: คำนวณจาก ห้องบ่ม (ต่อพันแผ่น) | P7: =IF($G$15=0,0,P5*1000/$G$15) -> 0.1582785 | R7: =IF($G$15=0,0,R5*1000/$G$15) -> 0.87995732 | T7: =IF($G$15=0,0,T5*1000/$G$15) -> 0.086430731 | V7: =IF($G$15=0,0,V5*1000/$G$15) -> 2.0561978 | X7: =IF($G$15=0,0,X5*1000/$G$15) -> 0.044282412 | Z7: =IF($G$15=0,0,Z5*1000/$G$15) -> 34.678997 | AB7: =IF($G$15=0,0,AB5*1000/$G$15) -> 5.1573893 | AD7: =IF($G$15=0,0,AD5*1000/$G$15) -> 0.17784101 | AF7: =IF(AF5=0,0,G15/AF5) -> 140.575 | AH7: =IF(AH5=0,0,G15/AH5) -> 0 | AJ7: =IF(AJ5=0,0,G15/AJ5) -> 0
